{"channel":"book","type":"snapshot","data":[{"symbol":"ETH/BTC","bids":[{"price":0.05425,"qty":4.48728080},{"price":0.05424,"qty":3.34653225},{"price":0.05423,"qty":18.73859788},{"price":0.05422,"qty":15.41246298},{"price":0.05421,"qty":18.26407027},{"price":0.05420,"qty":1.76014268},{"price":0.05419,"qty":3.61203992},{"price":0.05418,"qty":16.61927322},{"price":0.05417,"qty":14.46019632},{"price":0.05416,"qty":4.16020000}],"asks":[{"price":0.05426,"qty":22.02748073},{"price":0.05427,"qty":17.21320458},{"price":0.05428,"qty":3.90006206},{"price":0.05429,"qty":16.74152550},{"price":0.05430,"qty":23.98626918},{"price":0.05431,"qty":17.14040783},{"price":0.05432,"qty":3.73595915},{"price":0.05433,"qty":2.81430000},{"price":0.05434,"qty":0.68820000},{"price":0.05435,"qty":11.87732014}],"checksum":837313468}]}
{"channel":"book","type":"snapshot","data":[{"symbol":"BTC/USD","bids":[{"price":68200.1,"qty":11.96415600},{"price":68195.4,"qty":0.00010000},{"price":68186.3,"qty":0.33750000},{"price":68185.5,"qty":0.01353482},{"price":68185.2,"qty":0.04828856},{"price":68183.9,"qty":1.46661981},{"price":68183.4,"qty":0.00035492},{"price":68180.0,"qty":0.15000000},{"price":68179.5,"qty":0.30954789},{"price":68179.4,"qty":1.80421809}],"asks":[{"price":68200.2,"qty":3.13989060},{"price":68200.6,"qty":1.46626299},{"price":68200.9,"qty":1.46625649},{"price":68202.0,"qty":0.17890000},{"price":68204.0,"qty":0.00010000},{"price":68205.4,"qty":0.09927886},{"price":68207.0,"qty":0.12646589},{"price":68207.1,"qty":0.33750000},{"price":68209.9,"qty":0.38160000},{"price":68210.7,"qty":0.08412000}],"checksum":2741596154}]}
{"channel":"book","type":"snapshot","data":[{"symbol":"ETH/USD","bids":[{"price":3698.70,"qty":0.26593017},{"price":3698.68,"qty":0.02662875},{"price":3698.67,"qty":1.01235805},{"price":3698.53,"qty":3.00000000},{"price":3698.52,"qty":27.03776944},{"price":3698.51,"qty":0.31854025},{"price":3698.37,"qty":3.00000000},{"price":3698.36,"qty":27.03897924},{"price":3698.33,"qty":4.80967403},{"price":3698.17,"qty":27.04036952}],"asks":[{"price":3698.80,"qty":3.58330136},{"price":3698.90,"qty":3.73750000},{"price":3699.06,"qty":27.03389693},{"price":3699.14,"qty":4.05512812},{"price":3699.17,"qty":3.18750000},{"price":3699.31,"qty":0.40085891},{"price":3699.32,"qty":27.03204938},{"price":3699.35,"qty":4.05512812},{"price":3699.48,"qty":0.18297052},{"price":3699.49,"qty":3.30000000}],"checksum":4241460169}]}
{"channel":"book","type":"update","data":[{"symbol":"ETH/USD","bids":[],"asks":[{"price":3698.85,"qty":27.03543711}],"checksum":1222856726,"timestamp":"2024-05-24T15:53:59.340607Z"}]}
{"channel":"book","type":"update","data":[{"symbol":"ETH/USD","bids":[{"price":3698.57,"qty":27.03746839}],"asks":[],"checksum":1819310489,"timestamp":"2024-05-24T15:53:59.340644Z"}]}
{"channel":"book","type":"update","data":[{"symbol":"BTC/USD","bids":[{"price":68183.9,"qty":0.00000000},{"price":68178.8,"qty":0.11607238}],"asks":[],"checksum":2618098102,"timestamp":"2024-05-24T15:53:59.357969Z"}]}
{"channel":"book","type":"update","data":[{"symbol":"ETH/USD","bids":[],"asks":[{"price":3698.85,"qty":0.00000000},{"price":3699.49,"qty":3.30000000}],"checksum":3629949510,"timestamp":"2024-05-24T15:53:59.359897Z"}]}
{"channel":"book","type":"update","data":[{"symbol":"ETH/USD","bids":[{"price":3698.57,"qty":0.00000000},{"price":3698.17,"qty":27.04036952}],"asks":[],"checksum":4241460169,"timestamp":"2024-05-24T15:53:59.359914Z"}]}
{"channel":"book","type":"update","data":[{"symbol":"ETH/USD","bids":[{"price":3698.36,"qty":0.00000000},{"price":3698.16,"qty":0.75856873}],"asks":[],"checksum":1047765111,"timestamp":"2024-05-24T15:53:59.374246Z"}]}
{"channel":"book","type":"update","data":[{"symbol":"ETH/USD","bids":[{"price":3698.52,"qty":0.00000000},{"price":3698.14,"qty":0.72912968}],"asks":[],"checksum":931279308,"timestamp":"2024-05-24T15:53:59.374312Z"}]}
{"channel":"book","type":"update","data":[{"symbol":"ETH/USD","bids":[{"price":3698.47,"qty":27.03815165}],"asks":[],"checksum":978875713,"timestamp":"2024-05-24T15:53:59.378178Z"}]}
{"channel":"book","type":"update","data":[{"symbol":"ETH/USD","bids":[],"asks":[{"price":3699.15,"qty":27.03327680}],"checksum":2769777620,"timestamp":"2024-05-24T15:53:59.378283Z"}]}
{"channel":"book","type":"update","data":[{"symbol":"ETH/USD","bids":[],"asks":[{"price":3699.06,"qty":0.00000000},{"price":3699.49,"qty":3.30000000}],"checksum":1372150197,"timestamp":"2024-05-24T15:53:59.414399Z"}]}
{"channel":"book","type":"update","data":[{"symbol":"ETH/USD","bids":[],"asks":[{"price":3698.92,"qty":27.03492813}],"checksum":1009042157,"timestamp":"2024-05-24T15:53:59.418531Z"}]}
{"channel":"book","type":"update","data":[{"symbol":"ETH/USD","bids":[{"price":3698.66,"qty":27.03677254}],"asks":[],"checksum":954260360,"timestamp":"2024-05-24T15:53:59.418577Z"}]}
{"channel":"book","type":"update","data":[{"symbol":"ETH/USD","bids":[{"price":3698.66,"qty":0.00000000},{"price":3698.16,"qty":0.75856873}],"asks":[],"checksum":1009042157,"timestamp":"2024-05-24T15:53:59.424371Z"}]}
{"channel":"book","type":"update","data":[{"symbol":"ETH/USD","bids":[],"asks":[{"price":3698.92,"qty":0.00000000},{"price":3699.49,"qty":3.30000000}],"checksum":1372150197,"timestamp":"2024-05-24T15:53:59.424455Z"}]}
{"channel":"book","type":"update","data":[{"symbol":"ETH/USD","bids":[],"asks":[{"price":3699.01,"qty":27.03432134}],"checksum":2500815147,"timestamp":"2024-05-24T15:53:59.428129Z"}]}
{"channel":"book","type":"update","data":[{"symbol":"ETH/USD","bids":[{"price":3698.67,"qty":28.04905488}],"asks":[],"checksum":982301713,"timestamp":"2024-05-24T15:53:59.472916Z"}]}
{"channel":"book","type":"update","data":[{"symbol":"ETH/USD","bids":[],"asks":[{"price":3698.93,"qty":27.03485243}],"checksum":1034510313,"timestamp":"2024-05-24T15:53:59.473028Z"}]}
{"channel":"book","type":"update","data":[{"symbol":"ETH/USD","bids":[],"asks":[{"price":3698.80,"qty":0.39580136}],"checksum":2245488765,"timestamp":"2024-05-24T15:53:59.475886Z"}]}
{"channel":"book","type":"update","data":[{"symbol":"ETH/USD","bids":[{"price":3698.67,"qty":1.01235805}],"asks":[],"checksum":513938200,"timestamp":"2024-05-24T15:53:59.485534Z"}]}
{"channel":"book","type":"update","data":[{"symbol":"ETH/USD","bids":[],"asks":[{"price":3699.31,"qty":0.00000000},{"price":3699.48,"qty":0.18297052}],"checksum":1106362495,"timestamp":"2024-05-24T15:53:59.485835Z"}]}
{"channel":"book","type":"update","data":[{"symbol":"BTC/USD","bids":[{"price":68200.1,"qty":11.96425600}],"asks":[],"checksum":396809,"timestamp":"2024-05-24T15:53:59.502680Z"}]}
{"channel":"book","type":"update","data":[{"symbol":"ETH/USD","bids":[{"price":3698.68,"qty":27.06328232}],"asks":[],"checksum":4122459762,"timestamp":"2024-05-24T15:53:59.543105Z"}]}
{"channel":"book","type":"update","data":[{"symbol":"ETH/USD","bids":[],"asks":[{"price":3699.17,"qty":0.00000000},{"price":3699.49,"qty":3.30000000}],"checksum":2683310623,"timestamp":"2024-05-24T15:53:59.547979Z"}]}
{"channel":"book","type":"update","data":[{"symbol":"ETH/USD","bids":[{"price":3698.68,"qty":0.02662875}],"asks":[],"checksum":2279372925,"timestamp":"2024-05-24T15:53:59.567169Z"}]}
{"channel":"book","type":"update","data":[{"symbol":"ETH/USD","bids":[],"asks":[{"price":3699.01,"qty":0.00000000},{"price":3699.58,"qty":0.81451322}],"checksum":1386314842,"timestamp":"2024-05-24T15:53:59.567267Z"}]}
{"channel":"book","type":"update","data":[{"symbol":"ETH/USD","bids":[{"price":3698.57,"qty":27.03743076}],"asks":[],"checksum":3604152810,"timestamp":"2024-05-24T15:53:59.571080Z"}]}
{"channel":"book","type":"update","data":[{"symbol":"ETH/USD","bids":[],"asks":[{"price":3698.89,"qty":27.03514441}],"checksum":4189543046,"timestamp":"2024-05-24T15:53:59.571127Z"}]}
{"channel":"book","type":"update","data":[{"symbol":"ETH/BTC","bids":[{"price":0.05425,"qty":4.93728080}],"asks":[],"checksum":472430474,"timestamp":"2024-05-24T15:53:59.591215Z"}]}
{"channel":"book","type":"update","data":[{"symbol":"ETH/USD","bids":[],"asks":[{"price":3699.35,"qty":4.45600415}],"checksum":1729468368,"timestamp":"2024-05-24T15:53:59.595803Z"}]}
{"channel":"book","type":"update","data":[{"symbol":"ETH/USD","bids":[],"asks":[{"price":3698.89,"qty":0.00000000},{"price":3699.58,"qty":0.81451322}],"checksum":1283302870,"timestamp":"2024-05-24T15:53:59.617603Z"}]}
{"channel":"book","type":"update","data":[{"symbol":"ETH/USD","bids":[],"asks":[{"price":3698.91,"qty":27.03501193}],"checksum":2101752620,"timestamp":"2024-05-24T15:53:59.621737Z"}]}
{"channel":"book","type":"update","data":[{"symbol":"ETH/USD","bids":[{"price":3698.65,"qty":27.03685636}],"asks":[],"checksum":534190858,"timestamp":"2024-05-24T15:53:59.621803Z"}]}
{"channel":"book","type":"update","data":[{"symbol":"ETH/USD","bids":[{"price":3698.57,"qty":0.00000000},{"price":3698.17,"qty":27.04036952}],"asks":[],"checksum":3000915317,"timestamp":"2024-05-24T15:53:59.628407Z"}]}
{"channel":"book","type":"update","data":[{"symbol":"ETH/USD","bids":[{"price":3698.53,"qty":0.00000000},{"price":3698.16,"qty":0.75856873}],"asks":[],"checksum":4165877388,"timestamp":"2024-05-24T15:53:59.651976Z"}]}
{"channel":"book","type":"update","data":[{"symbol":"ETH/USD","bids":[{"price":3698.37,"qty":0.00000000},{"price":3698.14,"qty":0.72912968}],"asks":[],"checksum":2734519576,"timestamp":"2024-05-24T15:53:59.696755Z"}]}
{"channel":"book","type":"update","data":[{"symbol":"ETH/USD","bids":[{"price":3698.65,"qty":0.00000000},{"price":3698.06,"qty":2.11000000}],"asks":[],"checksum":3796813231,"timestamp":"2024-05-24T15:53:59.709080Z"}]}
{"channel":"book","type":"update","data":[{"symbol":"ETH/USD","bids":[{"price":3698.63,"qty":27.03698445}],"asks":[],"checksum":4240649565,"timestamp":"2024-05-24T15:53:59.709092Z"}]}
{"channel":"book","type":"update","data":[{"symbol":"ETH/USD","bids":[],"asks":[{"price":3698.91,"qty":0.00000000},{"price":3699.58,"qty":0.81451322}],"checksum":3790646506,"timestamp":"2024-05-24T15:53:59.709129Z"}]}
{"channel":"book","type":"update","data":[{"symbol":"BTC/USD","bids":[{"price":68184.0,"qty":1.46661966}],"asks":[],"checksum":2922955097,"timestamp":"2024-05-24T15:53:59.716162Z"}]}
{"channel":"book","type":"update","data":[{"symbol":"ETH/USD","bids":[{"price":3698.63,"qty":0.00000000},{"price":3698.06,"qty":2.11000000}],"asks":[],"checksum":1725896383,"timestamp":"2024-05-24T15:53:59.717684Z"}]}
{"channel":"book","type":"update","data":[{"symbol":"ETH/USD","bids":[],"asks":[{"price":3698.87,"qty":27.03529363}],"checksum":2310724953,"timestamp":"2024-05-24T15:53:59.720788Z"}]}
{"channel":"book","type":"update","data":[{"symbol":"ETH/USD","bids":[{"price":3698.38,"qty":27.03882327}],"asks":[],"checksum":2567412137,"timestamp":"2024-05-24T15:53:59.720829Z"}]}
{"channel":"book","type":"update","data":[{"symbol":"BTC/USD","bids":[{"price":68184.0,"qty":0.00000000},{"price":68178.8,"qty":0.11607238}],"asks":[],"checksum":396809,"timestamp":"2024-05-24T15:53:59.722392Z"}]}
{"channel":"book","type":"update","data":[{"symbol":"ETH/USD","bids":[{"price":3698.47,"qty":0.00000000},{"price":3698.06,"qty":2.11000000}],"asks":[],"checksum":1602153813,"timestamp":"2024-05-24T15:53:59.723449Z"}]}
{"channel":"book","type":"update","data":[{"symbol":"ETH/USD","bids":[],"asks":[{"price":3698.87,"qty":0.00000000},{"price":3699.58,"qty":0.81451322}],"checksum":2954569395,"timestamp":"2024-05-24T15:53:59.724511Z"}]}
{"channel":"book","type":"update","data":[{"symbol":"ETH/BTC","bids":[{"price":0.05425,"qty":5.38728080}],"asks":[],"checksum":4281955239,"timestamp":"2024-05-24T15:53:59.739964Z"}]}
{"channel":"book","type":"update","data":[{"symbol":"ETH/USD","bids":[],"asks":[{"price":3699.17,"qty":3.18750000}],"checksum":1876148635,"timestamp":"2024-05-24T15:53:59.760850Z"}]}
{"channel":"book","type":"update","data":[{"symbol":"ETH/USD","bids":[{"price":3698.57,"qty":27.03740356}],"asks":[],"checksum":3927268404,"timestamp":"2024-05-24T15:53:59.763205Z"}]}
{"channel":"book","type":"update","data":[{"symbol":"ETH/USD","bids":[],"asks":[{"price":3699.17,"qty":0.00000000},{"price":3699.58,"qty":0.81451322}],"checksum":3749657641,"timestamp":"2024-05-24T15:53:59.766024Z"}]}
{"channel":"book","type":"update","data":[{"symbol":"BTC/USD","bids":[{"price":68179.6,"qty":0.00248023}],"asks":[],"checksum":1430671431,"timestamp":"2024-05-24T15:53:59.770369Z"}]}
{"channel":"book","type":"update","data":[{"symbol":"ETH/USD","bids":[{"price":3698.52,"qty":27.03783196}],"asks":[],"checksum":350493759,"timestamp":"2024-05-24T15:53:59.787407Z"}]}
{"channel":"book","type":"update","data":[{"symbol":"ETH/USD","bids":[],"asks":[{"price":3698.86,"qty":27.03536663}],"checksum":3458586634,"timestamp":"2024-05-24T15:53:59.787428Z"}]}
{"channel":"book","type":"update","data":[{"symbol":"ETH/USD","bids":[],"asks":[{"price":3699.17,"qty":3.18750000}],"checksum":3764158676,"timestamp":"2024-05-24T15:53:59.788768Z"}]}
{"channel":"book","type":"update","data":[{"symbol":"ETH/USD","bids":[],"asks":[{"price":3699.17,"qty":0.00000000},{"price":3699.49,"qty":3.30000000}],"checksum":3458586634,"timestamp":"2024-05-24T15:53:59.807166Z"}]}
{"channel":"book","type":"update","data":[{"symbol":"ETH/USD","bids":[],"asks":[{"price":3699.48,"qty":0.00000000},{"price":3699.58,"qty":0.81451322},{"price":3699.57,"qty":0.18297050}],"checksum":2652258384,"timestamp":"2024-05-24T15:53:59.811506Z"}]}
{"channel":"book","type":"update","data":[{"symbol":"ETH/USD","bids":[{"price":3698.38,"qty":0.00000000},{"price":3698.14,"qty":0.72912968}],"asks":[],"checksum":2242909819,"timestamp":"2024-05-24T15:53:59.815874Z"}]}
{"channel":"book","type":"update","data":[{"symbol":"ETH/USD","bids":[],"asks":[{"price":3698.86,"qty":0.00000000},{"price":3699.58,"qty":0.81451322}],"checksum":2263113537,"timestamp":"2024-05-24T15:53:59.815919Z"}]}
{"channel":"book","type":"update","data":[{"symbol":"ETH/USD","bids":[{"price":3698.57,"qty":0.00000000},{"price":3698.06,"qty":2.11000000}],"asks":[],"checksum":1593909080,"timestamp":"2024-05-24T15:53:59.815974Z"}]}
{"channel":"book","type":"update","data":[{"symbol":"ETH/USD","bids":[],"asks":[{"price":3698.93,"qty":0.00000000},{"price":3699.61,"qty":4.22000000}],"checksum":2357046461,"timestamp":"2024-05-24T15:53:59.816098Z"}]}
{"channel":"book","type":"update","data":[{"symbol":"ETH/USD","bids":[],"asks":[{"price":3699.57,"qty":0.00000000},{"price":3699.64,"qty":3.18750000},{"price":3699.60,"qty":0.18297050}],"checksum":1798891944,"timestamp":"2024-05-24T15:53:59.820307Z"}]}
{"channel":"book","type":"update","data":[{"symbol":"ETH/USD","bids":[{"price":3698.67,"qty":28.04907127}],"asks":[],"checksum":1466264059,"timestamp":"2024-05-24T15:53:59.820992Z"}]}
{"channel":"book","type":"update","data":[{"symbol":"ETH/USD","bids":[],"asks":[{"price":3699.02,"qty":27.03425116}],"checksum":2793070140,"timestamp":"2024-05-24T15:53:59.821082Z"}]}
{"channel":"book","type":"update","data":[{"symbol":"ETH/USD","bids":[],"asks":[{"price":3698.95,"qty":27.03472547}],"checksum":1757353245,"timestamp":"2024-05-24T15:53:59.851943Z"}]}
{"channel":"book","type":"update","data":[{"symbol":"ETH/USD","bids":[{"price":3698.67,"qty":1.01235805}],"asks":[],"checksum":71488014,"timestamp":"2024-05-24T15:53:59.859995Z"}]}
{"channel":"book","type":"update","data":[{"symbol":"ETH/USD","bids":[],"asks":[{"price":3698.95,"qty":0.00000000},{"price":3699.60,"qty":0.18297050}],"checksum":2691525753,"timestamp":"2024-05-24T15:53:59.860003Z"}]}
{"channel":"book","type":"update","data":[{"symbol":"ETH/USD","bids":[{"price":3698.66,"qty":27.03678893}],"asks":[],"checksum":3035723933,"timestamp":"2024-05-24T15:53:59.872600Z"}]}
{"channel":"book","type":"update","data":[{"symbol":"BTC/USD","bids":[{"price":68184.0,"qty":1.46661966}],"asks":[],"checksum":3430171478,"timestamp":"2024-05-24T15:53:59.912760Z"}]}
{"channel":"book","type":"update","data":[{"symbol":"ETH/USD","bids":[],"asks":[{"price":3699.02,"qty":0.00000000},{"price":3699.61,"qty":4.22000000}],"checksum":1173278554,"timestamp":"2024-05-24T15:53:59.913306Z"}]}
{"channel":"book","type":"update","data":[{"symbol":"ETH/USD","bids":[{"price":3698.66,"qty":0.00000000},{"price":3698.06,"qty":2.11000000}],"asks":[],"checksum":1798891944,"timestamp":"2024-05-24T15:53:59.913339Z"}]}
{"channel":"book","type":"update","data":[{"symbol":"BTC/USD","bids":[{"price":68184.0,"qty":0.00000000},{"price":68179.4,"qty":1.80421809}],"asks":[],"checksum":1430671431,"timestamp":"2024-05-24T15:53:59.916192Z"}]}
{"channel":"book","type":"update","data":[{"symbol":"ETH/USD","bids":[],"asks":[{"price":3698.90,"qty":30.77258506}],"checksum":1616581513,"timestamp":"2024-05-24T15:53:59.917060Z"}]}
{"channel":"book","type":"update","data":[{"symbol":"ETH/USD","bids":[],"asks":[{"price":3698.90,"qty":3.73750000}],"checksum":1798891944,"timestamp":"2024-05-24T15:53:59.926123Z"}]}
{"channel":"book","type":"update","data":[{"symbol":"ETH/USD","bids":[{"price":3698.61,"qty":27.03714855}],"asks":[],"checksum":1746675049,"timestamp":"2024-05-24T15:53:59.929486Z"}]}
{"channel":"book","type":"update","data":[{"symbol":"ETH/USD","bids":[{"price":3698.61,"qty":0.00000000},{"price":3698.06,"qty":2.11000000}],"asks":[],"checksum":1798891944,"timestamp":"2024-05-24T15:53:59.935431Z"}]}
{"channel":"book","type":"update","data":[{"symbol":"ETH/USD","bids":[{"price":3698.53,"qty":3.00000000}],"asks":[],"checksum":2170729041,"timestamp":"2024-05-24T15:53:59.948228Z"}]}
{"channel":"book","type":"update","data":[{"symbol":"BTC/USD","bids":[{"price":68182.3,"qty":1.46665595}],"asks":[],"checksum":3962570497,"timestamp":"2024-05-24T15:53:59.958870Z"}]}
{"channel":"book","type":"update","data":[{"symbol":"BTC/USD","bids":[{"price":68183.6,"qty":1.46662700}],"asks":[],"checksum":1163996405,"timestamp":"2024-05-24T15:53:59.962928Z"}]}
{"channel":"book","type":"update","data":[{"symbol":"BTC/USD","bids":[{"price":68183.6,"qty":0.00000000},{"price":68179.5,"qty":0.30954789}],"asks":[],"checksum":3962570497,"timestamp":"2024-05-24T15:53:59.970490Z"}]}
{"channel":"book","type":"update","data":[{"symbol":"ETH/USD","bids":[],"asks":[{"price":3699.15,"qty":0.00000000},{"price":3699.64,"qty":3.18750000}],"checksum":3361949649,"timestamp":"2024-05-24T15:53:59.978027Z"}]}
{"channel":"book","type":"update","data":[{"symbol":"ETH/USD","bids":[],"asks":[{"price":3699.06,"qty":27.03393832}],"checksum":1538637979,"timestamp":"2024-05-24T15:53:59.982336Z"}]}
{"channel":"book","type":"update","data":[{"symbol":"ETH/USD","bids":[{"price":3698.55,"qty":27.03756629}],"asks":[],"checksum":3273425953,"timestamp":"2024-05-24T15:53:59.982370Z"}]}
{"channel":"book","type":"update","data":[{"symbol":"ETH/USD","bids":[],"asks":[{"price":3698.84,"qty":27.03552547}],"checksum":548067020,"timestamp":"2024-05-24T15:53:59.982393Z"}]}
{"channel":"book","type":"update","data":[{"symbol":"ETH/USD","bids":[],"asks":[{"price":3698.84,"qty":0.00000000},{"price":3699.61,"qty":4.22000000}],"checksum":3273425953,"timestamp":"2024-05-24T15:53:59.990335Z"}]}
{"channel":"book","type":"update","data":[{"symbol":"ETH/USD","bids":[{"price":3698.55,"qty":0.00000000},{"price":3698.14,"qty":0.72912968}],"asks":[],"checksum":1538637979,"timestamp":"2024-05-24T15:53:59.990481Z"}]}
{"channel":"book","type":"update","data":[{"symbol":"BTC/USD","bids":[{"price":68183.9,"qty":1.46662069}],"asks":[],"checksum":2489336687,"timestamp":"2024-05-24T15:54:00.013814Z"}]}
{"channel":"book","type":"update","data":[{"symbol":"BTC/USD","bids":[{"price":68182.3,"qty":0.00000000},{"price":68179.5,"qty":0.30954789}],"asks":[],"checksum":160360831,"timestamp":"2024-05-24T15:54:00.018459Z"}]}
{"channel":"book","type":"update","data":[{"symbol":"ETH/USD","bids":[{"price":3698.52,"qty":0.00000000},{"price":3698.06,"qty":2.11000000}],"asks":[],"checksum":3467998709,"timestamp":"2024-05-24T15:54:00.019975Z"}]}
{"channel":"book","type":"update","data":[{"symbol":"ETH/BTC","bids":[{"price":0.05425,"qty":4.93728080}],"asks":[],"checksum":472430474,"timestamp":"2024-05-24T15:54:00.020373Z"}]}
{"channel":"book","type":"update","data":[{"symbol":"ETH/BTC","bids":[{"price":0.05425,"qty":4.48728080}],"asks":[],"checksum":837313468,"timestamp":"2024-05-24T15:54:00.020525Z"}]}
{"channel":"book","type":"update","data":[{"symbol":"ETH/USD","bids":[],"asks":[{"price":3698.98,"qty":27.03448490}],"checksum":3607281322,"timestamp":"2024-05-24T15:54:00.024028Z"}]}
{"channel":"book","type":"update","data":[{"symbol":"ETH/USD","bids":[{"price":3698.37,"qty":27.03887111}],"asks":[],"checksum":1701322571,"timestamp":"2024-05-24T15:54:00.024042Z"}]}
{"channel":"book","type":"update","data":[{"symbol":"ETH/USD","bids":[{"price":3698.53,"qty":30.03770140}],"asks":[],"checksum":3898851673,"timestamp":"2024-05-24T15:54:00.030516Z"}]}
{"channel":"book","type":"update","data":[{"symbol":"ETH/USD","bids":[],"asks":[{"price":3698.89,"qty":27.03514036}],"checksum":1773229914,"timestamp":"2024-05-24T15:54:00.033921Z"}]}
{"channel":"book","type":"update","data":[{"symbol":"ETH/USD","bids":[{"price":3698.60,"qty":27.03721235}],"asks":[],"checksum":4233012659,"timestamp":"2024-05-24T15:54:00.033959Z"}]}
{"channel":"book","type":"update","data":[{"symbol":"ETH/USD","bids":[{"price":3698.53,"qty":3.00000000}],"asks":[],"checksum":2878032921,"timestamp":"2024-05-24T15:54:00.039272Z"}]}
{"channel":"book","type":"update","data":[{"symbol":"ETH/USD","bids":[],"asks":[{"price":3698.89,"qty":0.00000000},{"price":3699.60,"qty":0.18297050}],"checksum":839110453,"timestamp":"2024-05-24T15:54:00.039468Z"}]}
{"channel":"book","type":"update","data":[{"symbol":"ETH/USD","bids":[],"asks":[{"price":3699.06,"qty":0.00000000},{"price":3699.61,"qty":4.22000000}],"checksum":2910553660,"timestamp":"2024-05-24T15:54:00.047163Z"}]}
{"channel":"book","type":"update","data":[{"symbol":"ETH/USD","bids":[{"price":3698.37,"qty":0.00000000},{"price":3698.14,"qty":0.72912968}],"asks":[],"checksum":388920593,"timestamp":"2024-05-24T15:54:00.047235Z"}]}
{"channel":"book","type":"update","data":[{"symbol":"ETH/USD","bids":[],"asks":[{"price":3698.98,"qty":0.00000000},{"price":3699.64,"qty":3.18750000}],"checksum":87161742,"timestamp":"2024-05-24T15:54:00.047317Z"}]}
{"channel":"book","type":"update","data":[{"symbol":"ETH/USD","bids":[],"asks":[{"price":3699.32,"qty":0.00000000},{"price":3699.91,"qty":1.53600000}],"checksum":2546407409,"timestamp":"2024-05-24T15:54:00.047379Z"}]}
{"channel":"book","type":"update","data":[{"symbol":"ETH/USD","bids":[{"price":3698.60,"qty":0.00000000},{"price":3698.06,"qty":2.11000000}],"asks":[],"checksum":900679348,"timestamp":"2024-05-24T15:54:00.047418Z"}]}
{"channel":"book","type":"update","data":[{"symbol":"ETH/USD","bids":[],"asks":[{"price":3699.48,"qty":27.03089198}],"checksum":3308007587,"timestamp":"2024-05-24T15:54:00.051618Z"}]}
{"channel":"book","type":"update","data":[{"symbol":"BTC/USD","bids":[{"price":68184.4,"qty":1.46661108}],"asks":[],"checksum":4120431032,"timestamp":"2024-05-24T15:54:00.086732Z"}]}
{"channel":"book","type":"update","data":[{"symbol":"ETH/USD","bids":[{"price":3698.71,"qty":27.03645324}],"asks":[],"checksum":79966449,"timestamp":"2024-05-24T15:54:00.096307Z"}]}
{"channel":"book","type":"update","data":[{"symbol":"ETH/USD","bids":[],"asks":[{"price":3699.01,"qty":27.03429401}],"checksum":3819921594,"timestamp":"2024-05-24T15:54:00.096378Z"}]}
{"channel":"book","type":"update","data":[{"symbol":"ETH/USD","bids":[{"price":3698.71,"qty":0.00000000},{"price":3698.06,"qty":2.11000000}],"asks":[],"checksum":374439085,"timestamp":"2024-05-24T15:54:00.102018Z"}]}
{"channel":"book","type":"update","data":[{"symbol":"ETH/USD","bids":[],"asks":[{"price":3699.35,"qty":4.05512812}],"checksum":3283822701,"timestamp":"2024-05-24T15:54:00.119601Z"}]}
{"channel":"book","type":"update","data":[{"symbol":"ETH/USD","bids":[],"asks":[{"price":3698.90,"qty":0.55000000}],"checksum":2070674428,"timestamp":"2024-05-24T15:54:00.135304Z"}]}
{"channel":"book","type":"update","data":[{"symbol":"BTC/USD","bids":[{"price":68184.4,"qty":0.00000000},{"price":68179.5,"qty":0.30954789}],"asks":[],"checksum":160360831,"timestamp":"2024-05-24T15:54:00.135646Z"}]}
{"channel":"book","type":"update","data":[{"symbol":"BTC/USD","bids":[{"price":68184.4,"qty":1.46661108}],"asks":[],"checksum":4120431032,"timestamp":"2024-05-24T15:54:00.140557Z"}]}
{"channel":"book","type":"update","data":[{"symbol":"BTC/USD","bids":[{"price":68184.4,"qty":0.00000000},{"price":68179.5,"qty":0.30954789}],"asks":[],"checksum":160360831,"timestamp":"2024-05-24T15:54:00.149419Z"}]}
{"channel":"book","type":"update","data":[{"symbol":"BTC/USD","bids":[],"asks":[{"price":68209.8,"qty":0.91228408}],"checksum":749365199,"timestamp":"2024-05-24T15:54:00.178262Z"}]}
{"channel":"book","type":"update","data":[{"symbol":"ETH/USD","bids":[{"price":3698.71,"qty":27.03645324}],"asks":[],"checksum":4289608543,"timestamp":"2024-05-24T15:54:00.179697Z"}]}
{"channel":"book","type":"update","data":[{"symbol":"ETH/USD","bids":[{"price":3698.71,"qty":0.00000000},{"price":3698.06,"qty":2.11000000}],"asks":[],"checksum":2070674428,"timestamp":"2024-05-24T15:54:00.183958Z"}]}
{"channel":"book","type":"update","data":[{"symbol":"ETH/USD","bids":[],"asks":[{"price":3699.01,"qty":0.00000000},{"price":3699.64,"qty":3.18750000}],"checksum":1113111111,"timestamp":"2024-05-24T15:54:00.202790Z"}]}
{"channel":"book","type":"update","data":[{"symbol":"ETH/USD","bids":[],"asks":[{"price":3699.49,"qty":0.00000000},{"price":3699.91,"qty":1.53600000}],"checksum":2295677944,"timestamp":"2024-05-24T15:54:00.205302Z"}]}
{"channel":"book","type":"update","data":[{"symbol":"ETH/USD","bids":[],"asks":[{"price":3699.43,"qty":3.30000000}],"checksum":3533701672,"timestamp":"2024-05-24T15:54:00.205444Z"}]}
{"channel":"book","type":"update","data":[{"symbol":"ETH/USD","bids":[],"asks":[{"price":3699.00,"qty":27.03435620}],"checksum":211968,"timestamp":"2024-05-24T15:54:00.206062Z"}]}
{"channel":"book","type":"update","data":[{"symbol":"ETH/USD","bids":[],"asks":[{"price":3699.13,"qty":0.04046589}],"checksum":651440117,"timestamp":"2024-05-24T15:54:00.207089Z"}]}
{"channel":"book","type":"update","data":[{"symbol":"ETH/USD","bids":[],"asks":[{"price":3699.00,"qty":0.00000000},{"price":3699.61,"qty":4.22000000}],"checksum":3527249141,"timestamp":"2024-05-24T15:54:00.208817Z"}]}
{"channel":"book","type":"update","data":[{"symbol":"ETH/USD","bids":[],"asks":[{"price":3699.13,"qty":0.00000000},{"price":3699.64,"qty":3.18750000}],"checksum":3533701672,"timestamp":"2024-05-24T15:54:00.210887Z"}]}
{"channel":"book","type":"update","data":[{"symbol":"BTC/USD","bids":[{"price":68184.4,"qty":1.46661108}],"asks":[],"checksum":1054629562,"timestamp":"2024-05-24T15:54:00.214520Z"}]}
{"channel":"book","type":"update","data":[{"symbol":"ETH/USD","bids":[],"asks":[{"price":3699.13,"qty":0.04046589}],"checksum":3527249141,"timestamp":"2024-05-24T15:54:00.215128Z"}]}
{"channel":"book","type":"update","data":[{"symbol":"BTC/USD","bids":[{"price":68184.4,"qty":0.00000000},{"price":68179.5,"qty":0.30954789}],"asks":[],"checksum":749365199,"timestamp":"2024-05-24T15:54:00.218105Z"}]}
{"channel":"book","type":"update","data":[{"symbol":"ETH/USD","bids":[],"asks":[{"price":3699.48,"qty":0.00000000},{"price":3699.64,"qty":3.18750000}],"checksum":2065175198,"timestamp":"2024-05-24T15:54:00.222599Z"}]}
{"channel":"book","type":"update","data":[{"symbol":"ETH/USD","bids":[],"asks":[{"price":3698.88,"qty":27.03525967}],"checksum":666472511,"timestamp":"2024-05-24T15:54:00.319932Z"}]}
{"channel":"book","type":"update","data":[{"symbol":"ETH/USD","bids":[{"price":3698.60,"qty":27.03724260}],"asks":[],"checksum":1267257234,"timestamp":"2024-05-24T15:54:00.320017Z"}]}
{"channel":"book","type":"update","data":[{"symbol":"ETH/USD","bids":[],"asks":[{"price":3699.16,"qty":27.03319095}],"checksum":1123540737,"timestamp":"2024-05-24T15:54:00.320173Z"}]}
{"channel":"book","type":"update","data":[{"symbol":"ETH/USD","bids":[],"asks":[{"price":3699.13,"qty":0.00000000},{"price":3699.61,"qty":4.22000000}],"checksum":93648495,"timestamp":"2024-05-24T15:54:00.323258Z"}]}
{"channel":"book","type":"update","data":[{"symbol":"ETH/USD","bids":[{"price":3698.35,"qty":27.03903061}],"asks":[],"checksum":3415240830,"timestamp":"2024-05-24T15:54:00.324049Z"}]}
{"channel":"book","type":"update","data":[{"symbol":"ETH/USD","bids":[{"price":3698.68,"qty":3.02662875}],"asks":[],"checksum":3173547521,"timestamp":"2024-05-24T15:54:00.453632Z"}]}
{"channel":"book","type":"update","data":[{"symbol":"ETH/USD","bids":[{"price":3698.53,"qty":0.00000000},{"price":3698.14,"qty":0.72912968}],"asks":[],"checksum":3193298296,"timestamp":"2024-05-24T15:54:00.453647Z"}]}
{"channel":"book","type":"update","data":[{"symbol":"ETH/USD","bids":[],"asks":[{"price":3699.17,"qty":3.18750000}],"checksum":4003314631,"timestamp":"2024-05-24T15:54:00.522413Z"}]}
{"channel":"book","type":"update","data":[{"symbol":"BTC/USD","bids":[{"price":68186.3,"qty":0.00000000},{"price":68179.4,"qty":1.80421809}],"asks":[],"checksum":4135814060,"timestamp":"2024-05-24T15:54:00.523778Z"}]}
{"channel":"book","type":"update","data":[{"symbol":"ETH/BTC","bids":[{"price":0.05425,"qty":4.93728080}],"asks":[],"checksum":472430474,"timestamp":"2024-05-24T15:54:00.525361Z"}]}
{"channel":"book","type":"update","data":[{"symbol":"ETH/USD","bids":[{"price":3698.33,"qty":1.62217403}],"asks":[],"checksum":534968454,"timestamp":"2024-05-24T15:54:00.525613Z"}]}
{"channel":"book","type":"update","data":[{"symbol":"BTC/USD","bids":[{"price":68184.1,"qty":1.46661729}],"asks":[],"checksum":3385024676,"timestamp":"2024-05-24T15:54:00.534637Z"}]}
{"channel":"book","type":"update","data":[{"symbol":"ETH/USD","bids":[],"asks":[{"price":3699.16,"qty":0.00000000},{"price":3699.61,"qty":4.22000000}],"checksum":3233028311,"timestamp":"2024-05-24T15:54:00.540735Z"}]}
{"channel":"book","type":"update","data":[{"symbol":"ETH/USD","bids":[{"price":3698.60,"qty":0.00000000},{"price":3698.06,"qty":2.11000000}],"asks":[],"checksum":2981482700,"timestamp":"2024-05-24T15:54:00.540760Z"}]}
{"channel":"book","type":"update","data":[{"symbol":"ETH/USD","bids":[],"asks":[{"price":3698.85,"qty":27.03549710}],"checksum":3024971272,"timestamp":"2024-05-24T15:54:00.546840Z"}]}
{"channel":"book","type":"update","data":[{"symbol":"ETH/USD","bids":[{"price":3698.57,"qty":27.03744325}],"asks":[],"checksum":2058489885,"timestamp":"2024-05-24T15:54:00.546969Z"}]}
{"channel":"book","type":"update","data":[{"symbol":"ETH/USD","bids":[{"price":3698.50,"qty":27.03797655}],"asks":[],"checksum":202012256,"timestamp":"2024-05-24T15:54:00.546996Z"}]}
{"channel":"book","type":"update","data":[{"symbol":"ETH/USD","bids":[],"asks":[{"price":3698.80,"qty":3.58330136}],"checksum":3481333079,"timestamp":"2024-05-24T15:54:00.548665Z"}]}
{"channel":"book","type":"update","data":[{"symbol":"ETH/USD","bids":[],"asks":[{"price":3699.26,"qty":1.62216965}],"checksum":1264483236,"timestamp":"2024-05-24T15:54:00.554125Z"}]}
{"channel":"book","type":"update","data":[{"symbol":"ETH/USD","bids":[{"price":3698.57,"qty":0.00000000},{"price":3698.14,"qty":0.72912968}],"asks":[],"checksum":876086795,"timestamp":"2024-05-24T15:54:00.569233Z"}]}
{"channel":"book","type":"update","data":[{"symbol":"ETH/USD","bids":[],"asks":[{"price":3698.85,"qty":0.00000000},{"price":3699.60,"qty":0.18297050}],"checksum":1385084748,"timestamp":"2024-05-24T15:54:00.569634Z"}]}
{"channel":"book","type":"update","data":[{"symbol":"ETH/USD","bids":[],"asks":[{"price":3699.32,"qty":27.03205216}],"checksum":3093099940,"timestamp":"2024-05-24T15:54:00.572741Z"}]}
{"channel":"book","type":"update","data":[{"symbol":"ETH/USD","bids":[{"price":3698.33,"qty":4.80967403}],"asks":[],"checksum":1227077349,"timestamp":"2024-05-24T15:54:00.578843Z"}]}
{"channel":"book","type":"update","data":[{"symbol":"ETH/USD","bids":[],"asks":[{"price":3698.79,"qty":2.75000000}],"checksum":811273121,"timestamp":"2024-05-24T15:54:00.584408Z"}]}
{"channel":"book","type":"update","data":[{"symbol":"ETH/USD","bids":[],"asks":[{"price":3699.17,"qty":0.00000000},{"price":3699.58,"qty":0.81451322}],"checksum":3912599706,"timestamp":"2024-05-24T15:54:00.588193Z"}]}
{"channel":"book","type":"update","data":[{"symbol":"ETH/USD","bids":[{"price":3698.33,"qty":1.62217403}],"asks":[],"checksum":407555035,"timestamp":"2024-05-24T15:54:00.588208Z"}]}
{"channel":"book","type":"update","data":[{"symbol":"ETH/USD","bids":[{"price":3698.70,"qty":0.00000000},{"price":3698.06,"qty":2.11000000}],"asks":[],"checksum":3680418145,"timestamp":"2024-05-24T15:54:00.589101Z"}]}
{"channel":"book","type":"update","data":[{"symbol":"ETH/USD","bids":[],"asks":[{"price":3698.79,"qty":5.93750000}],"checksum":3696555591,"timestamp":"2024-05-24T15:54:00.593113Z"}]}
{"channel":"book","type":"update","data":[{"symbol":"ETH/USD","bids":[],"asks":[{"price":3699.16,"qty":3.18750000}],"checksum":2279968255,"timestamp":"2024-05-24T15:54:00.595793Z"}]}
{"channel":"book","type":"update","data":[{"symbol":"ETH/USD","bids":[{"price":3698.31,"qty":3.18750000}],"asks":[],"checksum":3603552210,"timestamp":"2024-05-24T15:54:00.597436Z"}]}
{"channel":"book","type":"update","data":[{"symbol":"ETH/USD","bids":[],"asks":[{"price":3699.40,"qty":0.40090274}],"checksum":3592876901,"timestamp":"2024-05-24T15:54:00.613501Z"}]}
{"channel":"book","type":"update","data":[{"symbol":"ETH/USD","bids":[],"asks":[{"price":3698.77,"qty":3.18750000}],"checksum":908678862,"timestamp":"2024-05-24T15:54:00.618195Z"}]}
{"channel":"book","type":"update","data":[{"symbol":"ETH/USD","bids":[],"asks":[{"price":3698.80,"qty":0.39580136}],"checksum":2265989752,"timestamp":"2024-05-24T15:54:00.618456Z"}]}
{"channel":"book","type":"update","data":[{"symbol":"ETH/USD","bids":[],"asks":[{"price":3699.16,"qty":0.00000000},{"price":3699.40,"qty":0.40090274}],"checksum":1429143633,"timestamp":"2024-05-24T15:54:00.620871Z"}]}
{"channel":"book","type":"update","data":[{"symbol":"ETH/USD","bids":[{"price":3698.31,"qty":0.00000000},{"price":3698.06,"qty":2.11000000}],"asks":[],"checksum":67328636,"timestamp":"2024-05-24T15:54:00.620916Z"}]}
{"channel":"book","type":"update","data":[{"symbol":"ETH/USD","bids":[],"asks":[{"price":3699.14,"qty":7.24262812}],"checksum":1259001645,"timestamp":"2024-05-24T15:54:00.623932Z"}]}
{"channel":"book","type":"update","data":[{"symbol":"ETH/USD","bids":[{"price":3698.31,"qty":3.18750000}],"asks":[],"checksum":438734080,"timestamp":"2024-05-24T15:54:00.624947Z"}]}
{"channel":"book","type":"update","data":[{"symbol":"ETH/USD","bids":[],"asks":[{"price":3698.83,"qty":27.03563394}],"checksum":3755289126,"timestamp":"2024-05-24T15:54:00.634741Z"}]}
{"channel":"book","type":"update","data":[{"symbol":"ETH/USD","bids":[{"price":3698.55,"qty":27.03759348}],"asks":[],"checksum":749111615,"timestamp":"2024-05-24T15:54:00.634792Z"}]}
{"channel":"book","type":"update","data":[{"symbol":"ETH/USD","bids":[],"asks":[{"price":3699.06,"qty":27.03390994}],"checksum":1734195152,"timestamp":"2024-05-24T15:54:00.634808Z"}]}
{"channel":"book","type":"update","data":[{"symbol":"ETH/USD","bids":[],"asks":[{"price":3698.79,"qty":3.18750000}],"checksum":3037628356,"timestamp":"2024-05-24T15:54:00.649294Z"}]}
{"channel":"book","type":"update","data":[{"symbol":"BTC/USD","bids":[{"price":68184.1,"qty":0.00000000},{"price":68179.4,"qty":1.80421809}],"asks":[],"checksum":4135814060,"timestamp":"2024-05-24T15:54:00.652217Z"}]}
{"channel":"book","type":"update","data":[{"symbol":"ETH/USD","bids":[],"asks":[{"price":3698.79,"qty":0.00000000},{"price":3699.35,"qty":4.05512812}],"checksum":1079760806,"timestamp":"2024-05-24T15:54:00.652505Z"}]}
{"channel":"book","type":"update","data":[{"symbol":"BTC/USD","bids":[{"price":68184.3,"qty":1.46661223}],"asks":[],"checksum":1226734624,"timestamp":"2024-05-24T15:54:00.656035Z"}]}
{"channel":"book","type":"update","data":[{"symbol":"ETH/USD","bids":[{"price":3698.55,"qty":0.00000000},{"price":3698.14,"qty":0.72912968}],"asks":[],"checksum":3236764537,"timestamp":"2024-05-24T15:54:00.664221Z"}]}
{"channel":"book","type":"update","data":[{"symbol":"ETH/USD","bids":[],"asks":[{"price":3698.83,"qty":0.00000000},{"price":3699.40,"qty":0.40090274}],"checksum":3118963247,"timestamp":"2024-05-24T15:54:00.664243Z"}]}
{"channel":"book","type":"update","data":[{"symbol":"ETH/USD","bids":[],"asks":[{"price":3699.14,"qty":4.05512812}],"checksum":4142798718,"timestamp":"2024-05-24T15:54:00.725682Z"}]}
{"channel":"book","type":"update","data":[{"symbol":"ETH/USD","bids":[],"asks":[{"price":3698.77,"qty":0.00000000},{"price":3699.43,"qty":3.30000000}],"checksum":216827509,"timestamp":"2024-05-24T15:54:00.728304Z"}]}
{"channel":"book","type":"update","data":[{"symbol":"ETH/USD","bids":[],"asks":[{"price":3699.17,"qty":3.18750000}],"checksum":2741716167,"timestamp":"2024-05-24T15:54:00.739398Z"}]}
{"channel":"book","type":"update","data":[{"symbol":"ETH/USD","bids":[],"asks":[{"price":3698.85,"qty":27.03548252}],"checksum":2457904139,"timestamp":"2024-05-24T15:54:00.763258Z"}]}
{"channel":"book","type":"update","data":[{"symbol":"ETH/USD","bids":[{"price":3698.57,"qty":27.03745558}],"asks":[],"checksum":701986070,"timestamp":"2024-05-24T15:54:00.763321Z"}]}
{"channel":"book","type":"update","data":[{"symbol":"ETH/USD","bids":[],"asks":[{"price":3698.79,"qty":3.18750000}],"checksum":3150540027,"timestamp":"2024-05-24T15:54:00.766441Z"}]}
{"channel":"book","type":"update","data":[{"symbol":"ETH/USD","bids":[],"asks":[{"price":3699.17,"qty":0.00000000},{"price":3699.35,"qty":4.05512812}],"checksum":2923254065,"timestamp":"2024-05-24T15:54:00.769599Z"}]}
{"channel":"book","type":"update","data":[{"symbol":"ETH/USD","bids":[{"price":3698.50,"qty":0.00000000},{"price":3698.14,"qty":0.72912968}],"asks":[],"checksum":2984563286,"timestamp":"2024-05-24T15:54:00.787888Z"}]}
{"channel":"book","type":"update","data":[{"symbol":"ETH/USD","bids":[],"asks":[{"price":3698.85,"qty":0.00000000},{"price":3699.40,"qty":0.40090274}],"checksum":3290879543,"timestamp":"2024-05-24T15:54:00.787935Z"}]}
{"channel":"book","type":"update","data":[{"symbol":"ETH/USD","bids":[],"asks":[{"price":3698.88,"qty":0.00000000},{"price":3699.43,"qty":3.30000000}],"checksum":2956737113,"timestamp":"2024-05-24T15:54:00.792505Z"}]}
{"channel":"book","type":"update","data":[{"symbol":"ETH/USD","bids":[],"asks":[{"price":3698.79,"qty":0.00000000},{"price":3699.58,"qty":0.81451322}],"checksum":2095272389,"timestamp":"2024-05-24T15:54:00.793869Z"}]}
{"channel":"book","type":"update","data":[{"symbol":"ETH/USD","bids":[],"asks":[{"price":3698.94,"qty":27.03478379}],"checksum":1256446588,"timestamp":"2024-05-24T15:54:00.796084Z"}]}
{"channel":"book","type":"update","data":[{"symbol":"BTC/USD","bids":[{"price":68186.3,"qty":0.33750000}],"asks":[],"checksum":746335101,"timestamp":"2024-05-24T15:54:00.808024Z"}]}
{"channel":"book","type":"update","data":[{"symbol":"ETH/USD","bids":[{"price":3698.58,"qty":3.00000000}],"asks":[],"checksum":2804383299,"timestamp":"2024-05-24T15:54:00.808548Z"}]}
{"channel":"book","type":"update","data":[{"symbol":"BTC/USD","bids":[{"price":68184.3,"qty":0.00000000},{"price":68179.5,"qty":0.30954789}],"asks":[],"checksum":749365199,"timestamp":"2024-05-24T15:54:00.814776Z"}]}
{"channel":"book","type":"update","data":[{"symbol":"BTC/USD","bids":[{"price":68184.5,"qty":1.46660754}],"asks":[],"checksum":1046233564,"timestamp":"2024-05-24T15:54:00.818889Z"}]}
{"channel":"book","type":"update","data":[{"symbol":"ETH/BTC","bids":[{"price":0.05425,"qty":5.38728080}],"asks":[],"checksum":4281955239,"timestamp":"2024-05-24T15:54:00.826448Z"}]}
{"channel":"book","type":"update","data":[{"symbol":"ETH/USD","bids":[{"price":3698.68,"qty":6.21412875}],"asks":[],"checksum":2224652000,"timestamp":"2024-05-24T15:54:00.831966Z"}]}
{"channel":"book","type":"update","data":[{"symbol":"ETH/USD","bids":[],"asks":[{"price":3698.92,"qty":27.03492555}],"checksum":3208894170,"timestamp":"2024-05-24T15:54:00.833082Z"}]}
{"channel":"book","type":"update","data":[{"symbol":"ETH/USD","bids":[{"price":3698.64,"qty":27.03692561}],"asks":[],"checksum":2774577001,"timestamp":"2024-05-24T15:54:00.833284Z"}]}
{"channel":"book","type":"update","data":[{"symbol":"ETH/USD","bids":[],"asks":[{"price":3699.14,"qty":0.00000000},{"price":3699.43,"qty":3.30000000}],"checksum":2015650367,"timestamp":"2024-05-24T15:54:00.835115Z"}]}
{"channel":"book","type":"update","data":[{"symbol":"BTC/USD","bids":[{"price":68184.5,"qty":0.00000000},{"price":68179.5,"qty":0.30954789}],"asks":[],"checksum":749365199,"timestamp":"2024-05-24T15:54:00.835522Z"}]}
{"channel":"book","type":"update","data":[{"symbol":"BTC/USD","bids":[{"price":68181.1,"qty":1.46668161}],"asks":[],"checksum":1053370208,"timestamp":"2024-05-24T15:54:00.839485Z"}]}
{"channel":"book","type":"update","data":[{"symbol":"ETH/USD","bids":[],"asks":[{"price":3698.94,"qty":0.00000000},{"price":3699.58,"qty":0.81451322}],"checksum":2700659178,"timestamp":"2024-05-24T15:54:00.840027Z"}]}
{"channel":"book","type":"update","data":[{"symbol":"ETH/USD","bids":[],"asks":[{"price":3699.32,"qty":0.00000000},{"price":3699.60,"qty":0.18297050}],"checksum":14894066,"timestamp":"2024-05-24T15:54:00.840090Z"}]}
{"channel":"book","type":"update","data":[{"symbol":"ETH/USD","bids":[{"price":3698.17,"qty":0.00000000},{"price":3698.16,"qty":0.75856873}],"asks":[],"checksum":2363329123,"timestamp":"2024-05-24T15:54:00.840173Z"}]}
{"channel":"book","type":"update","data":[{"symbol":"ETH/USD","bids":[],"asks":[{"price":3698.92,"qty":0.00000000},{"price":3699.61,"qty":4.22000000}],"checksum":4178765319,"timestamp":"2024-05-24T15:54:00.842413Z"}]}
{"channel":"book","type":"update","data":[{"symbol":"ETH/USD","bids":[],"asks":[{"price":3699.06,"qty":0.00000000},{"price":3699.64,"qty":3.18750000}],"checksum":2516353765,"timestamp":"2024-05-24T15:54:00.842454Z"}]}
{"channel":"book","type":"update","data":[{"symbol":"ETH/USD","bids":[{"price":3698.64,"qty":0.00000000},{"price":3698.14,"qty":0.72912968}],"asks":[],"checksum":2959185631,"timestamp":"2024-05-24T15:54:00.842477Z"}]}
{"channel":"book","type":"update","data":[{"symbol":"ETH/USD","bids":[],"asks":[{"price":3699.44,"qty":4.05531449}],"checksum":3966406439,"timestamp":"2024-05-24T15:54:00.844042Z"}]}
{"channel":"book","type":"update","data":[{"symbol":"BTC/USD","bids":[{"price":68179.6,"qty":0.00000000},{"price":68179.5,"qty":0.30954789}],"asks":[],"checksum":3909252500,"timestamp":"2024-05-24T15:54:00.845094Z"}]}
{"channel":"book","type":"update","data":[{"symbol":"ETH/USD","bids":[],"asks":[{"price":3699.25,"qty":0.04046589}],"checksum":3467493639,"timestamp":"2024-05-24T15:54:00.846037Z"}]}
{"channel":"book","type":"update","data":[{"symbol":"ETH/USD","bids":[{"price":3698.69,"qty":27.03659944}],"asks":[],"checksum":827702858,"timestamp":"2024-05-24T15:54:00.848526Z"}]}
{"channel":"book","type":"update","data":[{"symbol":"ETH/USD","bids":[{"price":3698.68,"qty":3.02662875}],"asks":[],"checksum":825544405,"timestamp":"2024-05-24T15:54:00.851844Z"}]}
{"channel":"book","type":"update","data":[{"symbol":"ETH/USD","bids":[{"price":3698.69,"qty":0.00000000},{"price":3698.14,"qty":0.72912968}],"asks":[],"checksum":1962670748,"timestamp":"2024-05-24T15:54:00.852895Z"}]}
{"channel":"book","type":"update","data":[{"symbol":"ETH/USD","bids":[],"asks":[{"price":3698.80,"qty":0.00000000},{"price":3699.61,"qty":4.22000000}],"checksum":923806425,"timestamp":"2024-05-24T15:54:00.854595Z"}]}
{"channel":"book","type":"update","data":[{"symbol":"ETH/USD","bids":[],"asks":[{"price":3699.26,"qty":0.00000000},{"price":3699.64,"qty":3.18750000}],"checksum":791680368,"timestamp":"2024-05-24T15:54:00.857378Z"}]}
{"channel":"book","type":"update","data":[{"symbol":"ETH/USD","bids":[{"price":3698.68,"qty":6.21412875}],"asks":[],"checksum":2506501867,"timestamp":"2024-05-24T15:54:00.860543Z"}]}
{"channel":"book","type":"update","data":[{"symbol":"ETH/USD","bids":[{"price":3698.68,"qty":6.18750000},{"price":3698.69,"qty":0.02663894}],"asks":[],"checksum":4107688555,"timestamp":"2024-05-24T15:54:00.863445Z"}]}
{"channel":"book","type":"update","data":[{"symbol":"ETH/USD","bids":[],"asks":[{"price":3699.60,"qty":0.00000000},{"price":3699.91,"qty":1.53600000},{"price":3699.90,"qty":0.18297066}],"checksum":3082421928,"timestamp":"2024-05-24T15:54:00.865978Z"}]}
{"channel":"book","type":"update","data":[{"symbol":"ETH/USD","bids":[{"price":3698.68,"qty":3.00000000}],"asks":[],"checksum":2736073133,"timestamp":"2024-05-24T15:54:00.866452Z"}]}
{"channel":"book","type":"update","data":[{"symbol":"ETH/USD","bids":[{"price":3698.69,"qty":3.21413894}],"asks":[],"checksum":2765187814,"timestamp":"2024-05-24T15:54:00.869283Z"}]}
{"channel":"book","type":"update","data":[{"symbol":"ETH/BTC","bids":[{"price":0.05423,"qty":16.03493318}],"asks":[],"checksum":2387698969,"timestamp":"2024-05-24T15:54:00.869429Z"}]}
{"channel":"book","type":"update","data":[{"symbol":"ETH/BTC","bids":[{"price":0.05424,"qty":6.05003763}],"asks":[],"checksum":2492254553,"timestamp":"2024-05-24T15:54:00.873110Z"}]}
{"channel":"book","type":"update","data":[{"symbol":"ETH/USD","bids":[],"asks":[{"price":3699.07,"qty":27.03388485}],"checksum":1285473933,"timestamp":"2024-05-24T15:54:00.888392Z"}]}
{"channel":"book","type":"update","data":[{"symbol":"ETH/USD","bids":[{"price":3698.80,"qty":27.03575915}],"asks":[],"checksum":2323227440,"timestamp":"2024-05-24T15:54:00.888638Z"}]}
{"channel":"book","type":"update","data":[{"symbol":"ETH/USD","bids":[],"asks":[{"price":3699.25,"qty":0.00000000},{"price":3699.90,"qty":0.18297066}],"checksum":661955114,"timestamp":"2024-05-24T15:54:00.892067Z"}]}
{"channel":"book","type":"update","data":[{"symbol":"ETH/USD","bids":[{"price":3698.69,"qty":0.02663894}],"asks":[],"checksum":3309409494,"timestamp":"2024-05-24T15:54:00.892454Z"}]}
{"channel":"book","type":"update","data":[{"symbol":"ETH/USD","bids":[],"asks":[{"price":3699.07,"qty":0.00000000},{"price":3699.91,"qty":1.53600000}],"checksum":624982312,"timestamp":"2024-05-24T15:54:00.898625Z"}]}
{"channel":"book","type":"update","data":[{"symbol":"ETH/USD","bids":[{"price":3698.80,"qty":0.00000000},{"price":3698.16,"qty":0.75856873}],"asks":[],"checksum":1192526614,"timestamp":"2024-05-24T15:54:00.898672Z"}]}
{"channel":"book","type":"update","data":[{"symbol":"ETH/USD","bids":[],"asks":[{"price":3699.43,"qty":0.00000000},{"price":3699.97,"qty":5.40400000}],"checksum":555818468,"timestamp":"2024-05-24T15:54:00.901592Z"}]}
{"channel":"book","type":"update","data":[{"symbol":"ETH/USD","bids":[],"asks":[{"price":3699.34,"qty":0.04046589}],"checksum":3405827092,"timestamp":"2024-05-24T15:54:00.902702Z"}]}
{"channel":"book","type":"update","data":[{"symbol":"ETH/USD","bids":[{"price":3698.69,"qty":3.21413894}],"asks":[],"checksum":1102447093,"timestamp":"2024-05-24T15:54:00.905032Z"}]}
{"channel":"book","type":"update","data":[{"symbol":"ETH/USD","bids":[{"price":3698.69,"qty":0.02663894}],"asks":[],"checksum":3405827092,"timestamp":"2024-05-24T15:54:00.923343Z"}]}
{"channel":"book","type":"update","data":[{"symbol":"ETH/USD","bids":[{"price":3698.69,"qty":3.21413894}],"asks":[],"checksum":1102447093,"timestamp":"2024-05-24T15:54:00.930072Z"}]}
{"channel":"book","type":"update","data":[{"symbol":"ETH/USD","bids":[],"asks":[{"price":3699.28,"qty":27.03228967}],"checksum":509715686,"timestamp":"2024-05-24T15:54:00.935001Z"}]}
{"channel":"book","type":"update","data":[{"symbol":"ETH/USD","bids":[],"asks":[{"price":3699.34,"qty":0.00000000},{"price":3699.91,"qty":1.53600000}],"checksum":3429675988,"timestamp":"2024-05-24T15:54:00.938530Z"}]}
{"channel":"book","type":"update","data":[{"symbol":"ETH/USD","bids":[{"price":3698.84,"qty":27.03545092}],"asks":[],"checksum":423062814,"timestamp":"2024-05-24T15:54:00.938558Z"}]}
{"channel":"book","type":"update","data":[{"symbol":"ETH/USD","bids":[],"asks":[{"price":3699.11,"qty":27.03359665}],"checksum":3609611231,"timestamp":"2024-05-24T15:54:00.938577Z"}]}
{"channel":"book","type":"update","data":[{"symbol":"ETH/USD","bids":[{"price":3698.69,"qty":0.02663894}],"asks":[],"checksum":3622503980,"timestamp":"2024-05-24T15:54:00.941442Z"}]}
{"channel":"book","type":"update","data":[{"symbol":"ETH/USD","bids":[],"asks":[{"price":3699.27,"qty":0.04046589}],"checksum":3557360525,"timestamp":"2024-05-24T15:54:00.941721Z"}]}
{"channel":"book","type":"update","data":[{"symbol":"ETH/USD","bids":[],"asks":[{"price":3699.27,"qty":0.00000000},{"price":3699.91,"qty":1.53600000}],"checksum":1974786200,"timestamp":"2024-05-24T15:54:00.944481Z"}]}
{"channel":"book","type":"update","data":[{"symbol":"ETH/BTC","bids":[],"asks":[{"price":0.05430,"qty":2.10047227}],"checksum":2419734823,"timestamp":"2024-05-24T15:54:00.950269Z"}]}
{"channel":"book","type":"update","data":[{"symbol":"ETH/BTC","bids":[],"asks":[{"price":0.05430,"qty":18.64998412}],"checksum":1369766380,"timestamp":"2024-05-24T15:54:00.955132Z"}]}
{"channel":"book","type":"update","data":[{"symbol":"BTC/USD","bids":[{"price":68184.9,"qty":1.46660035}],"asks":[],"checksum":2058120973,"timestamp":"2024-05-24T15:54:00.955219Z"}]}
{"channel":"book","type":"update","data":[{"symbol":"ETH/USD","bids":[{"price":3698.84,"qty":0.00000000},{"price":3698.16,"qty":0.75856873}],"asks":[],"checksum":4261672805,"timestamp":"2024-05-24T15:54:00.986038Z"}]}
{"channel":"book","type":"update","data":[{"symbol":"ETH/USD","bids":[],"asks":[{"price":3699.28,"qty":0.00000000},{"price":3699.96,"qty":0.18297066}],"checksum":2110217633,"timestamp":"2024-05-24T15:54:00.986055Z"}]}
{"channel":"book","type":"update","data":[{"symbol":"BTC/USD","bids":[{"price":68184.9,"qty":0.00000000},{"price":68179.5,"qty":0.30954789}],"asks":[],"checksum":3909252500,"timestamp":"2024-05-24T15:54:00.986066Z"}]}
{"channel":"book","type":"update","data":[{"symbol":"ETH/USD","bids":[{"price":3698.79,"qty":27.03582123}],"asks":[],"checksum":778712071,"timestamp":"2024-05-24T15:54:00.992109Z"}]}
{"channel":"book","type":"update","data":[{"symbol":"ETH/USD","bids":[],"asks":[{"price":3699.06,"qty":27.03395111}],"checksum":2984065468,"timestamp":"2024-05-24T15:54:00.992138Z"}]}
{"channel":"book","type":"update","data":[{"symbol":"ETH/USD","bids":[],"asks":[{"price":3699.06,"qty":0.00000000},{"price":3699.96,"qty":0.18297066}],"checksum":778712071,"timestamp":"2024-05-24T15:54:01.003778Z"}]}
{"channel":"book","type":"update","data":[{"symbol":"ETH/USD","bids":[{"price":3698.79,"qty":0.00000000},{"price":3698.16,"qty":0.75856873}],"asks":[],"checksum":2110217633,"timestamp":"2024-05-24T15:54:01.030385Z"}]}
{"channel":"book","type":"update","data":[{"symbol":"ETH/USD","bids":[{"price":3698.86,"qty":0.26592621}],"asks":[],"checksum":3854385947,"timestamp":"2024-05-24T15:54:01.044480Z"}]}
{"channel":"book","type":"update","data":[{"symbol":"ETH/USD","bids":[],"asks":[{"price":3699.02,"qty":27.03422417}],"checksum":3218955964,"timestamp":"2024-05-24T15:54:01.049359Z"}]}
{"channel":"book","type":"update","data":[{"symbol":"ETH/USD","bids":[{"price":3698.75,"qty":27.03609431}],"asks":[],"checksum":1024219231,"timestamp":"2024-05-24T15:54:01.049451Z"}]}
{"channel":"book","type":"update","data":[{"symbol":"ETH/USD","bids":[{"price":3698.86,"qty":0.00000000},{"price":3698.31,"qty":3.18750000}],"asks":[],"checksum":2809231855,"timestamp":"2024-05-24T15:54:01.089270Z"}]}
{"channel":"book","type":"update","data":[{"symbol":"ETH/USD","bids":[],"asks":[{"price":3699.11,"qty":0.00000000},{"price":3699.96,"qty":0.18297066}],"checksum":2096006573,"timestamp":"2024-05-24T15:54:01.124629Z"}]}
{"channel":"book","type":"update","data":[{"symbol":"ETH/USD","bids":[],"asks":[{"price":3699.01,"qty":27.03431880}],"checksum":1958573189,"timestamp":"2024-05-24T15:54:01.129357Z"}]}
{"channel":"book","type":"update","data":[{"symbol":"ETH/USD","bids":[{"price":3698.70,"qty":27.03652634}],"asks":[],"checksum":814606193,"timestamp":"2024-05-24T15:54:01.129491Z"}]}
{"channel":"book","type":"update","data":[{"symbol":"ETH/USD","bids":[],"asks":[{"price":3699.48,"qty":27.03087483}],"checksum":2213680493,"timestamp":"2024-05-24T15:54:01.129535Z"}]}
{"channel":"book","type":"update","data":[{"symbol":"ETH/USD","bids":[{"price":3698.75,"qty":0.00000000},{"price":3698.31,"qty":3.18750000}],"asks":[],"checksum":549129929,"timestamp":"2024-05-24T15:54:01.133574Z"}]}
{"channel":"book","type":"update","data":[{"symbol":"ETH/USD","bids":[],"asks":[{"price":3699.01,"qty":0.00000000},{"price":3699.91,"qty":1.53600000}],"checksum":1045340474,"timestamp":"2024-05-24T15:54:01.133715Z"}]}
{"channel":"book","type":"update","data":[{"symbol":"ETH/USD","bids":[],"asks":[{"price":3699.40,"qty":0.00000000},{"price":3699.96,"qty":0.18297066}],"checksum":333873864,"timestamp":"2024-05-24T15:54:01.143602Z"}]}
{"channel":"book","type":"update","data":[{"symbol":"ETH/USD","bids":[],"asks":[{"price":3699.09,"qty":27.03373636}],"checksum":3247338200,"timestamp":"2024-05-24T15:54:01.145903Z"}]}
{"channel":"book","type":"update","data":[{"symbol":"ETH/USD","bids":[],"asks":[{"price":3699.37,"qty":0.40090210}],"checksum":279274397,"timestamp":"2024-05-24T15:54:01.183825Z"}]}
{"channel":"book","type":"update","data":[{"symbol":"ETH/USD","bids":[{"price":3698.70,"qty":0.00000000},{"price":3698.16,"qty":0.75856873}],"asks":[],"checksum":1294234033,"timestamp":"2024-05-24T15:54:01.186472Z"}]}
{"channel":"book","type":"update","data":[{"symbol":"ETH/USD","bids":[{"price":3698.77,"qty":27.03599110}],"asks":[],"checksum":3847238262,"timestamp":"2024-05-24T15:54:01.191032Z"}]}
{"channel":"book","type":"update","data":[{"symbol":"ETH/USD","bids":[],"asks":[{"price":3699.02,"qty":0.00000000},{"price":3699.91,"qty":1.53600000}],"checksum":1058875984,"timestamp":"2024-05-24T15:54:01.201802Z"}]}
{"channel":"book","type":"update","data":[{"symbol":"ETH/USD","bids":[{"price":3698.77,"qty":0.00000000},{"price":3698.16,"qty":0.75856873}],"asks":[],"checksum":4013791054,"timestamp":"2024-05-24T15:54:01.201856Z"}]}
{"channel":"book","type":"update","data":[{"symbol":"ETH/USD","bids":[],"asks":[{"price":3699.04,"qty":27.03407190}],"checksum":326814825,"timestamp":"2024-05-24T15:54:01.208732Z"}]}
{"channel":"book","type":"update","data":[{"symbol":"ETH/USD","bids":[],"asks":[{"price":3699.04,"qty":0.00000000},{"price":3699.91,"qty":1.53600000}],"checksum":4013791054,"timestamp":"2024-05-24T15:54:01.232644Z"}]}
{"channel":"book","type":"update","data":[{"symbol":"ETH/USD","bids":[],"asks":[{"price":3699.25,"qty":27.03257252}],"checksum":2763101082,"timestamp":"2024-05-24T15:54:01.236257Z"}]}
{"channel":"book","type":"update","data":[{"symbol":"ETH/USD","bids":[{"price":3698.76,"qty":27.03604835}],"asks":[],"checksum":2066655397,"timestamp":"2024-05-24T15:54:01.250175Z"}]}
{"channel":"book","type":"update","data":[{"symbol":"ETH/USD","bids":[{"price":3698.76,"qty":0.00000000},{"price":3698.16,"qty":0.75856873}],"asks":[],"checksum":2763101082,"timestamp":"2024-05-24T15:54:01.255356Z"}]}
{"channel":"book","type":"update","data":[{"symbol":"ETH/USD","bids":[],"asks":[{"price":3699.03,"qty":27.03416383}],"checksum":3511893469,"timestamp":"2024-05-24T15:54:01.262535Z"}]}
{"channel":"book","type":"update","data":[{"symbol":"ETH/USD","bids":[],"asks":[{"price":3699.03,"qty":0.00000000},{"price":3699.64,"qty":3.18750000}],"checksum":2763101082,"timestamp":"2024-05-24T15:54:01.267758Z"}]}
{"channel":"book","type":"update","data":[{"symbol":"ETH/BTC","bids":[{"price":0.05424,"qty":3.34651587}],"asks":[],"checksum":1142036596,"timestamp":"2024-05-24T15:54:01.273328Z"}]}
{"channel":"book","type":"update","data":[{"symbol":"ETH/USD","bids":[],"asks":[{"price":3699.09,"qty":0.00000000},{"price":3699.91,"qty":1.53600000}],"checksum":3374329245,"timestamp":"2024-05-24T15:54:01.277260Z"}]}
{"channel":"book","type":"update","data":[{"symbol":"ETH/USD","bids":[{"price":3698.57,"qty":0.00000000},{"price":3698.14,"qty":0.72912968}],"asks":[],"checksum":3578129741,"timestamp":"2024-05-24T15:54:01.277273Z"}]}
{"channel":"book","type":"update","data":[{"symbol":"ETH/BTC","bids":[{"price":0.05423,"qty":18.73861699}],"asks":[],"checksum":2906714109,"timestamp":"2024-05-24T15:54:01.277579Z"}]}
{"channel":"book","type":"update","data":[{"symbol":"ETH/USD","bids":[],"asks":[{"price":3699.24,"qty":0.04046589}],"checksum":3190682659,"timestamp":"2024-05-24T15:54:01.280866Z"}]}
{"channel":"book","type":"update","data":[{"symbol":"ETH/BTC","bids":[{"price":0.05423,"qty":16.03493318}],"asks":[],"checksum":1142036596,"timestamp":"2024-05-24T15:54:01.281072Z"}]}
{"channel":"book","type":"update","data":[{"symbol":"BTC/USD","bids":[{"price":68184.7,"qty":1.46660304}],"asks":[],"checksum":4184111779,"timestamp":"2024-05-24T15:54:01.281520Z"}]}
{"channel":"book","type":"update","data":[{"symbol":"ETH/USD","bids":[{"price":3698.69,"qty":0.56737092}],"asks":[],"checksum":2626987174,"timestamp":"2024-05-24T15:54:01.281539Z"}]}
{"channel":"book","type":"update","data":[{"symbol":"BTC/USD","bids":[{"price":68184.7,"qty":0.00000000},{"price":68179.5,"qty":0.30954789}],"asks":[],"checksum":3909252500,"timestamp":"2024-05-24T15:54:01.285094Z"}]}
{"channel":"book","type":"update","data":[{"symbol":"ETH/USD","bids":[{"price":3698.69,"qty":0.02663894}],"asks":[],"checksum":3190682659,"timestamp":"2024-05-24T15:54:01.285449Z"}]}
{"channel":"book","type":"update","data":[{"symbol":"ETH/USD","bids":[{"price":3698.58,"qty":30.03733469}],"asks":[],"checksum":2360023940,"timestamp":"2024-05-24T15:54:01.286186Z"}]}
{"channel":"book","type":"update","data":[{"symbol":"ETH/USD","bids":[{"price":3698.35,"qty":0.00000000},{"price":3698.06,"qty":2.11000000}],"asks":[],"checksum":85052092,"timestamp":"2024-05-24T15:54:01.310656Z"}]}
{"channel":"book","type":"update","data":[{"symbol":"ETH/USD","bids":[],"asks":[{"price":3698.95,"qty":27.03472790}],"checksum":1331339983,"timestamp":"2024-05-24T15:54:01.314421Z"}]}
{"channel":"book","type":"update","data":[{"symbol":"ETH/USD","bids":[{"price":3698.20,"qty":27.04013797}],"asks":[],"checksum":3375641916,"timestamp":"2024-05-24T15:54:01.314443Z"}]}
{"channel":"book","type":"update","data":[{"symbol":"ETH/USD","bids":[{"price":3698.66,"qty":27.03674784}],"asks":[],"checksum":111283069,"timestamp":"2024-05-24T15:54:01.314495Z"}]}
{"channel":"book","type":"update","data":[{"symbol":"ETH/USD","bids":[],"asks":[{"price":3699.24,"qty":0.00000000},{"price":3699.64,"qty":3.18750000}],"checksum":3519778371,"timestamp":"2024-05-24T15:54:01.318196Z"}]}
{"channel":"book","type":"update","data":[{"symbol":"ETH/USD","bids":[],"asks":[{"price":3699.27,"qty":3.18750000}],"checksum":2992652741,"timestamp":"2024-05-24T15:54:01.325129Z"}]}
{"channel":"book","type":"update","data":[{"symbol":"ETH/USD","bids":[],"asks":[{"price":3698.95,"qty":0.00000000},{"price":3699.64,"qty":3.18750000}],"checksum":2592648642,"timestamp":"2024-05-24T15:54:01.331482Z"}]}
{"channel":"book","type":"update","data":[{"symbol":"ETH/USD","bids":[],"asks":[{"price":3699.25,"qty":0.00000000},{"price":3699.91,"qty":1.53600000}],"checksum":965669421,"timestamp":"2024-05-24T15:54:01.331897Z"}]}
{"channel":"book","type":"update","data":[{"symbol":"ETH/USD","bids":[],"asks":[{"price":3699.24,"qty":0.04046589}],"checksum":2012219536,"timestamp":"2024-05-24T15:54:01.335382Z"}]}
{"channel":"book","type":"update","data":[{"symbol":"ETH/USD","bids":[],"asks":[{"price":3699.27,"qty":0.00000000},{"price":3699.91,"qty":1.53600000}],"checksum":1801955304,"timestamp":"2024-05-24T15:54:01.354539Z"}]}
{"channel":"book","type":"update","data":[{"symbol":"BTC/USD","bids":[{"price":68186.3,"qty":0.00000000},{"price":68179.4,"qty":0.33750000}],"asks":[],"checksum":4166153314,"timestamp":"2024-05-24T15:54:01.362473Z"}]}
{"channel":"book","type":"update","data":[{"symbol":"BTC/USD","bids":[],"asks":[{"price":68200.2,"qty":3.47739060}],"checksum":1168724828,"timestamp":"2024-05-24T15:54:01.367202Z"}]}
{"channel":"book","type":"update","data":[{"symbol":"BTC/USD","bids":[],"asks":[{"price":68200.2,"qty":3.81489060}],"checksum":1629519333,"timestamp":"2024-05-24T15:54:01.367354Z"}]}
{"channel":"book","type":"update","data":[{"symbol":"BTC/USD","bids":[{"price":68185.5,"qty":0.00000000},{"price":68178.8,"qty":0.11607238}],"asks":[],"checksum":2159294624,"timestamp":"2024-05-24T15:54:01.368259Z"}]}
{"channel":"book","type":"update","data":[{"symbol":"ETH/USD","bids":[{"price":3698.66,"qty":0.00000000},{"price":3698.14,"qty":0.72912968}],"asks":[],"checksum":906844139,"timestamp":"2024-05-24T15:54:01.369669Z"}]}
{"channel":"book","type":"update","data":[{"symbol":"BTC/USD","bids":[{"price":68185.2,"qty":0.00000000},{"price":68177.6,"qty":0.00248061}],"asks":[],"checksum":3933782152,"timestamp":"2024-05-24T15:54:01.371279Z"}]}
{"channel":"book","type":"update","data":[{"symbol":"BTC/USD","bids":[{"price":68183.0,"qty":0.01353482}],"asks":[],"checksum":1595831714,"timestamp":"2024-05-24T15:54:01.371560Z"}]}
{"channel":"book","type":"update","data":[{"symbol":"ETH/USD","bids":[{"price":3698.67,"qty":28.04908673}],"asks":[],"checksum":2045570312,"timestamp":"2024-05-24T15:54:01.373269Z"}]}
{"channel":"book","type":"update","data":[{"symbol":"ETH/USD","bids":[],"asks":[{"price":3698.96,"qty":27.03467923}],"checksum":1761643945,"timestamp":"2024-05-24T15:54:01.373294Z"}]}
{"channel":"book","type":"update","data":[{"symbol":"ETH/USD","bids":[],"asks":[{"price":3699.27,"qty":3.18750000}],"checksum":3299070644,"timestamp":"2024-05-24T15:54:01.376949Z"}]}
{"channel":"book","type":"update","data":[{"symbol":"ETH/USD","bids":[],"asks":[{"price":3699.24,"qty":0.00000000},{"price":3699.64,"qty":3.18750000}],"checksum":493647126,"timestamp":"2024-05-24T15:54:01.378569Z"}]}
{"channel":"book","type":"update","data":[{"symbol":"ETH/USD","bids":[{"price":3698.67,"qty":1.01235805}],"asks":[],"checksum":3711797746,"timestamp":"2024-05-24T15:54:01.396094Z"}]}
{"channel":"book","type":"update","data":[{"symbol":"BTC/USD","bids":[{"price":68182.6,"qty":1.46664807}],"asks":[],"checksum":350441196,"timestamp":"2024-05-24T15:54:01.401178Z"}]}
{"channel":"book","type":"update","data":[{"symbol":"ETH/USD","bids":[],"asks":[{"price":3698.96,"qty":0.00000000},{"price":3699.91,"qty":1.53600000}],"checksum":1072179519,"timestamp":"2024-05-24T15:54:01.405232Z"}]}
{"channel":"book","type":"update","data":[{"symbol":"ETH/USD","bids":[],"asks":[{"price":3699.26,"qty":0.04046589}],"checksum":2161336783,"timestamp":"2024-05-24T15:54:01.409650Z"}]}
{"channel":"book","type":"update","data":[{"symbol":"BTC/USD","bids":[],"asks":[{"price":68200.2,"qty":3.47739060}],"checksum":4247941723,"timestamp":"2024-05-24T15:54:01.417407Z"}]}
{"channel":"book","type":"update","data":[{"symbol":"ETH/USD","bids":[],"asks":[{"price":3698.90,"qty":27.58507783}],"checksum":3031431689,"timestamp":"2024-05-24T15:54:01.443984Z"}]}
{"channel":"book","type":"update","data":[{"symbol":"ETH/USD","bids":[],"asks":[{"price":3699.48,"qty":0.00000000},{"price":3699.91,"qty":1.53600000}],"checksum":4080326657,"timestamp":"2024-05-24T15:54:01.444023Z"}]}
{"channel":"book","type":"update","data":[{"symbol":"ETH/USD","bids":[{"price":3698.62,"qty":27.03710481}],"asks":[],"checksum":2069944608,"timestamp":"2024-05-24T15:54:01.444065Z"}]}
{"channel":"book","type":"update","data":[{"symbol":"ETH/USD","bids":[{"price":3698.68,"qty":0.00000000},{"price":3698.14,"qty":0.72912968}],"asks":[],"checksum":1744122102,"timestamp":"2024-05-24T15:54:01.446413Z"}]}
{"channel":"book","type":"update","data":[{"symbol":"ETH/USD","bids":[{"price":3698.58,"qty":27.03733469}],"asks":[],"checksum":2655639703,"timestamp":"2024-05-24T15:54:01.446471Z"}]}
{"channel":"book","type":"update","data":[{"symbol":"ETH/USD","bids":[],"asks":[{"price":3699.26,"qty":0.00000000},{"price":3699.96,"qty":0.18297066}],"checksum":1019536296,"timestamp":"2024-05-24T15:54:01.447247Z"}]}
{"channel":"book","type":"update","data":[{"symbol":"ETH/USD","bids":[],"asks":[{"price":3698.90,"qty":0.55000000}],"checksum":1324873910,"timestamp":"2024-05-24T15:54:01.448949Z"}]}
{"channel":"book","type":"update","data":[{"symbol":"ETH/USD","bids":[{"price":3698.62,"qty":0.00000000},{"price":3698.06,"qty":2.11000000}],"asks":[],"checksum":502889636,"timestamp":"2024-05-24T15:54:01.448971Z"}]}
{"channel":"book","type":"update","data":[{"symbol":"ETH/USD","bids":[],"asks":[{"price":3699.26,"qty":0.04046589}],"checksum":3515715624,"timestamp":"2024-05-24T15:54:01.453219Z"}]}
{"channel":"book","type":"update","data":[{"symbol":"BTC/USD","bids":[],"asks":[{"price":68200.2,"qty":3.13989060}],"checksum":436036022,"timestamp":"2024-05-24T15:54:01.461740Z"}]}
{"channel":"book","type":"update","data":[{"symbol":"ETH/USD","bids":[{"price":3698.68,"qty":3.00000000}],"asks":[],"checksum":415894025,"timestamp":"2024-05-24T15:54:01.467537Z"}]}
{"channel":"book","type":"update","data":[{"symbol":"BTC/USD","bids":[{"price":68186.3,"qty":0.33750000}],"asks":[],"checksum":2562387503,"timestamp":"2024-05-24T15:54:01.490515Z"}]}
{"channel":"book","type":"update","data":[{"symbol":"ETH/USD","bids":[],"asks":[{"price":3698.91,"qty":27.03504809}],"checksum":568201200,"timestamp":"2024-05-24T15:54:01.518021Z"}]}
{"channel":"book","type":"update","data":[{"symbol":"BTC/USD","bids":[{"price":68182.6,"qty":0.00000000},{"price":68179.4,"qty":0.33750000}],"asks":[],"checksum":1393837214,"timestamp":"2024-05-24T15:54:01.518038Z"}]}
{"channel":"book","type":"update","data":[{"symbol":"ETH/USD","bids":[{"price":3698.62,"qty":27.03707506}],"asks":[],"checksum":2307782427,"timestamp":"2024-05-24T15:54:01.518201Z"}]}
{"channel":"book","type":"update","data":[{"symbol":"ETH/USD","bids":[],"asks":[{"price":3699.26,"qty":0.00000000},{"price":3699.91,"qty":1.53600000}],"checksum":3452460468,"timestamp":"2024-05-24T15:54:01.521629Z"}]}
{"channel":"book","type":"update","data":[{"symbol":"BTC/USD","bids":[{"price":68184.4,"qty":1.46661002}],"asks":[],"checksum":3089858206,"timestamp":"2024-05-24T15:54:01.522997Z"}]}
{"channel":"book","type":"update","data":[{"symbol":"ETH/USD","bids":[{"price":3698.62,"qty":0.00000000},{"price":3698.14,"qty":0.72912968}],"asks":[],"checksum":2725774171,"timestamp":"2024-05-24T15:54:01.527524Z"}]}
{"channel":"book","type":"update","data":[{"symbol":"ETH/USD","bids":[],"asks":[{"price":3699.27,"qty":0.00000000},{"price":3699.96,"qty":0.18297066}],"checksum":2718915306,"timestamp":"2024-05-24T15:54:01.530347Z"}]}
{"channel":"book","type":"update","data":[{"symbol":"BTC/USD","bids":[{"price":68179.5,"qty":0.00000000},{"price":68179.4,"qty":0.33750000}],"asks":[],"checksum":2677711438,"timestamp":"2024-05-24T15:54:01.535789Z"}]}
{"channel":"book","type":"update","data":[{"symbol":"ETH/USD","bids":[],"asks":[{"price":3698.85,"qty":3.18750000}],"checksum":2157923669,"timestamp":"2024-05-24T15:54:01.539533Z"}]}
{"channel":"book","type":"update","data":[{"symbol":"ETH/USD","bids":[],"asks":[{"price":3698.91,"qty":0.00000000},{"price":3699.96,"qty":0.18297066}],"checksum":3583209768,"timestamp":"2024-05-24T15:54:01.540849Z"}]}
{"channel":"book","type":"update","data":[{"symbol":"ETH/USD","bids":[],"asks":[{"price":3699.27,"qty":3.18750000}],"checksum":3613736172,"timestamp":"2024-05-24T15:54:01.542648Z"}]}
{"channel":"book","type":"update","data":[{"symbol":"ETH/USD","bids":[],"asks":[{"price":3699.16,"qty":27.03319059}],"checksum":2630559936,"timestamp":"2024-05-24T15:54:01.546438Z"}]}
{"channel":"book","type":"update","data":[{"symbol":"BTC/USD","bids":[{"price":68184.4,"qty":0.00000000},{"price":68178.8,"qty":0.11607238}],"asks":[],"checksum":3767509294,"timestamp":"2024-05-24T15:54:01.566755Z"}]}
{"channel":"book","type":"update","data":[{"symbol":"ETH/USD","bids":[{"price":3698.58,"qty":0.00000000},{"price":3698.06,"qty":2.11000000}],"asks":[],"checksum":1112903668,"timestamp":"2024-05-24T15:54:01.583842Z"}]}
{"channel":"book","type":"update","data":[{"symbol":"ETH/USD","bids":[],"asks":[{"price":3698.97,"qty":27.03458035}],"checksum":1359131682,"timestamp":"2024-05-24T15:54:01.587571Z"}]}
{"channel":"book","type":"update","data":[{"symbol":"ETH/USD","bids":[{"price":3698.47,"qty":27.03815565}],"asks":[],"checksum":563631747,"timestamp":"2024-05-24T15:54:01.587706Z"}]}
{"channel":"book","type":"update","data":[{"symbol":"ETH/USD","bids":[{"price":3698.70,"qty":27.03652634}],"asks":[],"checksum":151550413,"timestamp":"2024-05-24T15:54:01.587736Z"}]}
{"channel":"book","type":"update","data":[{"symbol":"ETH/USD","bids":[],"asks":[{"price":3699.04,"qty":27.03407893}],"checksum":367268573,"timestamp":"2024-05-24T15:54:01.587750Z"}]}
{"channel":"book","type":"update","data":[{"symbol":"ETH/USD","bids":[],"asks":[{"price":3698.85,"qty":0.00000000},{"price":3699.61,"qty":4.22000000}],"checksum":3576646090,"timestamp":"2024-05-24T15:54:01.590774Z"}]}
{"channel":"book","type":"update","data":[{"symbol":"ETH/USD","bids":[],"asks":[{"price":3699.27,"qty":0.00000000},{"price":3699.64,"qty":3.18750000}],"checksum":1195069767,"timestamp":"2024-05-24T15:54:01.591094Z"}]}
{"channel":"book","type":"update","data":[{"symbol":"ETH/USD","bids":[],"asks":[{"price":3699.15,"qty":4.05521582}],"checksum":2668263859,"timestamp":"2024-05-24T15:54:01.591518Z"}]}
{"channel":"book","type":"update","data":[{"symbol":"ETH/USD","bids":[{"price":3698.70,"qty":0.00000000},{"price":3698.14,"qty":0.72912968}],"asks":[],"checksum":1387740492,"timestamp":"2024-05-24T15:54:01.592466Z"}]}
{"channel":"book","type":"update","data":[{"symbol":"ETH/USD","bids":[],"asks":[{"price":3698.90,"qty":3.73750000}],"checksum":3609211698,"timestamp":"2024-05-24T15:54:01.594526Z"}]}
{"channel":"book","type":"update","data":[{"symbol":"ETH/USD","bids":[],"asks":[{"price":3699.44,"qty":0.00000000},{"price":3699.64,"qty":3.18750000}],"checksum":2829830204,"timestamp":"2024-05-24T15:54:01.594628Z"}]}
{"channel":"book","type":"update","data":[{"symbol":"ETH/USD","bids":[],"asks":[{"price":3699.27,"qty":3.18750000}],"checksum":751291062,"timestamp":"2024-05-24T15:54:01.597702Z"}]}
{"channel":"book","type":"update","data":[{"symbol":"BTC/USD","bids":[{"price":68184.4,"qty":1.46661002}],"asks":[],"checksum":2677711438,"timestamp":"2024-05-24T15:54:01.600192Z"}]}
{"channel":"book","type":"update","data":[{"symbol":"ETH/USD","bids":[],"asks":[{"price":3698.97,"qty":0.00000000},{"price":3699.64,"qty":3.18750000}],"checksum":1993816106,"timestamp":"2024-05-24T15:54:01.613619Z"}]}
{"channel":"book","type":"update","data":[{"symbol":"ETH/USD","bids":[],"asks":[{"price":3699.04,"qty":0.00000000},{"price":3699.91,"qty":1.53600000}],"checksum":3815631848,"timestamp":"2024-05-24T15:54:01.629033Z"}]}
{"channel":"book","type":"update","data":[{"symbol":"ETH/BTC","bids":[{"price":0.05425,"qty":4.93728080}],"asks":[],"checksum":2802048089,"timestamp":"2024-05-24T15:54:01.629723Z"}]}
{"channel":"book","type":"update","data":[{"symbol":"ETH/USD","bids":[],"asks":[{"price":3699.33,"qty":27.03192315}],"checksum":2829483811,"timestamp":"2024-05-24T15:54:01.632417Z"}]}
{"channel":"book","type":"update","data":[{"symbol":"BTC/USD","bids":[{"price":68184.4,"qty":0.00000000},{"price":68178.8,"qty":0.11607238}],"asks":[],"checksum":3767509294,"timestamp":"2024-05-24T15:54:01.640468Z"}]}
{"channel":"book","type":"update","data":[{"symbol":"ETH/USD","bids":[{"price":3698.66,"qty":27.03680239}],"asks":[],"checksum":3619350690,"timestamp":"2024-05-24T15:54:01.641081Z"}]}
{"channel":"book","type":"update","data":[{"symbol":"ETH/USD","bids":[],"asks":[{"price":3698.92,"qty":27.03493644}],"checksum":2912444225,"timestamp":"2024-05-24T15:54:01.641107Z"}]}
{"channel":"book","type":"update","data":[{"symbol":"ETH/USD","bids":[{"price":3698.60,"qty":27.03724300}],"asks":[],"checksum":1273383515,"timestamp":"2024-05-24T15:54:01.641456Z"}]}
{"channel":"book","type":"update","data":[{"symbol":"ETH/USD","bids":[],"asks":[{"price":3698.90,"qty":0.55000000}],"checksum":1766513548,"timestamp":"2024-05-24T15:54:01.644094Z"}]}
{"channel":"book","type":"update","data":[{"symbol":"ETH/USD","bids":[{"price":3698.66,"qty":0.00000000},{"price":3698.16,"qty":0.75856873}],"asks":[],"checksum":2745879229,"timestamp":"2024-05-24T15:54:01.645062Z"}]}
{"channel":"book","type":"update","data":[{"symbol":"BTC/USD","bids":[{"price":68184.4,"qty":1.46661002}],"asks":[],"checksum":2677711438,"timestamp":"2024-05-24T15:54:01.667568Z"}]}
{"channel":"book","type":"update","data":[{"symbol":"ETH/USD","bids":[],"asks":[{"price":3699.37,"qty":0.00000000},{"price":3699.64,"qty":3.18750000}],"checksum":948152045,"timestamp":"2024-05-24T15:54:01.697482Z"}]}
{"channel":"book","type":"update","data":[{"symbol":"ETH/USD","bids":[],"asks":[{"price":3698.89,"qty":27.03513756}],"checksum":1734142607,"timestamp":"2024-05-24T15:54:01.701294Z"}]}
{"channel":"book","type":"update","data":[{"symbol":"ETH/USD","bids":[{"price":3698.61,"qty":27.03716202}],"asks":[],"checksum":2467508223,"timestamp":"2024-05-24T15:54:01.701318Z"}]}
{"channel":"book","type":"update","data":[{"symbol":"ETH/USD","bids":[],"asks":[{"price":3699.27,"qty":0.00000000},{"price":3699.64,"qty":3.18750000}],"checksum":1292504974,"timestamp":"2024-05-24T15:54:01.704685Z"}]}
{"channel":"book","type":"update","data":[{"symbol":"ETH/USD","bids":[{"price":3698.61,"qty":0.00000000},{"price":3698.16,"qty":0.75856873}],"asks":[],"checksum":3197728172,"timestamp":"2024-05-24T15:54:01.705781Z"}]}
{"channel":"book","type":"update","data":[{"symbol":"BTC/USD","bids":[],"asks":[{"price":68209.8,"qty":0.00000000},{"price":68210.7,"qty":0.08412000}],"checksum":1433163145,"timestamp":"2024-05-24T15:54:01.768727Z"}]}
{"channel":"book","type":"update","data":[{"symbol":"ETH/BTC","bids":[{"price":0.05425,"qty":5.38728080}],"asks":[],"checksum":1142036596,"timestamp":"2024-05-24T15:54:01.806430Z"}]}
{"channel":"book","type":"update","data":[{"symbol":"ETH/BTC","bids":[{"price":0.05423,"qty":18.73864017}],"asks":[],"checksum":1693839126,"timestamp":"2024-05-24T15:54:01.808816Z"}]}
{"channel":"book","type":"update","data":[{"symbol":"ETH/USD","bids":[{"price":3698.60,"qty":0.00000000},{"price":3698.14,"qty":0.72912968}],"asks":[],"checksum":1668841449,"timestamp":"2024-05-24T15:54:01.811634Z"}]}
{"channel":"book","type":"update","data":[{"symbol":"ETH/USD","bids":[],"asks":[{"price":3698.89,"qty":0.00000000},{"price":3699.91,"qty":1.53600000}],"checksum":3719118070,"timestamp":"2024-05-24T15:54:01.811642Z"}]}
{"channel":"book","type":"update","data":[{"symbol":"ETH/USD","bids":[],"asks":[{"price":3698.92,"qty":0.00000000},{"price":3699.96,"qty":0.18297066}],"checksum":1733975425,"timestamp":"2024-05-24T15:54:01.811686Z"}]}
{"channel":"book","type":"update","data":[{"symbol":"ETH/USD","bids":[],"asks":[{"price":3699.33,"qty":0.00000000},{"price":3699.97,"qty":5.40400000}],"checksum":2298725791,"timestamp":"2024-05-24T15:54:01.814856Z"}]}
{"channel":"book","type":"update","data":[{"symbol":"ETH/BTC","bids":[{"price":0.05423,"qty":16.03493318}],"asks":[],"checksum":1142036596,"timestamp":"2024-05-24T15:54:01.815032Z"}]}
{"channel":"book","type":"update","data":[{"symbol":"ETH/USD","bids":[{"price":3698.47,"qty":0.00000000},{"price":3698.06,"qty":2.11000000}],"asks":[],"checksum":2907635087,"timestamp":"2024-05-24T15:54:01.815042Z"}]}
{"channel":"book","type":"update","data":[{"symbol":"BTC/USD","bids":[{"price":68184.4,"qty":0.00000000},{"price":68178.8,"qty":0.11607238}],"asks":[],"checksum":2897931487,"timestamp":"2024-05-24T15:54:01.816088Z"}]}
{"channel":"book","type":"update","data":[{"symbol":"ETH/USD","bids":[{"price":3698.69,"qty":0.29256515}],"asks":[],"checksum":4012522762,"timestamp":"2024-05-24T15:54:01.817605Z"}]}
{"channel":"book","type":"update","data":[{"symbol":"ETH/USD","bids":[],"asks":[{"price":3699.91,"qty":0.00000000},{"price":3699.98,"qty":16.22125796}],"checksum":4172949238,"timestamp":"2024-05-24T15:54:01.818634Z"}]}
{"channel":"book","type":"update","data":[{"symbol":"ETH/USD","bids":[{"price":3698.68,"qty":0.00000000},{"price":3697.82,"qty":1.53600000}],"asks":[],"checksum":1270578554,"timestamp":"2024-05-24T15:54:01.818738Z"}]}
{"channel":"book","type":"update","data":[{"symbol":"ETH/USD","bids":[{"price":3698.79,"qty":27.03586692}],"asks":[],"checksum":3503329780,"timestamp":"2024-05-24T15:54:01.819235Z"}]}
{"channel":"book","type":"update","data":[{"symbol":"ETH/USD","bids":[],"asks":[{"price":3699.06,"qty":27.03389641}],"checksum":698223804,"timestamp":"2024-05-24T15:54:01.819282Z"}]}
{"channel":"book","type":"update","data":[{"symbol":"ETH/USD","bids":[],"asks":[{"price":3699.35,"qty":5.59112812}],"checksum":2953677046,"timestamp":"2024-05-24T15:54:01.820687Z"}]}
{"channel":"book","type":"update","data":[{"symbol":"ETH/USD","bids":[],"asks":[{"price":3699.14,"qty":0.04046589}],"checksum":2887510394,"timestamp":"2024-05-24T15:54:01.821669Z"}]}
{"channel":"book","type":"update","data":[{"symbol":"ETH/USD","bids":[{"price":3698.69,"qty":3.48006515}],"asks":[],"checksum":867022269,"timestamp":"2024-05-24T15:54:01.822114Z"}]}
{"channel":"book","type":"update","data":[{"symbol":"ETH/BTC","bids":[{"price":0.05424,"qty":6.05002294}],"asks":[],"checksum":2590744168,"timestamp":"2024-05-24T15:54:01.826012Z"}]}
{"channel":"book","type":"update","data":[{"symbol":"BTC/USD","bids":[{"price":68184.7,"qty":1.46660357}],"asks":[],"checksum":361284999,"timestamp":"2024-05-24T15:54:01.826704Z"}]}
{"channel":"book","type":"update","data":[{"symbol":"ETH/USD","bids":[],"asks":[{"price":3699.06,"qty":0.00000000},{"price":3699.97,"qty":5.40400000}],"checksum":1360221166,"timestamp":"2024-05-24T15:54:01.827491Z"}]}
{"channel":"book","type":"update","data":[{"symbol":"ETH/USD","bids":[{"price":3698.20,"qty":0.00000000},{"price":3697.82,"qty":1.53600000}],"asks":[],"checksum":3954384548,"timestamp":"2024-05-24T15:54:01.827600Z"}]}
{"channel":"book","type":"update","data":[{"symbol":"ETH/USD","bids":[{"price":3698.79,"qty":0.00000000},{"price":3697.76,"qty":0.46522573}],"asks":[],"checksum":3691294158,"timestamp":"2024-05-24T15:54:01.827632Z"}]}
{"channel":"book","type":"update","data":[{"symbol":"ETH/USD","bids":[{"price":3698.69,"qty":0.29256515}],"asks":[],"checksum":2105323758,"timestamp":"2024-05-24T15:54:01.831477Z"}]}
{"channel":"book","type":"update","data":[{"symbol":"ETH/USD","bids":[],"asks":[{"price":3699.14,"qty":0.00000000},{"price":3699.98,"qty":16.22125796}],"checksum":2025836969,"timestamp":"2024-05-24T15:54:01.832063Z"}]}
{"channel":"book","type":"update","data":[{"symbol":"ETH/USD","bids":[{"price":3698.35,"qty":27.03902207}],"asks":[],"checksum":4117203338,"timestamp":"2024-05-24T15:54:01.832614Z"}]}
{"channel":"book","type":"update","data":[{"symbol":"ETH/USD","bids":[{"price":3698.69,"qty":3.48006515}],"asks":[],"checksum":2369175530,"timestamp":"2024-05-24T15:54:01.835467Z"}]}
{"channel":"book","type":"update","data":[{"symbol":"ETH/USD","bids":[],"asks":[{"price":3699.28,"qty":27.03231319}],"checksum":1906882225,"timestamp":"2024-05-24T15:54:01.847303Z"}]}
{"channel":"book","type":"update","data":[{"symbol":"ETH/USD","bids":[],"asks":[{"price":3699.14,"qty":0.04046589}],"checksum":2034630692,"timestamp":"2024-05-24T15:54:01.851409Z"}]}
{"channel":"book","type":"update","data":[{"symbol":"ETH/USD","bids":[{"price":3698.69,"qty":0.29256515}],"asks":[],"checksum":1366103708,"timestamp":"2024-05-24T15:54:01.861695Z"}]}
{"channel":"book","type":"update","data":[{"symbol":"ETH/USD","bids":[{"price":3698.69,"qty":3.48006515}],"asks":[],"checksum":2034630692,"timestamp":"2024-05-24T15:54:01.874554Z"}]}
{"channel":"book","type":"update","data":[{"symbol":"ETH/USD","bids":[{"price":3698.85,"qty":27.03536561}],"asks":[],"checksum":1775795287,"timestamp":"2024-05-24T15:54:01.900700Z"}]}
{"channel":"book","type":"update","data":[{"symbol":"ETH/USD","bids":[],"asks":[{"price":3699.12,"qty":27.03347329}],"checksum":1803484012,"timestamp":"2024-05-24T15:54:01.900716Z"}]}
{"channel":"book","type":"update","data":[{"symbol":"ETH/USD","bids":[],"asks":[{"price":3699.14,"qty":0.00000000},{"price":3699.96,"qty":0.18297066}],"checksum":1005629475,"timestamp":"2024-05-24T15:54:01.903985Z"}]}
{"channel":"book","type":"update","data":[{"symbol":"ETH/USD","bids":[{"price":3698.69,"qty":0.29256515}],"asks":[],"checksum":4020083002,"timestamp":"2024-05-24T15:54:01.904067Z"}]}
{"channel":"book","type":"update","data":[{"symbol":"ETH/USD","bids":[{"price":3698.69,"qty":0.26592621},{"price":3698.86,"qty":0.02663772}],"asks":[],"checksum":4240135308,"timestamp":"2024-05-24T15:54:01.911310Z"}]}
{"channel":"book","type":"update","data":[{"symbol":"ETH/USD","bids":[],"asks":[{"price":3699.12,"qty":0.00000000},{"price":3699.97,"qty":5.40400000}],"checksum":967931466,"timestamp":"2024-05-24T15:54:01.912340Z"}]}
{"channel":"book","type":"update","data":[{"symbol":"ETH/USD","bids":[],"asks":[{"price":3699.64,"qty":0.00000000},{"price":3699.98,"qty":16.22125796}],"checksum":1802973726,"timestamp":"2024-05-24T15:54:01.914178Z"}]}
{"channel":"book","type":"update","data":[{"symbol":"ETH/USD","bids":[],"asks":[{"price":3699.64,"qty":3.18750000}],"checksum":967931466,"timestamp":"2024-05-24T15:54:01.919981Z"}]}
{"channel":"book","type":"update","data":[{"symbol":"ETH/USD","bids":[{"price":3698.86,"qty":3.02663772}],"asks":[],"checksum":153553919,"timestamp":"2024-05-24T15:54:01.925856Z"}]}
{"channel":"book","type":"update","data":[{"symbol":"ETH/USD","bids":[],"asks":[{"price":3699.64,"qty":0.00000000},{"price":3699.98,"qty":16.22125796}],"checksum":2789295328,"timestamp":"2024-05-24T15:54:02.009514Z"}]}
{"channel":"book","type":"update","data":[{"symbol":"ETH/USD","bids":[],"asks":[{"price":3699.16,"qty":0.00000000},{"price":3700.01,"qty":3.18750000}],"checksum":1914287156,"timestamp":"2024-05-24T15:54:02.009676Z"}]}
{"channel":"book","type":"update","data":[{"symbol":"ETH/USD","bids":[{"price":3698.86,"qty":6.21413772}],"asks":[],"checksum":4094962368,"timestamp":"2024-05-24T15:54:02.009960Z"}]}
{"channel":"book","type":"update","data":[{"symbol":"ETH/USD","bids":[{"price":3698.85,"qty":0.00000000},{"price":3698.06,"qty":2.11000000}],"asks":[],"checksum":2942247621,"timestamp":"2024-05-24T15:54:02.014205Z"}]}
{"channel":"book","type":"update","data":[{"symbol":"ETH/USD","bids":[{"price":3698.89,"qty":27.03513756}],"asks":[],"checksum":4294175117,"timestamp":"2024-05-24T15:54:02.018273Z"}]}
{"channel":"book","type":"update","data":[{"symbol":"ETH/USD","bids":[],"asks":[{"price":3699.20,"qty":27.03292151}],"checksum":3171912274,"timestamp":"2024-05-24T15:54:02.018290Z"}]}
{"channel":"book","type":"update","data":[{"symbol":"ETH/USD","bids":[{"price":3698.87,"qty":27.03528374}],"asks":[],"checksum":3323777111,"timestamp":"2024-05-24T15:54:02.018350Z"}]}
{"channel":"book","type":"update","data":[{"symbol":"ETH/USD","bids":[{"price":3698.86,"qty":3.02663772}],"asks":[],"checksum":2870955072,"timestamp":"2024-05-24T15:54:02.021397Z"}]}
{"channel":"book","type":"update","data":[{"symbol":"ETH/USD","bids":[{"price":3698.86,"qty":3.00000000},{"price":3698.36,"qty":0.02664132}],"asks":[],"checksum":2301871519,"timestamp":"2024-05-24T15:54:02.022740Z"}]}
{"channel":"book","type":"update","data":[{"symbol":"ETH/USD","bids":[],"asks":[{"price":3699.64,"qty":3.18750000}],"checksum":91504693,"timestamp":"2024-05-24T15:54:02.028119Z"}]}
{"channel":"book","type":"update","data":[{"symbol":"BTC/USD","bids":[{"price":68200.1,"qty":11.96525600}],"asks":[],"checksum":645345460,"timestamp":"2024-05-24T15:54:02.035585Z"}]}
{"channel":"book","type":"update","data":[{"symbol":"ETH/USD","bids":[],"asks":[{"price":3699.64,"qty":0.00000000},{"price":3699.98,"qty":16.22125796}],"checksum":2301871519,"timestamp":"2024-05-24T15:54:02.047432Z"}]}
{"channel":"book","type":"update","data":[{"symbol":"ETH/USD","bids":[{"price":3698.35,"qty":0.00000000},{"price":3698.16,"qty":0.75856873}],"asks":[],"checksum":1947318589,"timestamp":"2024-05-24T15:54:02.052862Z"}]}
{"channel":"book","type":"update","data":[{"symbol":"ETH/USD","bids":[{"price":3698.89,"qty":30.22263756}],"asks":[],"checksum":2718280504,"timestamp":"2024-05-24T15:54:02.059237Z"}]}
{"channel":"book","type":"update","data":[{"symbol":"BTC/USD","bids":[{"price":68184.7,"qty":0.00000000},{"price":68178.8,"qty":0.11607238}],"asks":[],"checksum":1347566258,"timestamp":"2024-05-24T15:54:02.062286Z"}]}
{"channel":"book","type":"update","data":[{"symbol":"BTC/USD","bids":[{"price":68185.3,"qty":1.46659000}],"asks":[],"checksum":1746222787,"timestamp":"2024-05-24T15:54:02.066170Z"}]}
{"channel":"book","type":"update","data":[{"symbol":"BTC/USD","bids":[{"price":68183.9,"qty":0.00000000},{"price":68178.8,"qty":0.11607238}],"asks":[],"checksum":3393830316,"timestamp":"2024-05-24T15:54:02.085027Z"}]}
{"channel":"book","type":"update","data":[{"symbol":"ETH/USD","bids":[{"price":3698.87,"qty":0.00000000},{"price":3698.14,"qty":0.72912968}],"asks":[],"checksum":3757726842,"timestamp":"2024-05-24T15:54:02.087177Z"}]}
{"channel":"book","type":"update","data":[{"symbol":"ETH/USD","bids":[],"asks":[{"price":3699.20,"qty":0.00000000},{"price":3700.01,"qty":3.18750000}],"checksum":3773681315,"timestamp":"2024-05-24T15:54:02.087221Z"}]}
{"channel":"book","type":"update","data":[{"symbol":"ETH/USD","bids":[],"asks":[{"price":3699.24,"qty":27.03258207}],"checksum":1011674114,"timestamp":"2024-05-24T15:54:02.091108Z"}]}
{"channel":"book","type":"update","data":[{"symbol":"ETH/USD","bids":[{"price":3698.70,"qty":27.03652634}],"asks":[],"checksum":3605820175,"timestamp":"2024-05-24T15:54:02.091168Z"}]}
{"channel":"book","type":"update","data":[{"symbol":"ETH/USD","bids":[],"asks":[{"price":3699.24,"qty":0.00000000},{"price":3700.01,"qty":3.18750000}],"checksum":3029361634,"timestamp":"2024-05-24T15:54:02.096882Z"}]}
{"channel":"book","type":"update","data":[{"symbol":"ETH/USD","bids":[],"asks":[{"price":3700.01,"qty":0.00000000},{"price":3700.11,"qty":0.39579387}],"checksum":3370201653,"timestamp":"2024-05-24T15:54:02.109875Z"}]}
{"channel":"book","type":"update","data":[{"symbol":"ETH/USD","bids":[{"price":3698.33,"qty":3.73217403}],"asks":[],"checksum":486607930,"timestamp":"2024-05-24T15:54:02.111470Z"}]}
{"channel":"book","type":"update","data":[{"symbol":"ETH/USD","bids":[],"asks":[{"price":3699.15,"qty":0.00000000},{"price":3700.26,"qty":0.12684094}],"checksum":3767616913,"timestamp":"2024-05-24T15:54:02.112179Z"}]}
{"channel":"book","type":"update","data":[{"symbol":"ETH/USD","bids":[],"asks":[{"price":3699.35,"qty":1.53600000}],"checksum":3039314036,"timestamp":"2024-05-24T15:54:02.112664Z"}]}
{"channel":"book","type":"update","data":[{"symbol":"BTC/USD","bids":[{"price":68184.1,"qty":1.46661683}],"asks":[],"checksum":760824212,"timestamp":"2024-05-24T15:54:02.113030Z"}]}
{"channel":"book","type":"update","data":[{"symbol":"ETH/USD","bids":[],"asks":[{"price":3700.01,"qty":3.18750000}],"checksum":1913151475,"timestamp":"2024-05-24T15:54:02.114511Z"}]}
{"channel":"book","type":"update","data":[{"symbol":"ETH/USD","bids":[{"price":3698.33,"qty":5.84217403}],"asks":[],"checksum":1576843509,"timestamp":"2024-05-24T15:54:02.114524Z"}]}
{"channel":"book","type":"update","data":[{"symbol":"ETH/USD","bids":[],"asks":[{"price":3699.61,"qty":2.11000000}],"checksum":1425837747,"timestamp":"2024-05-24T15:54:02.114546Z"}]}
{"channel":"book","type":"update","data":[{"symbol":"ETH/USD","bids":[],"asks":[{"price":3699.27,"qty":0.04046589}],"checksum":2138609271,"timestamp":"2024-05-24T15:54:02.116639Z"}]}
{"channel":"book","type":"update","data":[{"symbol":"ETH/USD","bids":[],"asks":[{"price":3699.57,"qty":4.05521582}],"checksum":2437772979,"timestamp":"2024-05-24T15:54:02.117284Z"}]}
{"channel":"book","type":"update","data":[{"symbol":"ETH/USD","bids":[],"asks":[{"price":3699.76,"qty":4.05521582}],"checksum":245494817,"timestamp":"2024-05-24T15:54:02.117676Z"}]}
{"channel":"book","type":"update","data":[{"symbol":"ETH/USD","bids":[],"asks":[{"price":3699.28,"qty":0.00000000},{"price":3699.98,"qty":16.22125796}],"checksum":739279428,"timestamp":"2024-05-24T15:54:02.122976Z"}]}
{"channel":"book","type":"update","data":[{"symbol":"ETH/USD","bids":[{"price":3698.70,"qty":0.00000000},{"price":3698.14,"qty":0.72912968}],"asks":[],"checksum":1217122784,"timestamp":"2024-05-24T15:54:02.124133Z"}]}
{"channel":"book","type":"update","data":[{"symbol":"ETH/USD","bids":[],"asks":[{"price":3699.27,"qty":0.00000000},{"price":3700.01,"qty":3.18750000}],"checksum":2800949321,"timestamp":"2024-05-24T15:54:02.125293Z"}]}
{"channel":"book","type":"update","data":[{"symbol":"ETH/USD","bids":[],"asks":[{"price":3699.61,"qty":0.00000000},{"price":3700.11,"qty":0.39579387},{"price":3699.87,"qty":2.11000000}],"checksum":3133998578,"timestamp":"2024-05-24T15:54:02.128083Z"}]}
{"channel":"book","type":"update","data":[{"symbol":"ETH/USD","bids":[],"asks":[{"price":3699.87,"qty":4.22000000}],"checksum":2109181838,"timestamp":"2024-05-24T15:54:02.129064Z"}]}
{"channel":"book","type":"update","data":[{"symbol":"ETH/USD","bids":[],"asks":[{"price":3699.34,"qty":27.03188996}],"checksum":1372743667,"timestamp":"2024-05-24T15:54:02.134926Z"}]}
{"channel":"book","type":"update","data":[{"symbol":"ETH/USD","bids":[{"price":3698.80,"qty":27.03578552}],"asks":[],"checksum":2890454091,"timestamp":"2024-05-24T15:54:02.135124Z"}]}
{"channel":"book","type":"update","data":[{"symbol":"ETH/BTC","bids":[],"asks":[{"price":0.05426,"qty":8.51598945}],"checksum":1645559508,"timestamp":"2024-05-24T15:54:02.135659Z"}]}
{"channel":"book","type":"update","data":[{"symbol":"ETH/BTC","bids":[],"asks":[{"price":0.05428,"qty":17.40843887}],"checksum":1395505026,"timestamp":"2024-05-24T15:54:02.142607Z"}]}
{"channel":"book","type":"update","data":[{"symbol":"ETH/USD","bids":[],"asks":[{"price":3699.34,"qty":0.00000000},{"price":3700.01,"qty":3.18750000}],"checksum":2550699487,"timestamp":"2024-05-24T15:54:02.143399Z"}]}
{"channel":"book","type":"update","data":[{"symbol":"ETH/USD","bids":[],"asks":[{"price":3699.97,"qty":0.00000000},{"price":3700.11,"qty":0.39579387}],"checksum":2089902772,"timestamp":"2024-05-24T15:54:02.147145Z"}]}
{"channel":"book","type":"update","data":[{"symbol":"BTC/USD","bids":[{"price":68185.3,"qty":0.00000000},{"price":68178.8,"qty":0.11607238}],"asks":[],"checksum":493272450,"timestamp":"2024-05-24T15:54:02.151090Z"}]}
{"channel":"book","type":"update","data":[{"symbol":"ETH/USD","bids":[],"asks":[{"price":3699.38,"qty":27.03162555}],"checksum":3104937952,"timestamp":"2024-05-24T15:54:02.157178Z"}]}
{"channel":"book","type":"update","data":[{"symbol":"ETH/USD","bids":[{"price":3698.89,"qty":57.25777512}],"asks":[],"checksum":4032818518,"timestamp":"2024-05-24T15:54:02.157206Z"}]}
{"channel":"book","type":"update","data":[{"symbol":"BTC/USD","bids":[{"price":68185.8,"qty":1.46658095}],"asks":[],"checksum":4280230999,"timestamp":"2024-05-24T15:54:02.157317Z"}]}
{"channel":"book","type":"update","data":[{"symbol":"ETH/USD","bids":[],"asks":[{"price":3699.58,"qty":27.84467994}],"checksum":1482683485,"timestamp":"2024-05-24T15:54:02.157363Z"}]}
{"channel":"book","type":"update","data":[{"symbol":"ETH/USD","bids":[],"asks":[{"price":3699.48,"qty":27.03087702}],"checksum":2048158213,"timestamp":"2024-05-24T15:54:02.157376Z"}]}
{"channel":"book","type":"update","data":[{"symbol":"ETH/USD","bids":[{"price":3698.33,"qty":3.73217403}],"asks":[],"checksum":1440779523,"timestamp":"2024-05-24T15:54:02.161461Z"}]}
{"channel":"book","type":"update","data":[{"symbol":"ETH/USD","bids":[{"price":3698.80,"qty":0.00000000},{"price":3698.14,"qty":0.72912968}],"asks":[],"checksum":1350186805,"timestamp":"2024-05-24T15:54:02.167006Z"}]}
{"channel":"book","type":"update","data":[{"symbol":"BTC/USD","bids":[{"price":68185.8,"qty":0.00000000},{"price":68178.8,"qty":0.11607238}],"asks":[],"checksum":493272450,"timestamp":"2024-05-24T15:54:02.171348Z"}]}
{"channel":"book","type":"update","data":[{"symbol":"ETH/USD","bids":[],"asks":[{"price":3699.38,"qty":0.00000000},{"price":3700.01,"qty":3.18750000}],"checksum":3414112489,"timestamp":"2024-05-24T15:54:02.172600Z"}]}
{"channel":"book","type":"update","data":[{"symbol":"ETH/USD","bids":[],"asks":[{"price":3699.48,"qty":0.00000000},{"price":3700.11,"qty":0.39579387}],"checksum":656047906,"timestamp":"2024-05-24T15:54:02.172669Z"}]}
{"channel":"book","type":"update","data":[{"symbol":"ETH/USD","bids":[],"asks":[{"price":3700.01,"qty":0.00000000},{"price":3700.18,"qty":16.22086327}],"checksum":4292411066,"timestamp":"2024-05-24T15:54:02.186956Z"}]}
{"channel":"book","type":"update","data":[{"symbol":"ETH/USD","bids":[{"price":3698.33,"qty":1.62217403},{"price":3698.60,"qty":2.11000000}],"asks":[],"checksum":2794099596,"timestamp":"2024-05-24T15:54:02.190709Z"}]}
{"channel":"book","type":"update","data":[{"symbol":"ETH/USD","bids":[],"asks":[{"price":3700.01,"qty":3.18750000}],"checksum":1485195899,"timestamp":"2024-05-24T15:54:02.191508Z"}]}
{"channel":"book","type":"update","data":[{"symbol":"ETH/USD","bids":[],"asks":[{"price":3699.54,"qty":0.40096984}],"checksum":4257387544,"timestamp":"2024-05-24T15:54:02.192479Z"}]}
{"channel":"book","type":"update","data":[{"symbol":"ETH/USD","bids":[{"price":3698.60,"qty":4.22000000}],"asks":[],"checksum":3029098939,"timestamp":"2024-05-24T15:54:02.193338Z"}]}
{"channel":"book","type":"update","data":[{"symbol":"ETH/USD","bids":[],"asks":[{"price":3699.87,"qty":2.11000000}],"checksum":3744627350,"timestamp":"2024-05-24T15:54:02.193426Z"}]}
{"channel":"book","type":"update","data":[{"symbol":"ETH/USD","bids":[],"asks":[{"price":3699.87,"qty":0.00000000},{"price":3700.11,"qty":0.39579387},{"price":3700.10,"qty":2.11000000}],"checksum":3908189707,"timestamp":"2024-05-24T15:54:02.193570Z"}]}
{"channel":"book","type":"update","data":[{"symbol":"ETH/USD","bids":[{"price":3698.89,"qty":57.98690480}],"asks":[],"checksum":837744803,"timestamp":"2024-05-24T15:54:02.194993Z"}]}
{"channel":"book","type":"update","data":[{"symbol":"ETH/USD","bids":[{"price":3698.89,"qty":61.17440480}],"asks":[],"checksum":4130074581,"timestamp":"2024-05-24T15:54:02.215836Z"}]}
{"channel":"book","type":"update","data":[{"symbol":"ETH/USD","bids":[],"asks":[{"price":3699.38,"qty":27.03156480}],"checksum":2605790978,"timestamp":"2024-05-24T15:54:02.224835Z"}]}
{"channel":"book","type":"update","data":[{"symbol":"ETH/USD","bids":[{"price":3698.89,"qty":88.20954236}],"asks":[],"checksum":3419126196,"timestamp":"2024-05-24T15:54:02.224890Z"}]}
{"channel":"book","type":"update","data":[{"symbol":"ETH/USD","bids":[],"asks":[{"price":3699.38,"qty":0.00000000},{"price":3700.10,"qty":2.11000000}],"checksum":2796642659,"timestamp":"2024-05-24T15:54:02.228552Z"}]}
{"channel":"book","type":"update","data":[{"symbol":"ETH/USD","bids":[{"price":3698.89,"qty":85.02204236}],"asks":[],"checksum":3356015795,"timestamp":"2024-05-24T15:54:02.228724Z"}]}
{"channel":"book","type":"update","data":[{"symbol":"ETH/USD","bids":[{"price":3698.89,"qty":81.83454236}],"asks":[],"checksum":276514417,"timestamp":"2024-05-24T15:54:02.241438Z"}]}
{"channel":"book","type":"update","data":[{"symbol":"ETH/USD","bids":[],"asks":[{"price":3699.58,"qty":0.81451322}],"checksum":3091582510,"timestamp":"2024-05-24T15:54:02.244565Z"}]}
{"channel":"book","type":"update","data":[{"symbol":"ETH/USD","bids":[{"price":3698.89,"qty":54.79940480}],"asks":[],"checksum":2789622235,"timestamp":"2024-05-24T15:54:02.244651Z"}]}
{"channel":"book","type":"update","data":[{"symbol":"ETH/USD","bids":[],"asks":[{"price":3699.64,"qty":3.18750000}],"checksum":1031544763,"timestamp":"2024-05-24T15:54:02.245065Z"}]}
{"channel":"book","type":"update","data":[{"symbol":"BTC/USD","bids":[{"price":68185.3,"qty":1.46659092}],"asks":[],"checksum":3324724252,"timestamp":"2024-05-24T15:54:02.246784Z"}]}
{"channel":"book","type":"update","data":[{"symbol":"ETH/USD","bids":[],"asks":[{"price":3699.54,"qty":0.00000000},{"price":3700.10,"qty":2.11000000}],"checksum":2514359812,"timestamp":"2024-05-24T15:54:02.266463Z"}]}
{"channel":"book","type":"update","data":[{"symbol":"BTC/USD","bids":[{"price":68185.3,"qty":0.00000000},{"price":68178.8,"qty":0.11607238}],"asks":[],"checksum":493272450,"timestamp":"2024-05-24T15:54:02.271259Z"}]}
{"channel":"book","type":"update","data":[{"symbol":"ETH/USD","bids":[],"asks":[{"price":3699.64,"qty":0.00000000},{"price":3700.11,"qty":0.39579387}],"checksum":3655773280,"timestamp":"2024-05-24T15:54:02.274126Z"}]}
{"channel":"book","type":"update","data":[{"symbol":"ETH/USD","bids":[{"price":3698.89,"qty":57.98690480}],"asks":[],"checksum":3866139975,"timestamp":"2024-05-24T15:54:02.275428Z"}]}
{"channel":"book","type":"update","data":[{"symbol":"ETH/USD","bids":[],"asks":[{"price":3699.20,"qty":27.03291676}],"checksum":1451934952,"timestamp":"2024-05-24T15:54:02.280473Z"}]}
{"channel":"book","type":"update","data":[{"symbol":"BTC/USD","bids":[{"price":68181.2,"qty":0.00248047}],"asks":[],"checksum":1615391938,"timestamp":"2024-05-24T15:54:02.281789Z"}]}
{"channel":"book","type":"update","data":[{"symbol":"ETH/USD","bids":[],"asks":[{"price":3699.20,"qty":0.00000000},{"price":3700.11,"qty":0.39579387}],"checksum":3866139975,"timestamp":"2024-05-24T15:54:02.307071Z"}]}
{"channel":"book","type":"update","data":[{"symbol":"BTC/USD","bids":[{"price":68181.2,"qty":0.00000000},{"price":68178.8,"qty":0.11607238}],"asks":[],"checksum":493272450,"timestamp":"2024-05-24T15:54:02.351772Z"}]}
{"channel":"book","type":"update","data":[{"symbol":"ETH/USD","bids":[],"asks":[{"price":3699.24,"qty":27.03259629}],"checksum":2257205990,"timestamp":"2024-05-24T15:54:02.371145Z"}]}
{"channel":"book","type":"update","data":[{"symbol":"ETH/USD","bids":[{"price":3698.63,"qty":27.03696593}],"asks":[],"checksum":3762709916,"timestamp":"2024-05-24T15:54:02.371222Z"}]}
{"channel":"book","type":"update","data":[{"symbol":"ETH/USD","bids":[{"price":3698.89,"qty":54.79940480}],"asks":[],"checksum":1801316437,"timestamp":"2024-05-24T15:54:02.374720Z"}]}
{"channel":"book","type":"update","data":[{"symbol":"ETH/USD","bids":[],"asks":[{"price":3699.64,"qty":3.18750000}],"checksum":2188600379,"timestamp":"2024-05-24T15:54:02.378073Z"}]}
{"channel":"book","type":"update","data":[{"symbol":"BTC/USD","bids":[{"price":68184.7,"qty":1.46660456}],"asks":[],"checksum":1472302234,"timestamp":"2024-05-24T15:54:02.416141Z"}]}
{"channel":"book","type":"update","data":[{"symbol":"ETH/USD","bids":[],"asks":[{"price":3699.64,"qty":0.00000000},{"price":3700.10,"qty":2.11000000}],"checksum":1801316437,"timestamp":"2024-05-24T15:54:02.419899Z"}]}
{"channel":"book","type":"update","data":[{"symbol":"BTC/USD","bids":[{"price":68184.7,"qty":0.00000000},{"price":68178.8,"qty":0.11607238}],"asks":[],"checksum":493272450,"timestamp":"2024-05-24T15:54:02.420533Z"}]}
{"channel":"book","type":"update","data":[{"symbol":"ETH/USD","bids":[],"asks":[{"price":3699.64,"qty":3.18750000}],"checksum":2188600379,"timestamp":"2024-05-24T15:54:02.427026Z"}]}
{"channel":"book","type":"update","data":[{"symbol":"ETH/BTC","bids":[{"price":0.05417,"qty":0.94218042}],"asks":[],"checksum":3229552055,"timestamp":"2024-05-24T15:54:02.441854Z"}]}
{"channel":"book","type":"update","data":[{"symbol":"ETH/USD","bids":[],"asks":[{"price":3699.64,"qty":0.00000000},{"price":3700.10,"qty":2.11000000}],"checksum":1801316437,"timestamp":"2024-05-24T15:54:02.502413Z"}]}
{"channel":"book","type":"update","data":[{"symbol":"ETH/USD","bids":[{"price":3698.89,"qty":57.98690480}],"asks":[],"checksum":3762709916,"timestamp":"2024-05-24T15:54:02.540555Z"}]}
{"channel":"book","type":"update","data":[{"symbol":"ETH/USD","bids":[{"price":3698.89,"qty":58.25282382}],"asks":[],"checksum":3621240722,"timestamp":"2024-05-24T15:54:02.545714Z"}]}
{"channel":"book","type":"update","data":[{"symbol":"ETH/USD","bids":[],"asks":[{"price":3699.13,"qty":0.39579387}],"checksum":3455279611,"timestamp":"2024-05-24T15:54:02.548678Z"}]}
{"channel":"book","type":"update","data":[{"symbol":"ETH/USD","bids":[],"asks":[{"price":3699.24,"qty":0.00000000},{"price":3700.10,"qty":2.11000000}],"checksum":15587496,"timestamp":"2024-05-24T15:54:02.599478Z"}]}
{"channel":"book","type":"update","data":[{"symbol":"ETH/USD","bids":[],"asks":[{"price":3699.26,"qty":27.03249656}],"checksum":4047452564,"timestamp":"2024-05-24T15:54:02.604424Z"}]}
{"channel":"book","type":"update","data":[{"symbol":"ETH/USD","bids":[],"asks":[{"price":3699.46,"qty":27.03102786}],"checksum":1460164625,"timestamp":"2024-05-24T15:54:02.604517Z"}]}
{"channel":"book","type":"update","data":[{"symbol":"ETH/USD","bids":[{"price":3698.77,"qty":27.03595532}],"asks":[],"checksum":3783949004,"timestamp":"2024-05-24T15:54:02.604616Z"}]}
{"channel":"book","type":"update","data":[{"symbol":"ETH/USD","bids":[],"asks":[{"price":3699.64,"qty":3.18750000}],"checksum":838195563,"timestamp":"2024-05-24T15:54:02.630471Z"}]}
{"channel":"book","type":"update","data":[{"symbol":"ETH/USD","bids":[{"price":3698.89,"qty":55.06532382}],"asks":[],"checksum":758067975,"timestamp":"2024-05-24T15:54:02.630776Z"}]}
{"channel":"book","type":"update","data":[{"symbol":"ETH/USD","bids":[],"asks":[{"price":3699.26,"qty":0.00000000},{"price":3699.98,"qty":16.22125796}],"checksum":2833261945,"timestamp":"2024-05-24T15:54:02.640203Z"}]}
{"channel":"book","type":"update","data":[{"symbol":"ETH/USD","bids":[],"asks":[{"price":3699.65,"qty":27.02958933}],"checksum":4101050051,"timestamp":"2024-05-24T15:54:02.675855Z"}]}
{"channel":"book","type":"update","data":[{"symbol":"ETH/USD","bids":[],"asks":[{"price":3699.23,"qty":27.03268668}],"checksum":3981544471,"timestamp":"2024-05-24T15:54:02.675909Z"}]}
{"channel":"book","type":"update","data":[{"symbol":"ETH/USD","bids":[],"asks":[{"price":3699.23,"qty":0.00000000},{"price":3699.96,"qty":0.18297066}],"checksum":4101050051,"timestamp":"2024-05-24T15:54:02.679765Z"}]}
{"channel":"book","type":"update","data":[{"symbol":"ETH/USD","bids":[{"price":3698.63,"qty":0.00000000},{"price":3698.31,"qty":3.18750000}],"asks":[],"checksum":3668430678,"timestamp":"2024-05-24T15:54:02.686522Z"}]}
{"channel":"book","type":"update","data":[{"symbol":"ETH/USD","bids":[{"price":3698.86,"qty":0.00000000},{"price":3698.16,"qty":0.75856873}],"asks":[],"checksum":3654246605,"timestamp":"2024-05-24T15:54:02.699821Z"}]}
{"channel":"book","type":"update","data":[{"symbol":"ETH/USD","bids":[],"asks":[{"price":3699.25,"qty":27.03255151}],"checksum":3874738681,"timestamp":"2024-05-24T15:54:02.741060Z"}]}
{"channel":"book","type":"update","data":[{"symbol":"ETH/USD","bids":[],"asks":[{"price":3699.25,"qty":0.00000000},{"price":3699.77,"qty":0.40087700}],"checksum":585261871,"timestamp":"2024-05-24T15:54:02.773761Z"}]}
{"channel":"book","type":"update","data":[{"symbol":"BTC/USD","bids":[{"price":68184.4,"qty":1.46660933}],"asks":[],"checksum":111141025,"timestamp":"2024-05-24T15:54:02.785235Z"}]}
{"channel":"book","type":"update","data":[{"symbol":"BTC/USD","bids":[{"price":68184.4,"qty":0.00000000},{"price":68178.8,"qty":0.11607238}],"asks":[],"checksum":493272450,"timestamp":"2024-05-24T15:54:02.800218Z"}]}
{"channel":"book","type":"update","data":[{"symbol":"BTC/USD","bids":[{"price":68183.1,"qty":1.46663844}],"asks":[],"checksum":1165914439,"timestamp":"2024-05-24T15:54:02.827560Z"}]}
{"channel":"book","type":"update","data":[{"symbol":"ETH/USD","bids":[],"asks":[{"price":3699.21,"qty":27.03281154}],"checksum":2822058355,"timestamp":"2024-05-24T15:54:02.828844Z"}]}
{"channel":"book","type":"update","data":[{"symbol":"BTC/USD","bids":[{"price":68183.1,"qty":0.00000000},{"price":68178.8,"qty":0.11607238}],"asks":[],"checksum":493272450,"timestamp":"2024-05-24T15:54:02.835442Z"}]}
{"channel":"book","type":"update","data":[{"symbol":"BTC/USD","bids":[{"price":68184.7,"qty":1.46660405}],"asks":[],"checksum":3023950890,"timestamp":"2024-05-24T15:54:02.839199Z"}]}
{"channel":"book","type":"update","data":[{"symbol":"ETH/USD","bids":[],"asks":[{"price":3699.64,"qty":0.00000000},{"price":3699.77,"qty":0.40087700}],"checksum":1081755025,"timestamp":"2024-05-24T15:54:02.889723Z"}]}
{"channel":"book","type":"update","data":[{"symbol":"ETH/USD","bids":[{"price":3698.89,"qty":58.25282382}],"asks":[],"checksum":2908301742,"timestamp":"2024-05-24T15:54:02.892300Z"}]}
{"channel":"book","type":"update","data":[{"symbol":"ETH/USD","bids":[],"asks":[{"price":3699.27,"qty":27.03236413}],"checksum":2904728088,"timestamp":"2024-05-24T15:54:02.892652Z"}]}
{"channel":"book","type":"update","data":[{"symbol":"ETH/USD","bids":[{"price":3698.49,"qty":27.03804515}],"asks":[],"checksum":167575108,"timestamp":"2024-05-24T15:54:02.892828Z"}]}
{"channel":"book","type":"update","data":[{"symbol":"ETH/USD","bids":[],"asks":[{"price":3699.21,"qty":0.00000000},{"price":3699.77,"qty":0.40087700}],"checksum":3103069627,"timestamp":"2024-05-24T15:54:02.894614Z"}]}
{"channel":"book","type":"update","data":[{"symbol":"ETH/USD","bids":[],"asks":[{"price":3699.23,"qty":27.03269259}],"checksum":2295293381,"timestamp":"2024-05-24T15:54:02.900383Z"}]}
{"channel":"book","type":"update","data":[{"symbol":"ETH/USD","bids":[],"asks":[{"price":3699.23,"qty":0.00000000},{"price":3699.77,"qty":0.40087700}],"checksum":3103069627,"timestamp":"2024-05-24T15:54:02.911321Z"}]}
{"channel":"book","type":"update","data":[{"symbol":"ETH/USD","bids":[],"asks":[{"price":3699.27,"qty":0.00000000},{"price":3699.96,"qty":0.18297066}],"checksum":2936491252,"timestamp":"2024-05-24T15:54:02.924508Z"}]}
{"channel":"book","type":"update","data":[{"symbol":"ETH/BTC","bids":[{"price":0.05424,"qty":6.04363036},{"price":0.05425,"qty":5.39364970}],"asks":[],"checksum":2461082339,"timestamp":"2024-05-24T15:54:02.941986Z"}]}
{"channel":"book","type":"update","data":[{"symbol":"ETH/USD","bids":[],"asks":[{"price":3699.31,"qty":27.03209279}],"checksum":2163181100,"timestamp":"2024-05-24T15:54:02.955510Z"}]}
{"channel":"book","type":"update","data":[{"symbol":"ETH/BTC","bids":[{"price":0.05425,"qty":5.38728080},{"price":0.05424,"qty":6.05000043}],"asks":[],"checksum":1185712421,"timestamp":"2024-05-24T15:54:02.956850Z"}]}
{"channel":"book","type":"update","data":[{"symbol":"ETH/USD","bids":[],"asks":[{"price":3699.31,"qty":0.00000000},{"price":3699.96,"qty":0.18297066}],"checksum":2936491252,"timestamp":"2024-05-24T15:54:02.960144Z"}]}
{"channel":"book","type":"update","data":[{"symbol":"ETH/USD","bids":[{"price":3698.36,"qty":0.00000000},{"price":3698.16,"qty":0.75856873},{"price":3698.78,"qty":0.02661785}],"asks":[],"checksum":791413927,"timestamp":"2024-05-24T15:54:02.974703Z"}]}
{"channel":"book","type":"update","data":[{"symbol":"BTC/USD","bids":[{"price":68184.7,"qty":0.00000000},{"price":68178.8,"qty":0.11607238}],"asks":[],"checksum":493272450,"timestamp":"2024-05-24T15:54:02.993215Z"}]}
{"channel":"book","type":"update","data":[{"symbol":"BTC/USD","bids":[{"price":68184.9,"qty":1.46659877}],"asks":[],"checksum":3464014521,"timestamp":"2024-05-24T15:54:02.997505Z"}]}
{"channel":"book","type":"update","data":[{"symbol":"ETH/USD","bids":[],"asks":[{"price":3699.32,"qty":27.03201500}],"checksum":303885871,"timestamp":"2024-05-24T15:54:03.017599Z"}]}
{"channel":"book","type":"update","data":[{"symbol":"ETH/USD","bids":[],"asks":[{"price":3699.32,"qty":0.00000000},{"price":3699.97,"qty":0.18297271}],"checksum":2396450986,"timestamp":"2024-05-24T15:54:03.044895Z"}]}
{"channel":"book","type":"update","data":[{"symbol":"ETH/USD","bids":[{"price":3698.49,"qty":0.00000000},{"price":3698.16,"qty":0.75856873}],"asks":[],"checksum":817978018,"timestamp":"2024-05-24T15:54:03.044933Z"}]}
{"channel":"book","type":"update","data":[{"symbol":"ETH/USD","bids":[{"price":3698.87,"qty":27.03523762}],"asks":[],"checksum":3959038496,"timestamp":"2024-05-24T15:54:03.049375Z"}]}
{"channel":"book","type":"update","data":[{"symbol":"ETH/USD","bids":[],"asks":[{"price":3699.35,"qty":0.00000000},{"price":3699.98,"qty":16.22125796}],"checksum":3204070889,"timestamp":"2024-05-24T15:54:03.075596Z"}]}
{"channel":"book","type":"update","data":[{"symbol":"ETH/USD","bids":[{"price":3698.77,"qty":0.00000000},{"price":3698.16,"qty":0.75856873}],"asks":[],"checksum":517297759,"timestamp":"2024-05-24T15:54:03.077222Z"}]}
{"channel":"book","type":"update","data":[{"symbol":"ETH/USD","bids":[],"asks":[{"price":3699.65,"qty":0.00000000},{"price":3700.01,"qty":3.18750000}],"checksum":1527534157,"timestamp":"2024-05-24T15:54:03.077340Z"}]}
{"channel":"book","type":"update","data":[{"symbol":"ETH/USD","bids":[{"price":3698.87,"qty":0.00000000},{"price":3697.82,"qty":1.53600000}],"asks":[],"checksum":1267878453,"timestamp":"2024-05-24T15:54:03.082039Z"}]}
{"channel":"book","type":"update","data":[{"symbol":"BTC/USD","bids":[{"price":68184.9,"qty":0.00000000},{"price":68178.8,"qty":0.11607238}],"asks":[],"checksum":493272450,"timestamp":"2024-05-24T15:54:03.082837Z"}]}
{"channel":"book","type":"update","data":[{"symbol":"BTC/USD","bids":[{"price":68184.1,"qty":0.00000000},{"price":68177.6,"qty":0.00247878}],"asks":[],"checksum":1277606202,"timestamp":"2024-05-24T15:54:03.083134Z"}]}
{"channel":"book","type":"update","data":[{"symbol":"ETH/USD","bids":[],"asks":[{"price":3699.42,"qty":27.03130324}],"checksum":2316530751,"timestamp":"2024-05-24T15:54:03.086081Z"}]}
{"channel":"book","type":"update","data":[{"symbol":"ETH/USD","bids":[],"asks":[{"price":3699.56,"qty":27.03026794}],"checksum":3017321265,"timestamp":"2024-05-24T15:54:03.086107Z"}]}
{"channel":"book","type":"update","data":[{"symbol":"BTC/USD","bids":[{"price":68185.9,"qty":1.46657706}],"asks":[],"checksum":3344050483,"timestamp":"2024-05-24T15:54:03.087296Z"}]}
{"channel":"book","type":"update","data":[{"symbol":"ETH/USD","bids":[],"asks":[{"price":3699.42,"qty":0.00000000},{"price":3699.98,"qty":16.22125796}],"checksum":876333566,"timestamp":"2024-05-24T15:54:03.095840Z"}]}
{"channel":"book","type":"update","data":[{"symbol":"ETH/USD","bids":[],"asks":[{"price":3699.56,"qty":0.00000000},{"price":3700.01,"qty":3.18750000}],"checksum":1267878453,"timestamp":"2024-05-24T15:54:03.103417Z"}]}
{"channel":"book","type":"update","data":[{"symbol":"ETH/USD","bids":[],"asks":[{"price":3699.45,"qty":27.03111743}],"checksum":3000078763,"timestamp":"2024-05-24T15:54:03.151457Z"}]}
{"channel":"book","type":"update","data":[{"symbol":"BTC/USD","bids":[{"price":68185.9,"qty":0.00000000},{"price":68177.5,"qty":0.03947498}],"asks":[],"checksum":2897760783,"timestamp":"2024-05-24T15:54:03.157641Z"}]}
{"channel":"book","type":"update","data":[{"symbol":"BTC/USD","bids":[{"price":68186.0,"qty":1.46657511}],"asks":[],"checksum":580214039,"timestamp":"2024-05-24T15:54:03.162908Z"}]}
{"channel":"book","type":"update","data":[{"symbol":"ETH/USD","bids":[],"asks":[{"price":3699.56,"qty":1.53600000}],"checksum":4105499430,"timestamp":"2024-05-24T15:54:03.174070Z"}]}
{"channel":"book","type":"update","data":[{"symbol":"ETH/USD","bids":[],"asks":[{"price":3699.81,"qty":27.02848064}],"checksum":828423589,"timestamp":"2024-05-24T15:54:03.177440Z"}]}
{"channel":"book","type":"update","data":[{"symbol":"BTC/USD","bids":[{"price":68186.0,"qty":0.00000000},{"price":68177.5,"qty":0.03947498}],"asks":[],"checksum":2897760783,"timestamp":"2024-05-24T15:54:03.193145Z"}]}
{"channel":"book","type":"update","data":[{"symbol":"ETH/USD","bids":[],"asks":[{"price":3699.13,"qty":0.00000000},{"price":3699.97,"qty":0.18297271}],"checksum":537113090,"timestamp":"2024-05-24T15:54:03.219916Z"}]}
{"channel":"book","type":"update","data":[{"symbol":"ETH/USD","bids":[],"asks":[{"price":3699.45,"qty":0.00000000},{"price":3699.98,"qty":16.22125796}],"checksum":1345222555,"timestamp":"2024-05-24T15:54:03.240349Z"}]}
{"channel":"book","type":"update","data":[{"symbol":"ETH/USD","bids":[],"asks":[{"price":3699.47,"qty":27.03090388}],"checksum":1631979112,"timestamp":"2024-05-24T15:54:03.244133Z"}]}
{"channel":"book","type":"update","data":[{"symbol":"ETH/USD","bids":[],"asks":[{"price":3699.45,"qty":0.04046589}],"checksum":2422956668,"timestamp":"2024-05-24T15:54:03.293872Z"}]}
{"channel":"book","type":"update","data":[{"symbol":"ETH/USD","bids":[],"asks":[{"price":3699.56,"qty":0.00000000},{"price":3699.97,"qty":0.18297271}],"checksum":1145859276,"timestamp":"2024-05-24T15:54:03.295987Z"}]}
{"channel":"book","type":"update","data":[{"symbol":"ETH/USD","bids":[],"asks":[{"price":3699.47,"qty":0.00000000},{"price":3699.98,"qty":16.22125796}],"checksum":2655816807,"timestamp":"2024-05-24T15:54:03.301869Z"}]}
{"channel":"book","type":"update","data":[{"symbol":"ETH/USD","bids":[],"asks":[{"price":3699.46,"qty":0.00000000},{"price":3700.01,"qty":3.18750000}],"checksum":3217502370,"timestamp":"2024-05-24T15:54:03.301971Z"}]}
{"channel":"book","type":"update","data":[{"symbol":"ETH/USD","bids":[],"asks":[{"price":3699.45,"qty":0.00000000},{"price":3700.10,"qty":2.11000000}],"checksum":111537744,"timestamp":"2024-05-24T15:54:03.305389Z"}]}
{"channel":"book","type":"update","data":[{"symbol":"ETH/USD","bids":[],"asks":[{"price":3699.54,"qty":27.03040216}],"checksum":1204870885,"timestamp":"2024-05-24T15:54:03.306063Z"}]}
{"channel":"book","type":"update","data":[{"symbol":"ETH/USD","bids":[],"asks":[{"price":3699.49,"qty":27.03078195}],"checksum":2549806549,"timestamp":"2024-05-24T15:54:03.306099Z"}]}
{"channel":"book","type":"update","data":[{"symbol":"ETH/USD","bids":[],"asks":[{"price":3699.53,"qty":0.04046589}],"checksum":908483442,"timestamp":"2024-05-24T15:54:03.309633Z"}]}
{"channel":"book","type":"update","data":[{"symbol":"ETH/BTC","bids":[],"asks":[{"price":0.05430,"qty":2.10047227}],"checksum":1576958264,"timestamp":"2024-05-24T15:54:03.311809Z"}]}
{"channel":"book","type":"update","data":[{"symbol":"ETH/USD","bids":[],"asks":[{"price":3699.53,"qty":0.00000000},{"price":3699.98,"qty":16.22125796}],"checksum":2549806549,"timestamp":"2024-05-24T15:54:03.313157Z"}]}
{"channel":"book","type":"update","data":[{"symbol":"ETH/BTC","bids":[],"asks":[{"price":0.05430,"qty":25.32029629}],"checksum":3970789909,"timestamp":"2024-05-24T15:54:03.317414Z"}]}
{"channel":"book","type":"update","data":[{"symbol":"ETH/USD","bids":[],"asks":[{"price":3699.77,"qty":0.00000000},{"price":3700.01,"qty":3.18750000}],"checksum":597110505,"timestamp":"2024-05-24T15:54:03.326253Z"}]}
{"channel":"book","type":"update","data":[{"symbol":"ETH/USD","bids":[{"price":3698.89,"qty":85.28796138}],"asks":[],"checksum":3016300228,"timestamp":"2024-05-24T15:54:03.360185Z"}]}
{"channel":"book","type":"update","data":[{"symbol":"ETH/USD","bids":[],"asks":[{"price":3699.97,"qty":0.58388815}],"checksum":431989822,"timestamp":"2024-05-24T15:54:03.366407Z"}]}
{"channel":"book","type":"update","data":[{"symbol":"ETH/USD","bids":[],"asks":[{"price":3699.60,"qty":1.53600000}],"checksum":1326732763,"timestamp":"2024-05-24T15:54:03.394451Z"}]}
{"channel":"book","type":"update","data":[{"symbol":"ETH/USD","bids":[],"asks":[{"price":3699.67,"qty":27.02947585}],"checksum":2160680173,"timestamp":"2024-05-24T15:54:03.400349Z"}]}
{"channel":"book","type":"update","data":[{"symbol":"ETH/USD","bids":[{"price":3698.77,"qty":27.03601267}],"asks":[],"checksum":910249660,"timestamp":"2024-05-24T15:54:03.400406Z"}]}
{"channel":"book","type":"update","data":[{"symbol":"BTC/USD","bids":[{"price":68185.3,"qty":1.46658993}],"asks":[],"checksum":2467797977,"timestamp":"2024-05-24T15:54:03.432638Z"}]}
{"channel":"book","type":"update","data":[{"symbol":"ETH/USD","bids":[],"asks":[{"price":3699.49,"qty":0.00000000},{"price":3699.98,"qty":16.22125796}],"checksum":3807176795,"timestamp":"2024-05-24T15:54:03.519940Z"}]}
{"channel":"book","type":"update","data":[{"symbol":"ETH/USD","bids":[],"asks":[{"price":3699.48,"qty":27.03086559}],"checksum":4057632639,"timestamp":"2024-05-24T15:54:03.524270Z"}]}
{"channel":"book","type":"update","data":[{"symbol":"ETH/USD","bids":[],"asks":[{"price":3699.53,"qty":0.04046589}],"checksum":4178503989,"timestamp":"2024-05-24T15:54:03.524382Z"}]}
{"channel":"book","type":"update","data":[{"symbol":"ETH/USD","bids":[],"asks":[{"price":3699.53,"qty":0.00000000},{"price":3699.97,"qty":0.58388815}],"checksum":4057632639,"timestamp":"2024-05-24T15:54:03.527837Z"}]}
{"channel":"book","type":"update","data":[{"symbol":"ETH/USD","bids":[],"asks":[{"price":3699.48,"qty":0.00000000},{"price":3699.98,"qty":16.22125796}],"checksum":3807176795,"timestamp":"2024-05-24T15:54:03.550416Z"}]}
{"channel":"book","type":"update","data":[{"symbol":"ETH/USD","bids":[],"asks":[{"price":3699.54,"qty":0.00000000},{"price":3700.01,"qty":3.18750000}],"checksum":1905227495,"timestamp":"2024-05-24T15:54:03.550544Z"}]}
{"channel":"book","type":"update","data":[{"symbol":"ETH/USD","bids":[],"asks":[{"price":3699.39,"qty":27.03150376}],"checksum":115899000,"timestamp":"2024-05-24T15:54:03.595686Z"}]}
{"channel":"book","type":"update","data":[{"symbol":"ETH/USD","bids":[],"asks":[{"price":3699.38,"qty":4.05504042}],"checksum":2755371599,"timestamp":"2024-05-24T15:54:03.598887Z"}]}
{"channel":"book","type":"update","data":[{"symbol":"BTC/USD","bids":[{"price":68185.3,"qty":0.00000000},{"price":68177.5,"qty":0.03947498}],"asks":[],"checksum":2897760783,"timestamp":"2024-05-24T15:54:03.600061Z"}]}
{"channel":"book","type":"update","data":[{"symbol":"ETH/USD","bids":[],"asks":[{"price":3699.57,"qty":0.00000000},{"price":3700.01,"qty":3.18750000}],"checksum":1780717825,"timestamp":"2024-05-24T15:54:03.601443Z"}]}
{"channel":"book","type":"update","data":[{"symbol":"BTC/USD","bids":[{"price":68185.1,"qty":1.46659422}],"asks":[],"checksum":1740145811,"timestamp":"2024-05-24T15:54:03.604193Z"}]}
{"channel":"book","type":"update","data":[{"symbol":"ETH/USD","bids":[],"asks":[{"price":3699.39,"qty":0.00000000},{"price":3700.10,"qty":2.11000000}],"checksum":2486279299,"timestamp":"2024-05-24T15:54:03.631981Z"}]}
{"channel":"book","type":"update","data":[{"symbol":"ETH/USD","bids":[],"asks":[{"price":3699.49,"qty":27.03082223}],"checksum":980004034,"timestamp":"2024-05-24T15:54:03.636193Z"}]}
{"channel":"book","type":"update","data":[{"symbol":"ETH/USD","bids":[{"price":3698.89,"qty":82.10046138}],"asks":[],"checksum":3347841592,"timestamp":"2024-05-24T15:54:03.662049Z"}]}
{"channel":"book","type":"update","data":[{"symbol":"ETH/USD","bids":[],"asks":[{"price":3699.41,"qty":27.03136313}],"checksum":2932452764,"timestamp":"2024-05-24T15:54:03.663292Z"}]}
{"channel":"book","type":"update","data":[{"symbol":"ETH/USD","bids":[],"asks":[{"price":3699.64,"qty":3.18750000}],"checksum":4180973027,"timestamp":"2024-05-24T15:54:03.666009Z"}]}
{"channel":"book","type":"update","data":[{"symbol":"ETH/USD","bids":[],"asks":[{"price":3699.49,"qty":0.00000000},{"price":3699.97,"qty":0.58388815}],"checksum":4221551579,"timestamp":"2024-05-24T15:54:03.676946Z"}]}
{"channel":"book","type":"update","data":[{"symbol":"ETH/USD","bids":[],"asks":[{"price":3699.41,"qty":0.00000000},{"price":3700.01,"qty":3.18750000}],"checksum":2856836520,"timestamp":"2024-05-24T15:54:03.676987Z"}]}
{"channel":"book","type":"update","data":[{"symbol":"ETH/USD","bids":[{"price":3698.89,"qty":55.06532382}],"asks":[],"checksum":4291697952,"timestamp":"2024-05-24T15:54:03.677036Z"}]}
{"channel":"book","type":"update","data":[{"symbol":"ETH/USD","bids":[],"asks":[{"price":3699.67,"qty":0.00000000},{"price":3700.10,"qty":2.11000000}],"checksum":2899466156,"timestamp":"2024-05-24T15:54:03.677053Z"}]}
{"channel":"book","type":"update","data":[{"symbol":"ETH/USD","bids":[],"asks":[{"price":3699.57,"qty":27.03017243}],"checksum":3703165219,"timestamp":"2024-05-24T15:54:03.705138Z"}]}
{"channel":"book","type":"update","data":[{"symbol":"BTC/USD","bids":[{"price":68185.1,"qty":0.00000000},{"price":68177.5,"qty":0.03947498}],"asks":[],"checksum":2897760783,"timestamp":"2024-05-24T15:54:03.708887Z"}]}
{"channel":"book","type":"update","data":[{"symbol":"BTC/USD","bids":[{"price":68183.5,"qty":1.46662944}],"asks":[],"checksum":526885883,"timestamp":"2024-05-24T15:54:03.712777Z"}]}
{"channel":"book","type":"update","data":[{"symbol":"BTC/USD","bids":[{"price":68184.8,"qty":1.46660112}],"asks":[],"checksum":1585959069,"timestamp":"2024-05-24T15:54:03.712791Z"}]}
{"channel":"book","type":"update","data":[{"symbol":"BTC/USD","bids":[{"price":68184.8,"qty":0.00000000},{"price":68178.8,"qty":0.11607238}],"asks":[],"checksum":526885883,"timestamp":"2024-05-24T15:54:03.723633Z"}]}
{"channel":"book","type":"update","data":[{"symbol":"BTC/USD","bids":[{"price":68184.8,"qty":1.46660112}],"asks":[],"checksum":1585959069,"timestamp":"2024-05-24T15:54:03.764909Z"}]}
{"channel":"book","type":"update","data":[{"symbol":"ETH/USD","bids":[],"asks":[{"price":3699.30,"qty":27.03215417}],"checksum":4015740745,"timestamp":"2024-05-24T15:54:03.805150Z"}]}
{"channel":"book","type":"update","data":[{"symbol":"BTC/USD","bids":[{"price":68184.9,"qty":0.00247852}],"asks":[],"checksum":2204753694,"timestamp":"2024-05-24T15:54:03.819668Z"}]}
{"channel":"book","type":"update","data":[{"symbol":"ETH/USD","bids":[],"asks":[{"price":3699.30,"qty":0.00000000},{"price":3700.01,"qty":3.18750000}],"checksum":3703165219,"timestamp":"2024-05-24T15:54:03.824884Z"}]}
{"channel":"book","type":"update","data":[{"symbol":"BTC/USD","bids":[{"price":68184.9,"qty":0.00000000},{"price":68179.4,"qty":0.33750000}],"asks":[],"checksum":1585959069,"timestamp":"2024-05-24T15:54:03.825618Z"}]}
{"channel":"book","type":"update","data":[{"symbol":"ETH/USD","bids":[{"price":3698.60,"qty":2.11000000}],"asks":[],"checksum":3316286011,"timestamp":"2024-05-24T15:54:03.827297Z"}]}
{"channel":"book","type":"update","data":[{"symbol":"BTC/USD","bids":[{"price":68184.8,"qty":0.00000000},{"price":68178.8,"qty":0.11607238}],"asks":[],"checksum":526885883,"timestamp":"2024-05-24T15:54:03.828643Z"}]}
{"channel":"book","type":"update","data":[{"symbol":"ETH/USD","bids":[{"price":3698.60,"qty":0.00000000},{"price":3697.82,"qty":1.53600000}],"asks":[],"checksum":2911648558,"timestamp":"2024-05-24T15:54:03.830230Z"}]}
{"channel":"book","type":"update","data":[{"symbol":"ETH/USD","bids":[],"asks":[{"price":3699.81,"qty":0.00000000},{"price":3700.10,"qty":2.11000000}],"checksum":2946628927,"timestamp":"2024-05-24T15:54:03.831680Z"}]}
{"channel":"book","type":"update","data":[{"symbol":"BTC/USD","bids":[{"price":68184.5,"qty":1.46660743}],"asks":[],"checksum":1478712490,"timestamp":"2024-05-24T15:54:03.832579Z"}]}
{"channel":"book","type":"update","data":[{"symbol":"ETH/USD","bids":[],"asks":[{"price":3699.22,"qty":27.03277763}],"checksum":2634196485,"timestamp":"2024-05-24T15:54:03.876221Z"}]}
{"channel":"book","type":"update","data":[{"symbol":"ETH/USD","bids":[],"asks":[{"price":3699.22,"qty":0.00000000},{"price":3700.10,"qty":2.11000000}],"checksum":2946628927,"timestamp":"2024-05-24T15:54:03.879436Z"}]}
{"channel":"book","type":"update","data":[{"symbol":"ETH/USD","bids":[],"asks":[{"price":3699.97,"qty":0.18297271}],"checksum":97996741,"timestamp":"2024-05-24T15:54:03.885945Z"}]}
{"channel":"book","type":"update","data":[{"symbol":"ETH/USD","bids":[],"asks":[{"price":3699.23,"qty":27.03268571}],"checksum":2258621881,"timestamp":"2024-05-24T15:54:03.942490Z"}]}
{"channel":"book","type":"update","data":[{"symbol":"ETH/USD","bids":[{"price":3698.60,"qty":27.03719829}],"asks":[],"checksum":4291506693,"timestamp":"2024-05-24T15:54:03.942635Z"}]}
{"channel":"book","type":"update","data":[{"symbol":"BTC/USD","bids":[{"price":68184.5,"qty":0.00000000},{"price":68178.8,"qty":0.11607238}],"asks":[],"checksum":526885883,"timestamp":"2024-05-24T15:54:03.976549Z"}]}
{"channel":"book","type":"update","data":[{"symbol":"BTC/USD","bids":[{"price":68184.8,"qty":1.46660112}],"asks":[],"checksum":1585959069,"timestamp":"2024-05-24T15:54:03.980133Z"}]}
{"channel":"book","type":"update","data":[{"symbol":"ETH/USD","bids":[],"asks":[{"price":3699.97,"qty":0.00000000},{"price":3700.10,"qty":2.11000000},{"price":3699.56,"qty":0.18297271}],"checksum":3440765346,"timestamp":"2024-05-24T15:54:04.028508Z"}]}
{"channel":"book","type":"update","data":[{"symbol":"ETH/USD","bids":[],"asks":[{"price":3699.23,"qty":0.00000000},{"price":3700.10,"qty":2.11000000}],"checksum":3152818024,"timestamp":"2024-05-24T15:54:04.036900Z"}]}
{"channel":"book","type":"update","data":[{"symbol":"ETH/USD","bids":[],"asks":[{"price":3699.25,"qty":27.03257757}],"checksum":4254510480,"timestamp":"2024-05-24T15:54:04.040941Z"}]}
{"channel":"book","type":"update","data":[{"symbol":"ETH/USD","bids":[],"asks":[{"price":3699.45,"qty":27.03106017}],"checksum":2726356045,"timestamp":"2024-05-24T15:54:04.041095Z"}]}
{"channel":"book","type":"update","data":[{"symbol":"ETH/USD","bids":[],"asks":[{"price":3699.56,"qty":0.00000000},{"price":3700.01,"qty":3.18750000}],"checksum":1956636974,"timestamp":"2024-05-24T15:54:04.044362Z"}]}
{"channel":"book","type":"update","data":[{"symbol":"ETH/USD","bids":[{"price":3698.41,"qty":2.11000000}],"asks":[],"checksum":1333424070,"timestamp":"2024-05-24T15:54:04.053792Z"}]}
{"channel":"book","type":"update","data":[{"symbol":"BTC/USD","bids":[{"price":68184.8,"qty":0.00000000},{"price":68178.8,"qty":0.30687238}],"asks":[],"checksum":3410355443,"timestamp":"2024-05-24T15:54:04.058544Z"}]}
{"channel":"book","type":"update","data":[{"symbol":"BTC/USD","bids":[{"price":68185.1,"qty":1.46659496}],"asks":[],"checksum":2805004186,"timestamp":"2024-05-24T15:54:04.062397Z"}]}
{"channel":"book","type":"update","data":[{"symbol":"ETH/USD","bids":[],"asks":[{"price":3699.64,"qty":0.00000000},{"price":3700.09,"qty":0.18297271}],"checksum":942812992,"timestamp":"2024-05-24T15:54:04.062804Z"}]}
{"channel":"book","type":"update","data":[{"symbol":"ETH/USD","bids":[],"asks":[{"price":3699.57,"qty":0.00000000},{"price":3700.10,"qty":2.11000000}],"checksum":2873475656,"timestamp":"2024-05-24T15:54:04.066170Z"}]}
{"channel":"book","type":"update","data":[{"symbol":"ETH/USD","bids":[],"asks":[{"price":3699.71,"qty":27.02916238}],"checksum":3635876024,"timestamp":"2024-05-24T15:54:04.069929Z"}]}
{"channel":"book","type":"update","data":[{"symbol":"BTC/USD","bids":[{"price":68183.5,"qty":0.00000000},{"price":68178.8,"qty":0.30687238}],"asks":[],"checksum":427921663,"timestamp":"2024-05-24T15:54:04.072541Z"}]}
{"channel":"book","type":"update","data":[{"symbol":"ETH/USD","bids":[],"asks":[{"price":3699.25,"qty":0.00000000},{"price":3700.10,"qty":2.11000000}],"checksum":3257325805,"timestamp":"2024-05-24T15:54:04.072770Z"}]}
{"channel":"book","type":"update","data":[{"symbol":"ETH/USD","bids":[{"price":3698.89,"qty":58.25282382}],"asks":[],"checksum":3741069953,"timestamp":"2024-05-24T15:54:04.118302Z"}]}
{"channel":"book","type":"update","data":[{"symbol":"ETH/USD","bids":[],"asks":[{"price":3699.29,"qty":0.39579387}],"checksum":453377625,"timestamp":"2024-05-24T15:54:04.123383Z"}]}
{"channel":"book","type":"update","data":[{"symbol":"ETH/USD","bids":[],"asks":[{"price":3699.66,"qty":1.62210606}],"checksum":2405069417,"timestamp":"2024-05-24T15:54:04.126307Z"}]}
{"channel":"book","type":"update","data":[{"symbol":"BTC/USD","bids":[{"price":68185.6,"qty":1.46658455}],"asks":[],"checksum":3248747047,"timestamp":"2024-05-24T15:54:04.154420Z"}]}
{"channel":"book","type":"update","data":[{"symbol":"ETH/USD","bids":[],"asks":[{"price":3699.32,"qty":27.03202878}],"checksum":2577455126,"timestamp":"2024-05-24T15:54:04.154730Z"}]}
{"channel":"book","type":"update","data":[{"symbol":"ETH/USD","bids":[],"asks":[{"price":3699.45,"qty":0.00000000},{"price":3700.01,"qty":3.18750000}],"checksum":366136376,"timestamp":"2024-05-24T15:54:04.170113Z"}]}
{"channel":"book","type":"update","data":[{"symbol":"BTC/USD","bids":[{"price":68185.6,"qty":0.00000000},{"price":68178.8,"qty":0.30687238}],"asks":[],"checksum":427921663,"timestamp":"2024-05-24T15:54:04.180754Z"}]}
{"channel":"book","type":"update","data":[{"symbol":"ETH/USD","bids":[{"price":3698.77,"qty":0.00000000},{"price":3698.16,"qty":0.75856873}],"asks":[],"checksum":3588788300,"timestamp":"2024-05-24T15:54:04.186883Z"}]}
{"channel":"book","type":"update","data":[{"symbol":"ETH/USD","bids":[],"asks":[{"price":3699.32,"qty":0.00000000},{"price":3700.09,"qty":0.18297271}],"checksum":2345576707,"timestamp":"2024-05-24T15:54:04.187013Z"}]}
{"channel":"book","type":"update","data":[{"symbol":"ETH/USD","bids":[{"price":3698.89,"qty":85.28796138}],"asks":[],"checksum":3464604494,"timestamp":"2024-05-24T15:54:04.191263Z"}]}
{"channel":"book","type":"update","data":[{"symbol":"ETH/USD","bids":[],"asks":[{"price":3699.41,"qty":27.03135469}],"checksum":3678805421,"timestamp":"2024-05-24T15:54:04.191442Z"}]}
{"channel":"book","type":"update","data":[{"symbol":"BTC/USD","bids":[{"price":68185.1,"qty":0.00000000},{"price":68177.9,"qty":1.46674912}],"asks":[],"checksum":1842311830,"timestamp":"2024-05-24T15:54:04.222264Z"}]}
{"channel":"book","type":"update","data":[{"symbol":"BTC/USD","bids":[{"price":68181.1,"qty":0.00000000},{"price":68177.5,"qty":0.03947498}],"asks":[],"checksum":3127513981,"timestamp":"2024-05-24T15:54:04.222315Z"}]}
{"channel":"book","type":"update","data":[{"symbol":"BTC/USD","bids":[{"price":68186.4,"qty":1.46656763}],"asks":[],"checksum":1740175871,"timestamp":"2024-05-24T15:54:04.222356Z"}]}
{"channel":"book","type":"update","data":[{"symbol":"ETH/USD","bids":[],"asks":[{"price":3699.38,"qty":31.08663866}],"checksum":4158134269,"timestamp":"2024-05-24T15:54:04.225442Z"}]}
{"channel":"book","type":"update","data":[{"symbol":"ETH/USD","bids":[{"price":3698.60,"qty":0.00000000},{"price":3697.83,"qty":0.18337414}],"asks":[],"checksum":1597022860,"timestamp":"2024-05-24T15:54:04.225587Z"}]}
{"channel":"book","type":"update","data":[{"symbol":"BTC/USD","bids":[{"price":68182.9,"qty":1.46664128}],"asks":[],"checksum":844518907,"timestamp":"2024-05-24T15:54:04.226888Z"}]}
{"channel":"book","type":"update","data":[{"symbol":"ETH/USD","bids":[],"asks":[{"price":3699.38,"qty":4.05504042}],"checksum":2032427874,"timestamp":"2024-05-24T15:54:04.230134Z"}]}
{"channel":"book","type":"update","data":[{"symbol":"BTC/USD","bids":[{"price":68186.0,"qty":0.04828856}],"asks":[],"checksum":4238590333,"timestamp":"2024-05-24T15:54:04.231811Z"}]}
{"channel":"book","type":"update","data":[{"symbol":"BTC/USD","bids":[{"price":68187.2,"qty":1.46654989}],"asks":[],"checksum":414853935,"timestamp":"2024-05-24T15:54:04.272657Z"}]}
{"channel":"book","type":"update","data":[{"symbol":"ETH/USD","bids":[],"asks":[{"price":3699.41,"qty":0.00000000},{"price":3700.09,"qty":0.18297271}],"checksum":1436441202,"timestamp":"2024-05-24T15:54:04.273721Z"}]}
{"channel":"book","type":"update","data":[{"symbol":"BTC/USD","bids":[{"price":68187.2,"qty":0.00000000},{"price":68179.4,"qty":0.33750000}],"asks":[],"checksum":4238590333,"timestamp":"2024-05-24T15:54:04.276362Z"}]}
{"channel":"book","type":"update","data":[{"symbol":"ETH/USD","bids":[],"asks":[{"price":3699.43,"qty":27.03124439}],"checksum":4052943270,"timestamp":"2024-05-24T15:54:04.277024Z"}]}
{"channel":"book","type":"update","data":[{"symbol":"ETH/USD","bids":[],"asks":[{"price":3699.43,"qty":0.00000000},{"price":3700.09,"qty":0.18297271}],"checksum":1436441202,"timestamp":"2024-05-24T15:54:04.304058Z"}]}
{"channel":"book","type":"update","data":[{"symbol":"BTC/USD","bids":[{"price":68186.4,"qty":0.00000000},{"price":68178.8,"qty":0.30687238}],"asks":[],"checksum":2287367802,"timestamp":"2024-05-24T15:54:04.310137Z"}]}
{"channel":"book","type":"update","data":[{"symbol":"BTC/USD","bids":[{"price":68188.4,"qty":1.46652378}],"asks":[],"checksum":2551995137,"timestamp":"2024-05-24T15:54:04.333990Z"}]}
{"channel":"book","type":"update","data":[{"symbol":"BTC/USD","bids":[{"price":68182.9,"qty":0.00000000},{"price":68178.8,"qty":0.30687238}],"asks":[],"checksum":2214711276,"timestamp":"2024-05-24T15:54:04.351029Z"}]}
{"channel":"book","type":"update","data":[{"symbol":"BTC/USD","bids":[{"price":68188.4,"qty":0.00000000},{"price":68177.9,"qty":1.46674912}],"asks":[],"checksum":3719879294,"timestamp":"2024-05-24T15:54:04.351075Z"}]}
{"channel":"book","type":"update","data":[{"symbol":"ETH/USD","bids":[],"asks":[{"price":3699.45,"qty":27.03109337}],"checksum":1233860535,"timestamp":"2024-05-24T15:54:04.352977Z"}]}
{"channel":"book","type":"update","data":[{"symbol":"ETH/USD","bids":[],"asks":[{"price":3699.54,"qty":27.03045252}],"checksum":2801320520,"timestamp":"2024-05-24T15:54:04.353029Z"}]}
{"channel":"book","type":"update","data":[{"symbol":"ETH/USD","bids":[],"asks":[{"price":3699.45,"qty":0.00000000},{"price":3700.01,"qty":3.18750000}],"checksum":2339147466,"timestamp":"2024-05-24T15:54:04.356466Z"}]}
{"channel":"book","type":"update","data":[{"symbol":"ETH/USD","bids":[],"asks":[{"price":3700.01,"qty":3.58840422}],"checksum":492484295,"timestamp":"2024-05-24T15:54:04.376333Z"}]}
{"channel":"book","type":"update","data":[{"symbol":"BTC/USD","bids":[],"asks":[{"price":68207.1,"qty":0.00000000},{"price":68212.0,"qty":0.05495233}],"checksum":1881056944,"timestamp":"2024-05-24T15:54:04.391951Z"}]}
{"channel":"book","type":"update","data":[{"symbol":"BTC/USD","bids":[],"asks":[{"price":68207.1,"qty":0.33750000}],"checksum":3719879294,"timestamp":"2024-05-24T15:54:04.396625Z"}]}
{"channel":"book","type":"update","data":[{"symbol":"ETH/USD","bids":[],"asks":[{"price":3699.50,"qty":27.03074928}],"checksum":3770489279,"timestamp":"2024-05-24T15:54:04.402569Z"}]}
{"channel":"book","type":"update","data":[{"symbol":"ETH/USD","bids":[],"asks":[{"price":3699.50,"qty":0.00000000},{"price":3700.01,"qty":3.58840422}],"checksum":492484295,"timestamp":"2024-05-24T15:54:04.406296Z"}]}
{"channel":"book","type":"update","data":[{"symbol":"BTC/USD","bids":[],"asks":[{"price":68207.1,"qty":0.00000000},{"price":68212.0,"qty":0.05495233}],"checksum":1881056944,"timestamp":"2024-05-24T15:54:04.459451Z"}]}
{"channel":"book","type":"update","data":[{"symbol":"BTC/USD","bids":[{"price":68194.6,"qty":0.01353482}],"asks":[],"checksum":2578162076,"timestamp":"2024-05-24T15:54:04.460651Z"}]}
{"channel":"book","type":"update","data":[{"symbol":"ETH/USD","bids":[],"asks":[{"price":3699.49,"qty":27.03079944}],"checksum":2054765919,"timestamp":"2024-05-24T15:54:04.465489Z"}]}
{"channel":"book","type":"update","data":[{"symbol":"ETH/USD","bids":[{"price":3698.73,"qty":27.03625323}],"asks":[],"checksum":151631776,"timestamp":"2024-05-24T15:54:04.465532Z"}]}
{"channel":"book","type":"update","data":[{"symbol":"BTC/USD","bids":[{"price":68194.6,"qty":0.00000000},{"price":68177.9,"qty":1.46674912}],"asks":[],"checksum":1881056944,"timestamp":"2024-05-24T15:54:04.470536Z"}]}
{"channel":"book","type":"update","data":[{"symbol":"BTC/USD","bids":[{"price":68192.2,"qty":0.01353482}],"asks":[],"checksum":3481612943,"timestamp":"2024-05-24T15:54:04.473526Z"}]}
{"channel":"book","type":"update","data":[{"symbol":"ETH/USD","bids":[],"asks":[{"price":3699.29,"qty":0.00000000},{"price":3700.01,"qty":3.58840422}],"checksum":2657623415,"timestamp":"2024-05-24T15:54:04.476215Z"}]}
{"channel":"book","type":"update","data":[{"symbol":"BTC/USD","bids":[{"price":68188.4,"qty":1.46652329}],"asks":[],"checksum":2140765496,"timestamp":"2024-05-24T15:54:04.478299Z"}]}
{"channel":"book","type":"update","data":[{"symbol":"BTC/USD","bids":[{"price":68188.4,"qty":0.00000000},{"price":68178.8,"qty":0.30687238}],"asks":[],"checksum":3481612943,"timestamp":"2024-05-24T15:54:04.487873Z"}]}
{"channel":"book","type":"update","data":[{"symbol":"BTC/USD","bids":[{"price":68187.6,"qty":1.46654083}],"asks":[],"checksum":1230320798,"timestamp":"2024-05-24T15:54:04.498571Z"}]}
{"channel":"book","type":"update","data":[{"symbol":"BTC/USD","bids":[{"price":68200.1,"qty":12.29925600}],"asks":[],"checksum":1931147450,"timestamp":"2024-05-24T15:54:04.499133Z"}]}
{"channel":"book","type":"update","data":[{"symbol":"BTC/USD","bids":[{"price":68200.1,"qty":12.61125600}],"asks":[],"checksum":543915955,"timestamp":"2024-05-24T15:54:04.503238Z"}]}
{"channel":"book","type":"update","data":[{"symbol":"BTC/USD","bids":[{"price":68200.1,"qty":12.92225600}],"asks":[],"checksum":1839867333,"timestamp":"2024-05-24T15:54:04.504765Z"}]}
{"channel":"book","type":"update","data":[{"symbol":"BTC/USD","bids":[{"price":68200.1,"qty":13.22225600}],"asks":[],"checksum":2244165726,"timestamp":"2024-05-24T15:54:04.505405Z"}]}
{"channel":"book","type":"update","data":[{"symbol":"BTC/USD","bids":[{"price":68190.7,"qty":0.01353482}],"asks":[],"checksum":1986443884,"timestamp":"2024-05-24T15:54:04.506100Z"}]}
{"channel":"book","type":"update","data":[{"symbol":"BTC/USD","bids":[{"price":68200.1,"qty":13.52225600}],"asks":[],"checksum":1089638777,"timestamp":"2024-05-24T15:54:04.506161Z"}]}
{"channel":"book","type":"update","data":[{"symbol":"ETH/USD","bids":[],"asks":[{"price":3699.60,"qty":0.00000000},{"price":3700.09,"qty":0.18297271}],"checksum":3208917053,"timestamp":"2024-05-24T15:54:04.506924Z"}]}
{"channel":"book","type":"update","data":[{"symbol":"ETH/USD","bids":[],"asks":[{"price":3700.01,"qty":0.40090422}],"checksum":2607641360,"timestamp":"2024-05-24T15:54:04.506995Z"}]}
{"channel":"book","type":"update","data":[{"symbol":"ETH/USD","bids":[],"asks":[{"price":3699.49,"qty":0.00000000},{"price":3700.10,"qty":2.11000000}],"checksum":787374419,"timestamp":"2024-05-24T15:54:04.507888Z"}]}
{"channel":"book","type":"update","data":[{"symbol":"BTC/USD","bids":[],"asks":[{"price":68209.9,"qty":0.19080000}],"checksum":801735190,"timestamp":"2024-05-24T15:54:04.508013Z"}]}
{"channel":"book","type":"update","data":[{"symbol":"BTC/USD","bids":[{"price":68192.2,"qty":0.00000000},{"price":68179.4,"qty":0.33750000}],"asks":[],"checksum":606447976,"timestamp":"2024-05-24T15:54:04.509091Z"}]}
{"channel":"book","type":"update","data":[{"symbol":"BTC/USD","bids":[{"price":68200.1,"qty":13.82225600}],"asks":[],"checksum":202472197,"timestamp":"2024-05-24T15:54:04.510079Z"}]}
{"channel":"book","type":"update","data":[{"symbol":"ETH/USD","bids":[],"asks":[{"price":3699.38,"qty":0.00000000},{"price":3700.11,"qty":0.39579387}],"checksum":3272534787,"timestamp":"2024-05-24T15:54:04.512824Z"}]}
{"channel":"book","type":"update","data":[{"symbol":"ETH/USD","bids":[],"asks":[{"price":3699.84,"qty":4.05504042}],"checksum":2566055533,"timestamp":"2024-05-24T15:54:04.516595Z"}]}
{"channel":"book","type":"update","data":[{"symbol":"ETH/USD","bids":[{"price":3698.89,"qty":88.47546138}],"asks":[],"checksum":2794339417,"timestamp":"2024-05-24T15:54:04.520928Z"}]}
{"channel":"book","type":"update","data":[{"symbol":"BTC/USD","bids":[],"asks":[{"price":68209.9,"qty":0.00000000},{"price":68212.6,"qty":0.21994086}],"checksum":119218721,"timestamp":"2024-05-24T15:54:04.521417Z"}]}
{"channel":"book","type":"update","data":[{"symbol":"ETH/USD","bids":[],"asks":[{"price":3699.55,"qty":27.03031646}],"checksum":1169638277,"timestamp":"2024-05-24T15:54:04.522284Z"}]}
{"channel":"book","type":"update","data":[{"symbol":"BTC/USD","bids":[{"price":68186.4,"qty":0.91217870}],"asks":[],"checksum":3606162858,"timestamp":"2024-05-24T15:54:04.525726Z"}]}
{"channel":"book","type":"update","data":[{"symbol":"BTC/USD","bids":[{"price":68188.5,"qty":1.46652292}],"asks":[],"checksum":1291917277,"timestamp":"2024-05-24T15:54:04.527070Z"}]}
{"channel":"book","type":"update","data":[{"symbol":"ETH/USD","bids":[],"asks":[{"price":3700.01,"qty":3.58840422}],"checksum":537517981,"timestamp":"2024-05-24T15:54:04.528687Z"}]}
{"channel":"book","type":"update","data":[{"symbol":"BTC/USD","bids":[{"price":68200.1,"qty":13.85158147}],"asks":[],"checksum":1266559913,"timestamp":"2024-05-24T15:54:04.529167Z"}]}
{"channel":"book","type":"update","data":[{"symbol":"BTC/USD","bids":[{"price":68184.6,"qty":1.46660573}],"asks":[],"checksum":2653615108,"timestamp":"2024-05-24T15:54:04.532479Z"}]}
{"channel":"book","type":"update","data":[{"symbol":"ETH/USD","bids":[{"price":3698.73,"qty":0.00000000},{"price":3697.83,"qty":0.18337414}],"asks":[],"checksum":226924726,"timestamp":"2024-05-24T15:54:04.532790Z"}]}
{"channel":"book","type":"update","data":[{"symbol":"ETH/USD","bids":[],"asks":[{"price":3699.55,"qty":0.00000000},{"price":3700.10,"qty":2.11000000}],"checksum":2987612623,"timestamp":"2024-05-24T15:54:04.532971Z"}]}
{"channel":"book","type":"update","data":[{"symbol":"ETH/USD","bids":[],"asks":[{"price":3699.54,"qty":0.00000000},{"price":3700.11,"qty":0.39579387}],"checksum":3006972804,"timestamp":"2024-05-24T15:54:04.533053Z"}]}
{"channel":"book","type":"update","data":[{"symbol":"ETH/USD","bids":[],"asks":[{"price":3700.01,"qty":0.40090422}],"checksum":4283828519,"timestamp":"2024-05-24T15:54:04.536182Z"}]}
{"channel":"book","type":"update","data":[{"symbol":"ETH/USD","bids":[],"asks":[{"price":3699.66,"qty":0.00000000},{"price":3700.33,"qty":0.55000000}],"checksum":280308257,"timestamp":"2024-05-24T15:54:04.538238Z"}]}
{"channel":"book","type":"update","data":[{"symbol":"BTC/USD","bids":[{"price":68187.6,"qty":0.00000000},{"price":68183.0,"qty":0.01353482}],"asks":[],"checksum":3196122368,"timestamp":"2024-05-24T15:54:04.541967Z"}]}
{"channel":"book","type":"update","data":[{"symbol":"BTC/USD","bids":[{"price":68188.5,"qty":0.00000000},{"price":68180.0,"qty":0.15000000}],"asks":[],"checksum":4179052135,"timestamp":"2024-05-24T15:54:04.541977Z"}]}
{"channel":"book","type":"update","data":[{"symbol":"ETH/USD","bids":[],"asks":[{"price":3699.64,"qty":27.02971912}],"checksum":921820015,"timestamp":"2024-05-24T15:54:04.542366Z"}]}
{"channel":"book","type":"update","data":[{"symbol":"ETH/USD","bids":[],"asks":[{"price":3699.71,"qty":0.00000000},{"price":3700.33,"qty":0.55000000}],"checksum":2989964576,"timestamp":"2024-05-24T15:54:04.548137Z"}]}
{"channel":"book","type":"update","data":[{"symbol":"ETH/USD","bids":[{"price":3698.41,"qty":0.00000000},{"price":3697.82,"qty":1.53600000},{"price":3698.71,"qty":2.11000000}],"asks":[],"checksum":3228907397,"timestamp":"2024-05-24T15:54:04.551271Z"}]}
{"channel":"book","type":"update","data":[{"symbol":"ETH/USD","bids":[{"price":3698.04,"qty":27.04128923}],"asks":[],"checksum":3055034239,"timestamp":"2024-05-24T15:54:04.552370Z"}]}
{"channel":"book","type":"update","data":[{"symbol":"ETH/USD","bids":[{"price":3698.71,"qty":4.22000000}],"asks":[],"checksum":1883483857,"timestamp":"2024-05-24T15:54:04.554311Z"}]}
{"channel":"book","type":"update","data":[{"symbol":"BTC/USD","bids":[{"price":68184.6,"qty":0.00000000},{"price":68179.4,"qty":0.33750000}],"asks":[],"checksum":2534293572,"timestamp":"2024-05-24T15:54:04.557954Z"}]}
{"channel":"book","type":"update","data":[{"symbol":"BTC/USD","bids":[],"asks":[{"price":68202.0,"qty":0.00000000},{"price":68212.9,"qty":0.31505019}],"checksum":3377924673,"timestamp":"2024-05-24T15:54:04.563763Z"}]}
{"channel":"book","type":"update","data":[{"symbol":"BTC/USD","bids":[{"price":68185.2,"qty":0.19080000}],"asks":[],"checksum":2160238677,"timestamp":"2024-05-24T15:54:04.564337Z"}]}
{"channel":"book","type":"update","data":[{"symbol":"BTC/USD","bids":[],"asks":[{"price":68200.2,"qty":3.13772032}],"checksum":872965774,"timestamp":"2024-05-24T15:54:04.567054Z"}]}
{"channel":"book","type":"update","data":[{"symbol":"BTC/USD","bids":[{"price":68185.2,"qty":0.38160000}],"asks":[],"checksum":1580256454,"timestamp":"2024-05-24T15:54:04.567236Z"}]}
{"channel":"book","type":"update","data":[{"symbol":"BTC/USD","bids":[{"price":68193.2,"qty":0.33750000}],"asks":[],"checksum":690985353,"timestamp":"2024-05-24T15:54:04.567728Z"}]}
{"channel":"book","type":"update","data":[{"symbol":"BTC/USD","bids":[],"asks":[{"price":68206.0,"qty":0.17890000}],"checksum":2721987754,"timestamp":"2024-05-24T15:54:04.571075Z"}]}
{"channel":"book","type":"update","data":[{"symbol":"BTC/USD","bids":[{"price":68199.0,"qty":0.00750000}],"asks":[],"checksum":1491202475,"timestamp":"2024-05-24T15:54:04.571169Z"}]}
{"channel":"book","type":"update","data":[{"symbol":"ETH/USD","bids":[],"asks":[{"price":3700.03,"qty":27.02684728}],"checksum":619026735,"timestamp":"2024-05-24T15:54:04.587929Z"}]}
{"channel":"book","type":"update","data":[{"symbol":"ETH/USD","bids":[],"asks":[{"price":3699.59,"qty":27.03003701}],"checksum":2745723539,"timestamp":"2024-05-24T15:54:04.588008Z"}]}
{"channel":"book","type":"update","data":[{"symbol":"ETH/USD","bids":[],"asks":[{"price":3699.59,"qty":0.00000000},{"price":3700.11,"qty":0.39579387}],"checksum":619026735,"timestamp":"2024-05-24T15:54:04.594157Z"}]}
{"channel":"book","type":"update","data":[{"symbol":"BTC/USD","bids":[{"price":68190.1,"qty":1.46648692}],"asks":[],"checksum":3211936473,"timestamp":"2024-05-24T15:54:04.603999Z"}]}
{"channel":"book","type":"update","data":[{"symbol":"BTC/USD","bids":[],"asks":[{"price":68200.2,"qty":3.07575032}],"checksum":3477067196,"timestamp":"2024-05-24T15:54:04.604848Z"}]}
{"channel":"book","type":"update","data":[{"symbol":"ETH/USD","bids":[],"asks":[{"price":3699.71,"qty":1.53600000}],"checksum":1644024018,"timestamp":"2024-05-24T15:54:04.605484Z"}]}
{"channel":"book","type":"update","data":[{"symbol":"ETH/USD","bids":[],"asks":[{"price":3700.01,"qty":3.58840422}],"checksum":3762638201,"timestamp":"2024-05-24T15:54:04.610871Z"}]}
{"channel":"book","type":"update","data":[{"symbol":"ETH/USD","bids":[],"asks":[{"price":3699.54,"qty":27.03039924}],"checksum":1109981698,"timestamp":"2024-05-24T15:54:04.655673Z"}]}
{"channel":"book","type":"update","data":[{"symbol":"ETH/USD","bids":[],"asks":[{"price":3699.82,"qty":27.02837480}],"checksum":144575111,"timestamp":"2024-05-24T15:54:04.655785Z"}]}
{"channel":"book","type":"update","data":[{"symbol":"ETH/USD","bids":[{"price":3698.89,"qty":85.28796138}],"asks":[],"checksum":920834227,"timestamp":"2024-05-24T15:54:04.659135Z"}]}
{"channel":"book","type":"update","data":[{"symbol":"ETH/USD","bids":[],"asks":[{"price":3699.64,"qty":0.00000000},{"price":3700.09,"qty":0.18297271}],"checksum":2091764250,"timestamp":"2024-05-24T15:54:04.662374Z"}]}
{"channel":"book","type":"update","data":[{"symbol":"ETH/USD","bids":[],"asks":[{"price":3699.54,"qty":0.00000000},{"price":3700.10,"qty":2.11000000}],"checksum":1402726684,"timestamp":"2024-05-24T15:54:04.662582Z"}]}
{"channel":"book","type":"update","data":[{"symbol":"ETH/BTC","bids":[{"price":0.05422,"qty":15.58466983}],"asks":[],"checksum":2375871298,"timestamp":"2024-05-24T15:54:04.668652Z"}]}
{"channel":"book","type":"update","data":[{"symbol":"BTC/USD","bids":[{"price":68190.1,"qty":0.00000000},{"price":68183.4,"qty":0.00035492}],"asks":[],"checksum":2989458132,"timestamp":"2024-05-24T15:54:04.718383Z"}]}
{"channel":"book","type":"update","data":[{"symbol":"ETH/USD","bids":[],"asks":[{"price":3699.55,"qty":27.03031814}],"checksum":1645935299,"timestamp":"2024-05-24T15:54:04.720988Z"}]}
{"channel":"book","type":"update","data":[{"symbol":"BTC/USD","bids":[{"price":68189.0,"qty":1.46651162}],"asks":[],"checksum":1469612278,"timestamp":"2024-05-24T15:54:04.722196Z"}]}
{"channel":"book","type":"update","data":[{"symbol":"BTC/USD","bids":[{"price":68190.3,"qty":1.46648305}],"asks":[],"checksum":1369295470,"timestamp":"2024-05-24T15:54:04.722301Z"}]}
{"channel":"book","type":"update","data":[{"symbol":"BTC/USD","bids":[{"price":68190.3,"qty":0.00000000},{"price":68185.2,"qty":0.38160000}],"asks":[],"checksum":1469612278,"timestamp":"2024-05-24T15:54:04.729137Z"}]}
{"channel":"book","type":"update","data":[{"symbol":"ETH/USD","bids":[],"asks":[{"price":3699.82,"qty":0.00000000},{"price":3700.10,"qty":2.11000000}],"checksum":3244842718,"timestamp":"2024-05-24T15:54:04.730754Z"}]}
{"channel":"book","type":"update","data":[{"symbol":"BTC/USD","bids":[],"asks":[{"price":68200.9,"qty":0.00000000},{"price":68212.9,"qty":0.31505019}],"checksum":2474446226,"timestamp":"2024-05-24T15:54:04.758942Z"}]}
{"channel":"book","type":"update","data":[{"symbol":"BTC/USD","bids":[],"asks":[{"price":68203.5,"qty":1.46620153}],"checksum":3080711889,"timestamp":"2024-05-24T15:54:04.762684Z"}]}
{"channel":"book","type":"update","data":[{"symbol":"ETH/USD","bids":[],"asks":[{"price":3699.49,"qty":27.03075416}],"checksum":4142583157,"timestamp":"2024-05-24T15:54:04.802706Z"}]}
{"channel":"book","type":"update","data":[{"symbol":"ETH/USD","bids":[],"asks":[{"price":3699.49,"qty":0.00000000},{"price":3700.10,"qty":2.11000000}],"checksum":3244842718,"timestamp":"2024-05-24T15:54:04.814009Z"}]}
{"channel":"book","type":"update","data":[{"symbol":"ETH/USD","bids":[],"asks":[{"price":3699.61,"qty":27.02992483}],"checksum":3769850937,"timestamp":"2024-05-24T15:54:04.833233Z"}]}
{"channel":"book","type":"update","data":[{"symbol":"ETH/USD","bids":[{"price":3698.89,"qty":88.47546138}],"asks":[],"checksum":3738142221,"timestamp":"2024-05-24T15:54:04.835205Z"}]}
{"channel":"book","type":"update","data":[{"symbol":"BTC/USD","bids":[],"asks":[{"price":68206.0,"qty":0.00000000},{"price":68212.9,"qty":0.31505019}],"checksum":877952701,"timestamp":"2024-05-24T15:54:04.870505Z"}]}
{"channel":"book","type":"update","data":[{"symbol":"ETH/USD","bids":[{"price":3698.89,"qty":85.28796138}],"asks":[],"checksum":3769850937,"timestamp":"2024-05-24T15:54:04.888498Z"}]}
{"channel":"book","type":"update","data":[{"symbol":"BTC/USD","bids":[{"price":68186.6,"qty":1.46656341}],"asks":[],"checksum":1229744107,"timestamp":"2024-05-24T15:54:04.895929Z"}]}
{"channel":"book","type":"update","data":[{"symbol":"BTC/USD","bids":[{"price":68190.3,"qty":1.46648243}],"asks":[],"checksum":1121210941,"timestamp":"2024-05-24T15:54:04.895945Z"}]}
{"channel":"book","type":"update","data":[{"symbol":"BTC/USD","bids":[{"price":68193.2,"qty":0.00000000},{"price":68186.0,"qty":0.04828856}],"asks":[],"checksum":414437991,"timestamp":"2024-05-24T15:54:04.899896Z"}]}
{"channel":"book","type":"update","data":[{"symbol":"ETH/USD","bids":[],"asks":[{"price":3699.55,"qty":0.00000000},{"price":3700.10,"qty":2.11000000}],"checksum":3538417636,"timestamp":"2024-05-24T15:54:04.912252Z"}]}
{"channel":"book","type":"update","data":[{"symbol":"ETH/USD","bids":[],"asks":[{"price":3699.57,"qty":27.03019196}],"checksum":454160466,"timestamp":"2024-05-24T15:54:04.915788Z"}]}
{"channel":"book","type":"update","data":[{"symbol":"ETH/USD","bids":[],"asks":[{"price":3699.57,"qty":0.00000000},{"price":3700.10,"qty":2.11000000}],"checksum":3538417636,"timestamp":"2024-05-24T15:54:04.938220Z"}]}
{"channel":"book","type":"update","data":[{"symbol":"BTC/USD","bids":[{"price":68190.3,"qty":0.00000000},{"price":68185.2,"qty":0.38160000}],"asks":[],"checksum":1749657767,"timestamp":"2024-05-24T15:54:04.954842Z"}]}
{"channel":"book","type":"update","data":[{"symbol":"BTC/USD","bids":[{"price":68190.5,"qty":1.46647930}],"asks":[],"checksum":2667543700,"timestamp":"2024-05-24T15:54:04.958524Z"}]}
{"channel":"book","type":"update","data":[{"symbol":"ETH/USD","bids":[],"asks":[{"price":3699.70,"qty":27.02925023}],"checksum":4119361701,"timestamp":"2024-05-24T15:54:04.962527Z"}]}
{"channel":"book","type":"update","data":[{"symbol":"ETH/USD","bids":[],"asks":[{"price":3699.55,"qty":27.03032982}],"checksum":4094329286,"timestamp":"2024-05-24T15:54:04.966392Z"}]}
{"channel":"book","type":"update","data":[{"symbol":"ETH/USD","bids":[{"price":3698.88,"qty":27.03516206}],"asks":[],"checksum":784866066,"timestamp":"2024-05-24T15:54:04.966505Z"}]}
{"channel":"book","type":"update","data":[{"symbol":"BTC/USD","bids":[{"price":68193.2,"qty":0.33750000}],"asks":[],"checksum":3215173219,"timestamp":"2024-05-24T15:54:04.982475Z"}]}
{"channel":"book","type":"update","data":[{"symbol":"ETH/USD","bids":[],"asks":[{"price":3699.55,"qty":0.00000000},{"price":3700.09,"qty":0.18297271}],"checksum":793436785,"timestamp":"2024-05-24T15:54:04.992852Z"}]}
{"channel":"book","type":"update","data":[{"symbol":"BTC/USD","bids":[{"price":68190.5,"qty":0.00000000},{"price":68186.0,"qty":0.04828856}],"asks":[],"checksum":1229744107,"timestamp":"2024-05-24T15:54:05.011611Z"}]}
{"channel":"book","type":"update","data":[{"symbol":"BTC/USD","bids":[{"price":68190.6,"qty":1.46647584}],"asks":[],"checksum":2118432426,"timestamp":"2024-05-24T15:54:05.016331Z"}]}
{"channel":"book","type":"update","data":[{"symbol":"BTC/USD","bids":[{"price":68193.2,"qty":0.00000000},{"price":68186.0,"qty":0.04828856}],"asks":[],"checksum":2447834247,"timestamp":"2024-05-24T15:54:05.029970Z"}]}
{"channel":"book","type":"update","data":[{"symbol":"BTC/USD","bids":[{"price":68190.6,"qty":0.00000000},{"price":68185.2,"qty":0.38160000}],"asks":[],"checksum":1749657767,"timestamp":"2024-05-24T15:54:05.035022Z"}]}
{"channel":"book","type":"update","data":[{"symbol":"ETH/USD","bids":[],"asks":[{"price":3699.53,"qty":27.03046498}],"checksum":4200553238,"timestamp":"2024-05-24T15:54:05.041422Z"}]}
{"channel":"book","type":"update","data":[{"symbol":"ETH/USD","bids":[],"asks":[{"price":3699.61,"qty":0.00000000},{"price":3700.09,"qty":0.18297271}],"checksum":2468881339,"timestamp":"2024-05-24T15:54:05.047143Z"}]}
{"channel":"book","type":"update","data":[{"symbol":"ETH/USD","bids":[],"asks":[{"price":3699.53,"qty":0.00000000},{"price":3700.10,"qty":2.11000000}],"checksum":2387026694,"timestamp":"2024-05-24T15:54:05.047311Z"}]}
{"channel":"book","type":"update","data":[{"symbol":"ETH/USD","bids":[],"asks":[{"price":3699.59,"qty":27.03003979}],"checksum":267687471,"timestamp":"2024-05-24T15:54:05.053767Z"}]}
{"channel":"book","type":"update","data":[{"symbol":"ETH/USD","bids":[],"asks":[{"price":3700.09,"qty":0.00000000},{"price":3700.10,"qty":2.11000000},{"price":3699.57,"qty":0.18297273}],"checksum":711730838,"timestamp":"2024-05-24T15:54:05.069189Z"}]}
{"channel":"book","type":"update","data":[{"symbol":"ETH/USD","bids":[{"price":3698.78,"qty":0.00000000},{"price":3698.04,"qty":27.04128923},{"price":3698.05,"qty":0.02662848}],"asks":[],"checksum":4175141743,"timestamp":"2024-05-24T15:54:05.072974Z"}]}
{"channel":"book","type":"update","data":[{"symbol":"ETH/USD","bids":[{"price":3698.89,"qty":95.28796138}],"asks":[],"checksum":129575195,"timestamp":"2024-05-24T15:54:05.104036Z"}]}
{"channel":"book","type":"update","data":[{"symbol":"ETH/USD","bids":[],"asks":[{"price":3699.53,"qty":27.03052985}],"checksum":3919330082,"timestamp":"2024-05-24T15:54:05.109503Z"}]}
{"channel":"book","type":"update","data":[{"symbol":"BTC/USD","bids":[{"price":68190.5,"qty":1.46647892}],"asks":[],"checksum":429423503,"timestamp":"2024-05-24T15:54:05.134746Z"}]}
{"channel":"book","type":"update","data":[{"symbol":"ETH/USD","bids":[],"asks":[{"price":3699.53,"qty":0.00000000},{"price":3700.03,"qty":27.02684728}],"checksum":129575195,"timestamp":"2024-05-24T15:54:05.152909Z"}]}
{"channel":"book","type":"update","data":[{"symbol":"BTC/USD","bids":[{"price":68190.5,"qty":0.00000000},{"price":68185.2,"qty":0.38160000}],"asks":[],"checksum":1749657767,"timestamp":"2024-05-24T15:54:05.154836Z"}]}
{"channel":"book","type":"update","data":[{"symbol":"BTC/USD","bids":[{"price":68193.2,"qty":0.33750000}],"asks":[],"checksum":1229744107,"timestamp":"2024-05-24T15:54:05.174118Z"}]}
{"channel":"book","type":"update","data":[{"symbol":"BTC/USD","bids":[{"price":68193.2,"qty":0.00000000},{"price":68185.2,"qty":0.38160000}],"asks":[],"checksum":1749657767,"timestamp":"2024-05-24T15:54:05.181393Z"}]}
{"channel":"book","type":"update","data":[{"symbol":"ETH/USD","bids":[],"asks":[{"price":3699.50,"qty":27.03074881}],"checksum":3562434742,"timestamp":"2024-05-24T15:54:05.195298Z"}]}
{"channel":"book","type":"update","data":[{"symbol":"ETH/USD","bids":[],"asks":[{"price":3699.59,"qty":0.00000000},{"price":3700.03,"qty":27.02684728}],"checksum":3274825431,"timestamp":"2024-05-24T15:54:05.195670Z"}]}
{"channel":"book","type":"update","data":[{"symbol":"ETH/USD","bids":[],"asks":[{"price":3699.50,"qty":0.00000000},{"price":3700.10,"qty":2.11000000}],"checksum":2652672933,"timestamp":"2024-05-24T15:54:05.220155Z"}]}
{"channel":"book","type":"update","data":[{"symbol":"ETH/USD","bids":[{"price":3698.88,"qty":0.00000000},{"price":3698.04,"qty":27.04128923}],"asks":[],"checksum":846422374,"timestamp":"2024-05-24T15:54:05.226240Z"}]}
{"channel":"book","type":"update","data":[{"symbol":"ETH/USD","bids":[],"asks":[{"price":3700.03,"qty":0.00000000},{"price":3700.11,"qty":0.39579387}],"checksum":2837094015,"timestamp":"2024-05-24T15:54:05.226255Z"}]}
{"channel":"book","type":"update","data":[{"symbol":"ETH/USD","bids":[],"asks":[{"price":3699.88,"qty":27.02793100}],"checksum":25606639,"timestamp":"2024-05-24T15:54:05.230449Z"}]}
{"channel":"book","type":"update","data":[{"symbol":"ETH/USD","bids":[],"asks":[{"price":3699.56,"qty":4.05478830}],"checksum":355761698,"timestamp":"2024-05-24T15:54:05.239002Z"}]}
{"channel":"book","type":"update","data":[{"symbol":"ETH/USD","bids":[],"asks":[{"price":3699.84,"qty":0.00000000},{"price":3700.10,"qty":2.11000000}],"checksum":3016138187,"timestamp":"2024-05-24T15:54:05.241462Z"}]}
{"channel":"book","type":"update","data":[{"symbol":"ETH/USD","bids":[{"price":3698.71,"qty":2.11000000}],"asks":[],"checksum":2604781204,"timestamp":"2024-05-24T15:54:05.243038Z"}]}
{"channel":"book","type":"update","data":[{"symbol":"ETH/USD","bids":[{"price":3698.89,"qty":92.10046138}],"asks":[],"checksum":1722048622,"timestamp":"2024-05-24T15:54:05.257381Z"}]}
{"channel":"book","type":"update","data":[{"symbol":"ETH/USD","bids":[],"asks":[{"price":3699.40,"qty":27.03143605}],"checksum":499209527,"timestamp":"2024-05-24T15:54:05.258103Z"}]}
{"channel":"book","type":"update","data":[{"symbol":"ETH/USD","bids":[],"asks":[{"price":3699.40,"qty":0.00000000},{"price":3700.10,"qty":2.11000000}],"checksum":1722048622,"timestamp":"2024-05-24T15:54:05.262405Z"}]}
{"channel":"book","type":"update","data":[{"symbol":"ETH/USD","bids":[],"asks":[{"price":3699.70,"qty":0.00000000},{"price":3700.11,"qty":0.39579387}],"checksum":901142800,"timestamp":"2024-05-24T15:54:05.262421Z"}]}
{"channel":"book","type":"update","data":[{"symbol":"BTC/USD","bids":[],"asks":[{"price":68207.6,"qty":0.00039232}],"checksum":901360129,"timestamp":"2024-05-24T15:54:05.265371Z"}]}
{"channel":"book","type":"update","data":[{"symbol":"ETH/USD","bids":[],"asks":[{"price":3699.61,"qty":27.02990705}],"checksum":3226151877,"timestamp":"2024-05-24T15:54:05.266085Z"}]}
{"channel":"book","type":"update","data":[{"symbol":"ETH/BTC","bids":[{"price":0.05425,"qty":4.93728080}],"asks":[],"checksum":1170531972,"timestamp":"2024-05-24T15:54:05.266672Z"}]}
{"channel":"book","type":"update","data":[{"symbol":"ETH/USD","bids":[],"asks":[{"price":3699.64,"qty":3.18750000}],"checksum":2875371211,"timestamp":"2024-05-24T15:54:05.268267Z"}]}
{"channel":"book","type":"update","data":[{"symbol":"ETH/BTC","bids":[{"price":0.05425,"qty":5.38728080}],"asks":[],"checksum":2375871298,"timestamp":"2024-05-24T15:54:05.291028Z"}]}
{"channel":"book","type":"update","data":[{"symbol":"ETH/USD","bids":[{"price":3698.04,"qty":0.00000000},{"price":3697.88,"qty":9.83417729}],"asks":[],"checksum":1286298912,"timestamp":"2024-05-24T15:54:05.302982Z"}]}
{"channel":"book","type":"update","data":[{"symbol":"BTC/USD","bids":[{"price":68189.0,"qty":0.00000000},{"price":68183.4,"qty":0.00035492}],"asks":[],"checksum":2774588811,"timestamp":"2024-05-24T15:54:05.307148Z"}]}
{"channel":"book","type":"update","data":[{"symbol":"ETH/USD","bids":[{"price":3698.05,"qty":0.00000000},{"price":3697.84,"qty":4.02610258},{"price":3697.89,"qty":0.02662967}],"asks":[],"checksum":3382488360,"timestamp":"2024-05-24T15:54:05.312125Z"}]}
{"channel":"book","type":"update","data":[{"symbol":"BTC/USD","bids":[{"price":68188.8,"qty":1.46651622}],"asks":[],"checksum":3322704800,"timestamp":"2024-05-24T15:54:05.315660Z"}]}
{"channel":"book","type":"update","data":[{"symbol":"BTC/USD","bids":[{"price":68185.8,"qty":0.02195497}],"asks":[],"checksum":1964131969,"timestamp":"2024-05-24T15:54:05.341114Z"}]}
{"channel":"book","type":"update","data":[{"symbol":"BTC/USD","bids":[{"price":68186.6,"qty":0.00000000},{"price":68185.2,"qty":0.38160000}],"asks":[],"checksum":3458689848,"timestamp":"2024-05-24T15:54:05.352324Z"}]}
{"channel":"book","type":"update","data":[{"symbol":"ETH/USD","bids":[],"asks":[{"price":3699.36,"qty":27.03173651}],"checksum":1141612329,"timestamp":"2024-05-24T15:54:05.355111Z"}]}
{"channel":"book","type":"update","data":[{"symbol":"ETH/USD","bids":[],"asks":[{"price":3699.36,"qty":0.00000000},{"price":3700.01,"qty":3.58840422}],"checksum":3382488360,"timestamp":"2024-05-24T15:54:05.363443Z"}]}
{"channel":"book","type":"update","data":[{"symbol":"ETH/BTC","bids":[{"price":0.05425,"qty":4.93728080}],"asks":[],"checksum":1170531972,"timestamp":"2024-05-24T15:54:05.376301Z"}]}
{"channel":"book","type":"update","data":[{"symbol":"ETH/BTC","bids":[{"price":0.05425,"qty":4.48728080}],"asks":[],"checksum":2843786808,"timestamp":"2024-05-24T15:54:05.380473Z"}]}
{"channel":"book","type":"update","data":[{"symbol":"ETH/USD","bids":[],"asks":[{"price":3699.88,"qty":0.00000000},{"price":3700.10,"qty":2.11000000}],"checksum":571905899,"timestamp":"2024-05-24T15:54:05.382144Z"}]}
{"channel":"book","type":"update","data":[{"symbol":"BTC/USD","bids":[],"asks":[{"price":68207.1,"qty":0.33750000}],"checksum":4153664762,"timestamp":"2024-05-24T15:54:05.383915Z"}]}
{"channel":"book","type":"update","data":[{"symbol":"ETH/USD","bids":[],"asks":[{"price":3699.61,"qty":0.00000000},{"price":3700.11,"qty":0.39579387}],"checksum":628489365,"timestamp":"2024-05-24T15:54:05.390182Z"}]}
{"channel":"book","type":"update","data":[{"symbol":"ETH/USD","bids":[{"price":3698.71,"qty":0.00000000},{"price":3697.84,"qty":4.02610258},{"price":3698.47,"qty":2.11000000}],"asks":[],"checksum":1969220836,"timestamp":"2024-05-24T15:54:05.409585Z"}]}
{"channel":"book","type":"update","data":[{"symbol":"ETH/USD","bids":[],"asks":[{"price":3699.30,"qty":27.03215122}],"checksum":1342329659,"timestamp":"2024-05-24T15:54:05.410383Z"}]}
{"channel":"book","type":"update","data":[{"symbol":"ETH/USD","bids":[{"price":3698.47,"qty":4.22000000}],"asks":[],"checksum":529854364,"timestamp":"2024-05-24T15:54:05.412893Z"}]}
{"channel":"book","type":"update","data":[{"symbol":"BTC/USD","bids":[],"asks":[{"price":68200.2,"qty":3.13772032}],"checksum":492672901,"timestamp":"2024-05-24T15:54:05.426182Z"}]}
{"channel":"book","type":"update","data":[{"symbol":"ETH/USD","bids":[],"asks":[{"price":3699.68,"qty":0.39579387}],"checksum":1030078013,"timestamp":"2024-05-24T15:54:05.429278Z"}]}
{"channel":"book","type":"update","data":[{"symbol":"BTC/USD","bids":[{"price":68185.2,"qty":0.19080000}],"asks":[],"checksum":2372138632,"timestamp":"2024-05-24T15:54:05.430814Z"}]}
{"channel":"book","type":"update","data":[{"symbol":"ETH/USD","bids":[{"price":3698.47,"qty":2.11000000}],"asks":[],"checksum":1928528538,"timestamp":"2024-05-24T15:54:05.430862Z"}]}
{"channel":"book","type":"update","data":[{"symbol":"ETH/USD","bids":[{"price":3698.47,"qty":0.00000000},{"price":3697.84,"qty":4.02610258}],"asks":[],"checksum":2430893545,"timestamp":"2024-05-24T15:54:05.433795Z"}]}
{"channel":"book","type":"update","data":[{"symbol":"BTC/USD","bids":[{"price":68185.2,"qty":0.00000000},{"price":68185.0,"qty":1.46659712}],"asks":[],"checksum":2527961201,"timestamp":"2024-05-24T15:54:05.434054Z"}]}
{"channel":"book","type":"update","data":[{"symbol":"ETH/USD","bids":[],"asks":[{"price":3699.30,"qty":0.00000000},{"price":3700.05,"qty":1.62210606}],"checksum":938908829,"timestamp":"2024-05-24T15:54:05.434409Z"}]}
{"channel":"book","type":"update","data":[{"symbol":"ETH/USD","bids":[{"price":3698.89,"qty":65.06532382}],"asks":[],"checksum":1621111448,"timestamp":"2024-05-24T15:54:05.436246Z"}]}
{"channel":"book","type":"update","data":[{"symbol":"ETH/USD","bids":[{"price":3698.79,"qty":27.03583610}],"asks":[],"checksum":1356307071,"timestamp":"2024-05-24T15:54:05.440140Z"}]}
{"channel":"book","type":"update","data":[{"symbol":"BTC/USD","bids":[],"asks":[{"price":68207.1,"qty":0.00000000},{"price":68212.6,"qty":0.21994086}],"checksum":3825121122,"timestamp":"2024-05-24T15:54:05.460701Z"}]}
{"channel":"book","type":"update","data":[{"symbol":"ETH/USD","bids":[],"asks":[{"price":3699.86,"qty":2.11000000}],"checksum":2880212519,"timestamp":"2024-05-24T15:54:05.460768Z"}]}
{"channel":"book","type":"update","data":[{"symbol":"ETH/USD","bids":[],"asks":[{"price":3699.86,"qty":4.22000000}],"checksum":3710156292,"timestamp":"2024-05-24T15:54:05.463832Z"}]}
{"channel":"book","type":"update","data":[{"symbol":"BTC/USD","bids":[{"price":68186.4,"qty":0.00000000},{"price":68183.4,"qty":0.00035492}],"asks":[],"checksum":499398703,"timestamp":"2024-05-24T15:54:05.490927Z"}]}
{"channel":"book","type":"update","data":[{"symbol":"BTC/USD","bids":[],"asks":[{"price":68207.1,"qty":0.33750000}],"checksum":2627264593,"timestamp":"2024-05-24T15:54:05.495464Z"}]}
{"channel":"book","type":"update","data":[{"symbol":"ETH/USD","bids":[],"asks":[{"price":3699.23,"qty":27.03269258}],"checksum":3957403359,"timestamp":"2024-05-24T15:54:05.507584Z"}]}
{"channel":"book","type":"update","data":[{"symbol":"ETH/USD","bids":[{"price":3698.56,"qty":27.03753244}],"asks":[],"checksum":3409410788,"timestamp":"2024-05-24T15:54:05.507720Z"}]}
{"channel":"book","type":"update","data":[{"symbol":"ETH/USD","bids":[],"asks":[{"price":3699.23,"qty":0.00000000},{"price":3700.01,"qty":3.58840422}],"checksum":3657479400,"timestamp":"2024-05-24T15:54:05.515443Z"}]}
{"channel":"book","type":"update","data":[{"symbol":"ETH/USD","bids":[],"asks":[{"price":3699.33,"qty":27.03194147}],"checksum":1757715174,"timestamp":"2024-05-24T15:54:05.519837Z"}]}
{"channel":"book","type":"update","data":[{"symbol":"BTC/USD","bids":[],"asks":[{"price":68207.1,"qty":0.00000000},{"price":68212.6,"qty":0.21994086}],"checksum":499398703,"timestamp":"2024-05-24T15:54:05.526904Z"}]}
{"channel":"book","type":"update","data":[{"symbol":"BTC/USD","bids":[],"asks":[{"price":68207.1,"qty":0.33750000}],"checksum":2627264593,"timestamp":"2024-05-24T15:54:05.558212Z"}]}
{"channel":"book","type":"update","data":[{"symbol":"ETH/USD","bids":[],"asks":[{"price":3699.24,"qty":27.03264808}],"checksum":3810355979,"timestamp":"2024-05-24T15:54:05.561828Z"}]}
{"channel":"book","type":"update","data":[{"symbol":"BTC/USD","bids":[{"price":68189.4,"qty":1.46650314}],"asks":[],"checksum":1384541565,"timestamp":"2024-05-24T15:54:05.573463Z"}]}
{"channel":"book","type":"update","data":[{"symbol":"ETH/USD","bids":[],"asks":[{"price":3699.24,"qty":0.00000000},{"price":3699.86,"qty":4.22000000}],"checksum":1757715174,"timestamp":"2024-05-24T15:54:05.574244Z"}]}
{"channel":"book","type":"update","data":[{"symbol":"ETH/USD","bids":[],"asks":[{"price":3699.49,"qty":27.03076521}],"checksum":1261904942,"timestamp":"2024-05-24T15:54:05.579166Z"}]}
{"channel":"book","type":"update","data":[{"symbol":"BTC/USD","bids":[{"price":68189.4,"qty":0.00000000},{"price":68183.4,"qty":0.00035492}],"asks":[],"checksum":2627264593,"timestamp":"2024-05-24T15:54:05.579371Z"}]}
{"channel":"book","type":"update","data":[{"symbol":"ETH/USD","bids":[{"price":3698.42,"qty":2.11000000}],"asks":[],"checksum":1587763651,"timestamp":"2024-05-24T15:54:05.581206Z"}]}
{"channel":"book","type":"update","data":[{"symbol":"BTC/USD","bids":[],"asks":[{"price":68200.2,"qty":3.12772032}],"checksum":2291576991,"timestamp":"2024-05-24T15:54:05.628293Z"}]}
{"channel":"book","type":"update","data":[{"symbol":"ETH/USD","bids":[],"asks":[{"price":3699.25,"qty":27.03255546}],"checksum":1724131402,"timestamp":"2024-05-24T15:54:05.631108Z"}]}
{"channel":"book","type":"update","data":[{"symbol":"BTC/USD","bids":[],"asks":[{"price":68207.1,"qty":0.00000000},{"price":68212.6,"qty":0.21994086}],"checksum":164260065,"timestamp":"2024-05-24T15:54:05.631617Z"}]}
{"channel":"book","type":"update","data":[{"symbol":"BTC/USD","bids":[{"price":68189.2,"qty":1.46650744}],"asks":[],"checksum":4069329409,"timestamp":"2024-05-24T15:54:05.635478Z"}]}
{"channel":"book","type":"update","data":[{"symbol":"BTC/USD","bids":[{"price":68185.8,"qty":0.00000000},{"price":68183.4,"qty":0.00035492}],"asks":[],"checksum":167022698,"timestamp":"2024-05-24T15:54:05.665213Z"}]}
{"channel":"book","type":"update","data":[{"symbol":"ETH/BTC","bids":[],"asks":[{"price":0.05428,"qty":3.90006206}],"checksum":503132941,"timestamp":"2024-05-24T15:54:05.694966Z"}]}
{"channel":"book","type":"update","data":[{"symbol":"BTC/USD","bids":[{"price":68189.2,"qty":0.00000000},{"price":68183.0,"qty":0.01353482}],"asks":[],"checksum":1418120189,"timestamp":"2024-05-24T15:54:05.695884Z"}]}
{"channel":"book","type":"update","data":[{"symbol":"ETH/USD","bids":[],"asks":[{"price":3699.25,"qty":0.00000000},{"price":3699.76,"qty":4.05521582}],"checksum":1587763651,"timestamp":"2024-05-24T15:54:05.696629Z"}]}
{"channel":"book","type":"update","data":[{"symbol":"ETH/USD","bids":[],"asks":[{"price":3699.33,"qty":0.00000000},{"price":3699.86,"qty":4.22000000}],"checksum":972645530,"timestamp":"2024-05-24T15:54:05.696787Z"}]}
{"channel":"book","type":"update","data":[{"symbol":"ETH/BTC","bids":[],"asks":[{"price":0.05427,"qty":30.72449216}],"checksum":269545474,"timestamp":"2024-05-24T15:54:05.699616Z"}]}
{"channel":"book","type":"update","data":[{"symbol":"BTC/USD","bids":[{"price":68188.9,"qty":1.46651243}],"asks":[],"checksum":4093376208,"timestamp":"2024-05-24T15:54:05.700099Z"}]}
{"channel":"book","type":"update","data":[{"symbol":"ETH/USD","bids":[],"asks":[{"price":3699.22,"qty":27.03275374}],"checksum":3401660014,"timestamp":"2024-05-24T15:54:05.700456Z"}]}
{"channel":"book","type":"update","data":[{"symbol":"BTC/USD","bids":[{"price":68188.9,"qty":0.00000000},{"price":68183.0,"qty":0.01353482}],"asks":[],"checksum":1418120189,"timestamp":"2024-05-24T15:54:05.723376Z"}]}
{"channel":"book","type":"update","data":[{"symbol":"ETH/BTC","bids":[],"asks":[{"price":0.05430,"qty":2.10047227}],"checksum":3997795939,"timestamp":"2024-05-24T15:54:05.724856Z"}]}
{"channel":"book","type":"update","data":[{"symbol":"ETH/BTC","bids":[],"asks":[{"price":0.05430,"qty":19.53931335}],"checksum":3212518198,"timestamp":"2024-05-24T15:54:05.729590Z"}]}
{"channel":"book","type":"update","data":[{"symbol":"BTC/USD","bids":[{"price":68193.2,"qty":0.33750000}],"asks":[],"checksum":1342246337,"timestamp":"2024-05-24T15:54:05.773001Z"}]}
{"channel":"book","type":"update","data":[{"symbol":"BTC/USD","bids":[{"price":68193.2,"qty":0.00000000},{"price":68183.0,"qty":0.01353482}],"asks":[],"checksum":1418120189,"timestamp":"2024-05-24T15:54:05.806720Z"}]}
{"channel":"book","type":"update","data":[{"symbol":"ETH/BTC","bids":[{"price":0.05425,"qty":4.93728080}],"asks":[],"checksum":1396669322,"timestamp":"2024-05-24T15:54:05.818239Z"}]}
{"channel":"book","type":"update","data":[{"symbol":"ETH/USD","bids":[],"asks":[{"price":3699.22,"qty":0.00000000},{"price":3699.86,"qty":4.22000000}],"checksum":972645530,"timestamp":"2024-05-24T15:54:05.894585Z"}]}
{"channel":"book","type":"update","data":[{"symbol":"ETH/USD","bids":[],"asks":[{"price":3699.24,"qty":27.03263479}],"checksum":3965733374,"timestamp":"2024-05-24T15:54:05.898369Z"}]}
{"channel":"book","type":"update","data":[{"symbol":"ETH/USD","bids":[],"asks":[{"price":3699.30,"qty":27.03214198}],"checksum":613099525,"timestamp":"2024-05-24T15:54:05.898542Z"}]}
{"channel":"book","type":"update","data":[{"symbol":"ETH/USD","bids":[],"asks":[{"price":3699.24,"qty":0.00000000},{"price":3699.76,"qty":4.05521582}],"checksum":514263434,"timestamp":"2024-05-24T15:54:05.978502Z"}]}
{"channel":"book","type":"update","data":[{"symbol":"ETH/USD","bids":[],"asks":[{"price":3699.26,"qty":27.03248609}],"checksum":653355307,"timestamp":"2024-05-24T15:54:05.982007Z"}]}
{"channel":"book","type":"update","data":[{"symbol":"BTC/USD","bids":[{"price":68184.4,"qty":0.02195637}],"asks":[],"checksum":4273088664,"timestamp":"2024-05-24T15:54:06.027964Z"}]}
{"channel":"book","type":"update","data":[{"symbol":"ETH/USD","bids":[],"asks":[{"price":3699.26,"qty":0.00000000},{"price":3699.76,"qty":4.05521582}],"checksum":514263434,"timestamp":"2024-05-24T15:54:06.089733Z"}]}
{"channel":"book","type":"update","data":[{"symbol":"ETH/USD","bids":[],"asks":[{"price":3699.28,"qty":27.03234011}],"checksum":3833674153,"timestamp":"2024-05-24T15:54:06.095732Z"}]}
{"channel":"book","type":"update","data":[{"symbol":"BTC/USD","bids":[{"price":68189.4,"qty":1.46650275}],"asks":[],"checksum":2873188412,"timestamp":"2024-05-24T15:54:06.107320Z"}]}
{"channel":"book","type":"update","data":[{"symbol":"ETH/USD","bids":[],"asks":[{"price":3699.28,"qty":0.00000000},{"price":3699.76,"qty":4.05521582}],"checksum":514263434,"timestamp":"2024-05-24T15:54:06.110247Z"}]}
{"channel":"book","type":"update","data":[{"symbol":"ETH/USD","bids":[],"asks":[{"price":3699.37,"qty":27.03169862}],"checksum":2466312198,"timestamp":"2024-05-24T15:54:06.117107Z"}]}
{"channel":"book","type":"update","data":[{"symbol":"BTC/USD","bids":[{"price":68189.4,"qty":0.00000000},{"price":68183.4,"qty":0.00035492}],"asks":[],"checksum":4273088664,"timestamp":"2024-05-24T15:54:06.122088Z"}]}
{"channel":"book","type":"update","data":[{"symbol":"ETH/USD","bids":[{"price":3698.80,"qty":0.02662312}],"asks":[],"checksum":1430413025,"timestamp":"2024-05-24T15:54:06.122871Z"}]}
{"channel":"book","type":"update","data":[{"symbol":"ETH/USD","bids":[],"asks":[{"price":3699.57,"qty":0.00000000},{"price":3699.76,"qty":4.05521582},{"price":3699.48,"qty":0.18297272}],"checksum":735233382,"timestamp":"2024-05-24T15:54:06.122902Z"}]}
{"channel":"book","type":"update","data":[{"symbol":"BTC/USD","bids":[{"price":68189.2,"qty":1.46650744}],"asks":[],"checksum":2396667107,"timestamp":"2024-05-24T15:54:06.178413Z"}]}
{"channel":"book","type":"update","data":[{"symbol":"BTC/USD","bids":[{"price":68185.0,"qty":1.56544712}],"asks":[],"checksum":1337601063,"timestamp":"2024-05-24T15:54:06.179187Z"}]}
{"channel":"book","type":"update","data":[{"symbol":"ETH/USD","bids":[],"asks":[{"price":3699.37,"qty":0.00000000},{"price":3699.76,"qty":4.05521582}],"checksum":1558176027,"timestamp":"2024-05-24T15:54:06.252402Z"}]}
{"channel":"book","type":"update","data":[{"symbol":"ETH/USD","bids":[],"asks":[{"price":3699.26,"qty":27.03244014}],"checksum":2717732784,"timestamp":"2024-05-24T15:54:06.255907Z"}]}
{"channel":"book","type":"update","data":[{"symbol":"ETH/BTC","bids":[{"price":0.05425,"qty":5.38728080}],"asks":[],"checksum":2607248972,"timestamp":"2024-05-24T15:54:06.272058Z"}]}
{"channel":"book","type":"update","data":[{"symbol":"ETH/USD","bids":[],"asks":[{"price":3699.26,"qty":0.00000000},{"price":3699.76,"qty":4.05521582}],"checksum":1558176027,"timestamp":"2024-05-24T15:54:06.282368Z"}]}
{"channel":"book","type":"update","data":[{"symbol":"BTC/USD","bids":[],"asks":[{"price":68207.1,"qty":0.33750000}],"checksum":3413196526,"timestamp":"2024-05-24T15:54:06.304796Z"}]}
{"channel":"book","type":"update","data":[{"symbol":"ETH/USD","bids":[],"asks":[{"price":3699.24,"qty":27.03261586}],"checksum":2051430688,"timestamp":"2024-05-24T15:54:06.307714Z"}]}
{"channel":"book","type":"update","data":[{"symbol":"BTC/USD","bids":[{"price":68189.2,"qty":0.00000000},{"price":68183.4,"qty":0.00035492}],"asks":[],"checksum":2740971761,"timestamp":"2024-05-24T15:54:06.311325Z"}]}
{"channel":"book","type":"update","data":[{"symbol":"ETH/USD","bids":[{"price":3698.42,"qty":0.00000000},{"price":3698.16,"qty":0.75856873}],"asks":[],"checksum":781904381,"timestamp":"2024-05-24T15:54:06.314123Z"}]}
{"channel":"book","type":"update","data":[{"symbol":"BTC/USD","bids":[{"price":68188.9,"qty":1.46651243}],"asks":[],"checksum":1904887486,"timestamp":"2024-05-24T15:54:06.316885Z"}]}
{"channel":"book","type":"update","data":[{"symbol":"ETH/USD","bids":[],"asks":[{"price":3699.24,"qty":0.00000000},{"price":3699.76,"qty":4.05521582}],"checksum":1846705869,"timestamp":"2024-05-24T15:54:06.318846Z"}]}
{"channel":"book","type":"update","data":[{"symbol":"BTC/USD","bids":[{"price":68188.9,"qty":0.00000000},{"price":68183.4,"qty":0.00035492}],"asks":[],"checksum":2740971761,"timestamp":"2024-05-24T15:54:06.320380Z"}]}
{"channel":"book","type":"update","data":[{"symbol":"BTC/USD","bids":[],"asks":[{"price":68207.1,"qty":0.00000000},{"price":68212.6,"qty":0.21994086}],"checksum":570634383,"timestamp":"2024-05-24T15:54:06.327632Z"}]}
{"channel":"book","type":"update","data":[{"symbol":"BTC/USD","bids":[{"price":68184.4,"qty":0.00000000},{"price":68183.0,"qty":0.01353482}],"asks":[],"checksum":2285360106,"timestamp":"2024-05-24T15:54:06.349601Z"}]}
{"channel":"book","type":"update","data":[{"symbol":"BTC/USD","bids":[{"price":68188.9,"qty":1.46651258}],"asks":[],"checksum":3328411802,"timestamp":"2024-05-24T15:54:06.366969Z"}]}
{"channel":"book","type":"update","data":[{"symbol":"ETH/BTC","bids":[{"price":0.05420,"qty":1.67454748}],"asks":[],"checksum":58237075,"timestamp":"2024-05-24T15:54:06.369828Z"}]}
{"channel":"book","type":"update","data":[{"symbol":"BTC/USD","bids":[{"price":68200.1,"qty":13.53958147}],"asks":[],"checksum":307289144,"timestamp":"2024-05-24T15:54:06.370347Z"}]}
{"channel":"book","type":"update","data":[{"symbol":"BTC/USD","bids":[],"asks":[{"price":68207.1,"qty":0.33750000}],"checksum":736383994,"timestamp":"2024-05-24T15:54:06.372886Z"}]}
{"channel":"book","type":"update","data":[{"symbol":"BTC/USD","bids":[{"price":68200.1,"qty":13.20558147}],"asks":[],"checksum":4118076382,"timestamp":"2024-05-24T15:54:06.388563Z"}]}
{"channel":"book","type":"update","data":[{"symbol":"BTC/USD","bids":[{"price":68188.8,"qty":0.00000000},{"price":68183.0,"qty":0.01353482}],"asks":[],"checksum":996510370,"timestamp":"2024-05-24T15:54:06.398741Z"}]}
{"channel":"book","type":"update","data":[{"symbol":"BTC/USD","bids":[{"price":68188.9,"qty":0.00000000},{"price":68180.8,"qty":0.00247937}],"asks":[],"checksum":3420561750,"timestamp":"2024-05-24T15:54:06.398779Z"}]}
{"channel":"book","type":"update","data":[{"symbol":"BTC/USD","bids":[],"asks":[{"price":68203.5,"qty":0.00000000},{"price":68212.6,"qty":0.21994086}],"checksum":999568902,"timestamp":"2024-05-24T15:54:06.398824Z"}]}
{"channel":"book","type":"update","data":[{"symbol":"BTC/USD","bids":[],"asks":[{"price":68200.8,"qty":1.46626051}],"checksum":2290245398,"timestamp":"2024-05-24T15:54:06.402867Z"}]}
{"channel":"book","type":"update","data":[{"symbol":"BTC/USD","bids":[{"price":68186.9,"qty":1.46655677}],"asks":[],"checksum":1982822509,"timestamp":"2024-05-24T15:54:06.403037Z"}]}
{"channel":"book","type":"update","data":[{"symbol":"BTC/USD","bids":[{"price":68200.1,"qty":12.89458147}],"asks":[],"checksum":4067728423,"timestamp":"2024-05-24T15:54:06.404786Z"}]}
{"channel":"book","type":"update","data":[{"symbol":"BTC/USD","bids":[{"price":68187.5,"qty":1.46654367}],"asks":[],"checksum":2528856430,"timestamp":"2024-05-24T15:54:06.423380Z"}]}
{"channel":"book","type":"update","data":[{"symbol":"BTC/USD","bids":[{"price":68185.0,"qty":0.09885000}],"asks":[],"checksum":4092094288,"timestamp":"2024-05-24T15:54:06.426246Z"}]}
{"channel":"book","type":"update","data":[{"symbol":"BTC/USD","bids":[{"price":68187.5,"qty":0.00000000},{"price":68183.0,"qty":0.01353482}],"asks":[],"checksum":266830652,"timestamp":"2024-05-24T15:54:06.427239Z"}]}
{"channel":"book","type":"update","data":[{"symbol":"BTC/USD","bids":[{"price":68200.1,"qty":12.86525600}],"asks":[],"checksum":997095910,"timestamp":"2024-05-24T15:54:06.430644Z"}]}
{"channel":"book","type":"update","data":[{"symbol":"ETH/USD","bids":[{"price":3698.37,"qty":2.11000000}],"asks":[],"checksum":3606038823,"timestamp":"2024-05-24T15:54:06.431081Z"}]}
{"channel":"book","type":"update","data":[{"symbol":"BTC/USD","bids":[{"price":68183.0,"qty":1.48017436}],"asks":[],"checksum":578665769,"timestamp":"2024-05-24T15:54:06.431322Z"}]}
{"channel":"book","type":"update","data":[{"symbol":"BTC/USD","bids":[{"price":68186.9,"qty":0.00000000},{"price":68180.8,"qty":0.19327937}],"asks":[],"checksum":2106745046,"timestamp":"2024-05-24T15:54:06.448559Z"}]}
{"channel":"book","type":"update","data":[{"symbol":"BTC/USD","bids":[{"price":68200.1,"qty":12.56525600}],"asks":[],"checksum":338407036,"timestamp":"2024-05-24T15:54:06.455022Z"}]}
{"channel":"book","type":"update","data":[{"symbol":"BTC/USD","bids":[{"price":68200.1,"qty":12.26525600}],"asks":[],"checksum":2202684886,"timestamp":"2024-05-24T15:54:06.455096Z"}]}
{"channel":"book","type":"update","data":[{"symbol":"BTC/USD","bids":[{"price":68200.1,"qty":11.96525600}],"asks":[],"checksum":1389772625,"timestamp":"2024-05-24T15:54:06.457679Z"}]}
{"channel":"book","type":"update","data":[{"symbol":"BTC/USD","bids":[{"price":68200.1,"qty":12.67851967}],"asks":[],"checksum":1580410742,"timestamp":"2024-05-24T15:54:06.457826Z"}]}
{"channel":"book","type":"update","data":[{"symbol":"ETH/USD","bids":[],"asks":[{"price":3699.23,"qty":27.03269460}],"checksum":2141023135,"timestamp":"2024-05-24T15:54:06.508017Z"}]}
{"channel":"book","type":"update","data":[{"symbol":"BTC/USD","bids":[{"price":68188.2,"qty":1.46652754}],"asks":[],"checksum":1119621176,"timestamp":"2024-05-24T15:54:06.534685Z"}]}
{"channel":"book","type":"update","data":[{"symbol":"BTC/USD","bids":[{"price":68200.1,"qty":11.96525600}],"asks":[],"checksum":3887743051,"timestamp":"2024-05-24T15:54:06.536955Z"}]}
{"channel":"book","type":"update","data":[{"symbol":"BTC/USD","bids":[{"price":68190.7,"qty":0.00000000},{"price":68180.8,"qty":0.19327937}],"asks":[],"checksum":2557527153,"timestamp":"2024-05-24T15:54:06.547238Z"}]}
{"channel":"book","type":"update","data":[{"symbol":"ETH/USD","bids":[],"asks":[{"price":3699.23,"qty":0.00000000},{"price":3699.76,"qty":4.05521582}],"checksum":3606038823,"timestamp":"2024-05-24T15:54:06.571957Z"}]}
{"channel":"book","type":"update","data":[{"symbol":"ETH/USD","bids":[],"asks":[{"price":3699.22,"qty":27.03273786}],"checksum":1310569681,"timestamp":"2024-05-24T15:54:06.575601Z"}]}
{"channel":"book","type":"update","data":[{"symbol":"ETH/USD","bids":[],"asks":[{"price":3699.22,"qty":0.00000000},{"price":3699.76,"qty":4.05521582}],"checksum":3606038823,"timestamp":"2024-05-24T15:54:06.610707Z"}]}
{"channel":"book","type":"update","data":[{"symbol":"BTC/USD","bids":[{"price":68183.0,"qty":0.01353482}],"asks":[],"checksum":925973020,"timestamp":"2024-05-24T15:54:06.628422Z"}]}
{"channel":"book","type":"update","data":[{"symbol":"BTC/USD","bids":[],"asks":[{"price":68209.0,"qty":0.17890000}],"checksum":400716436,"timestamp":"2024-05-24T15:54:06.630319Z"}]}
{"channel":"book","type":"update","data":[{"symbol":"BTC/USD","bids":[{"price":68188.8,"qty":1.46651589}],"asks":[],"checksum":1304684500,"timestamp":"2024-05-24T15:54:06.632606Z"}]}
{"channel":"book","type":"update","data":[{"symbol":"ETH/USD","bids":[],"asks":[{"price":3699.23,"qty":27.03268853}],"checksum":751839905,"timestamp":"2024-05-24T15:54:06.649648Z"}]}
{"channel":"book","type":"update","data":[{"symbol":"ETH/USD","bids":[],"asks":[{"price":3699.23,"qty":0.00000000},{"price":3699.76,"qty":4.05521582}],"checksum":3606038823,"timestamp":"2024-05-24T15:54:06.656641Z"}]}
{"channel":"book","type":"update","data":[{"symbol":"BTC/USD","bids":[{"price":68184.0,"qty":0.02195484}],"asks":[],"checksum":2141626541,"timestamp":"2024-05-24T15:54:06.712807Z"}]}
{"channel":"book","type":"update","data":[{"symbol":"BTC/USD","bids":[{"price":68188.8,"qty":0.00000000},{"price":68183.0,"qty":0.01353482}],"asks":[],"checksum":2129448638,"timestamp":"2024-05-24T15:54:06.734954Z"}]}
{"channel":"book","type":"update","data":[{"symbol":"ETH/USD","bids":[],"asks":[{"price":3699.29,"qty":27.03228301}],"checksum":1997970959,"timestamp":"2024-05-24T15:54:06.736327Z"}]}
{"channel":"book","type":"update","data":[{"symbol":"BTC/USD","bids":[{"price":68184.8,"qty":1.46660192}],"asks":[],"checksum":2988637226,"timestamp":"2024-05-24T15:54:06.739225Z"}]}
{"channel":"book","type":"update","data":[{"symbol":"BTC/USD","bids":[{"price":68189.2,"qty":1.46650624}],"asks":[],"checksum":3497290918,"timestamp":"2024-05-24T15:54:06.739349Z"}]}
{"channel":"book","type":"update","data":[{"symbol":"ETH/USD","bids":[],"asks":[{"price":3699.64,"qty":0.00000000},{"price":3699.76,"qty":4.05521582}],"checksum":2087416054,"timestamp":"2024-05-24T15:54:06.764344Z"}]}
{"channel":"book","type":"update","data":[{"symbol":"ETH/USD","bids":[{"price":3698.89,"qty":68.25282382}],"asks":[],"checksum":1622252186,"timestamp":"2024-05-24T15:54:06.802335Z"}]}
{"channel":"book","type":"update","data":[{"symbol":"ETH/USD","bids":[],"asks":[{"price":3699.29,"qty":0.00000000},{"price":3699.77,"qty":27.02876772}],"checksum":1102777944,"timestamp":"2024-05-24T15:54:06.833067Z"}]}
{"channel":"book","type":"update","data":[{"symbol":"ETH/USD","bids":[],"asks":[{"price":3699.28,"qty":27.03231398}],"checksum":2916402650,"timestamp":"2024-05-24T15:54:06.837957Z"}]}
{"channel":"book","type":"update","data":[{"symbol":"BTC/USD","bids":[{"price":68189.2,"qty":0.00000000},{"price":68183.4,"qty":0.00035492}],"asks":[],"checksum":2988637226,"timestamp":"2024-05-24T15:54:06.864596Z"}]}
{"channel":"book","type":"update","data":[{"symbol":"ETH/USD","bids":[],"asks":[{"price":3699.28,"qty":0.00000000},{"price":3699.77,"qty":27.02876772}],"checksum":1102777944,"timestamp":"2024-05-24T15:54:06.864881Z"}]}
{"channel":"book","type":"update","data":[{"symbol":"BTC/USD","bids":[{"price":68188.9,"qty":1.46651387}],"asks":[],"checksum":821858162,"timestamp":"2024-05-24T15:54:06.868188Z"}]}
{"channel":"book","type":"update","data":[{"symbol":"ETH/USD","bids":[],"asks":[{"price":3699.28,"qty":27.03229776}],"checksum":4022955483,"timestamp":"2024-05-24T15:54:06.908880Z"}]}
{"channel":"book","type":"update","data":[{"symbol":"BTC/USD","bids":[],"asks":[{"price":68205.0,"qty":0.17890000}],"checksum":416466866,"timestamp":"2024-05-24T15:54:06.911995Z"}]}
{"channel":"book","type":"update","data":[{"symbol":"BTC/USD","bids":[],"asks":[{"price":68209.0,"qty":0.00000000},{"price":68210.7,"qty":0.08412000}],"checksum":104889820,"timestamp":"2024-05-24T15:54:06.912257Z"}]}
{"channel":"book","type":"update","data":[{"symbol":"BTC/USD","bids":[],"asks":[{"price":68207.1,"qty":0.00000000},{"price":68212.0,"qty":0.05495233}],"checksum":1876392773,"timestamp":"2024-05-24T15:54:06.931241Z"}]}
{"channel":"book","type":"update","data":[{"symbol":"ETH/USD","bids":[],"asks":[{"price":3699.28,"qty":0.00000000},{"price":3699.77,"qty":27.02876772}],"checksum":1102777944,"timestamp":"2024-05-24T15:54:06.932391Z"}]}
{"channel":"book","type":"update","data":[{"symbol":"ETH/USD","bids":[{"price":3698.89,"qty":65.06532382}],"asks":[],"checksum":1566696500,"timestamp":"2024-05-24T15:54:06.952043Z"}]}
{"channel":"book","type":"update","data":[{"symbol":"ETH/USD","bids":[],"asks":[{"price":3699.64,"qty":3.18750000}],"checksum":3606038823,"timestamp":"2024-05-24T15:54:06.954083Z"}]}
{"channel":"book","type":"update","data":[{"symbol":"ETH/USD","bids":[],"asks":[{"price":3699.25,"qty":27.03252755}],"checksum":2127165837,"timestamp":"2024-05-24T15:54:06.976193Z"}]}
{"channel":"book","type":"update","data":[{"symbol":"ETH/USD","bids":[],"asks":[{"price":3699.25,"qty":0.00000000},{"price":3699.76,"qty":4.05521582}],"checksum":3606038823,"timestamp":"2024-05-24T15:54:07.007051Z"}]}
{"channel":"book","type":"update","data":[{"symbol":"BTC/USD","bids":[],"asks":[{"price":68207.1,"qty":0.33750000}],"checksum":104889820,"timestamp":"2024-05-24T15:54:07.014371Z"}]}
{"channel":"book","type":"update","data":[{"symbol":"ETH/USD","bids":[{"price":3698.37,"qty":0.00000000},{"price":3698.16,"qty":0.75856873}],"asks":[],"checksum":1846705869,"timestamp":"2024-05-24T15:54:07.030479Z"}]}
{"channel":"book","type":"update","data":[{"symbol":"BTC/USD","bids":[{"price":68184.0,"qty":0.00000000},{"price":68183.4,"qty":0.00035492}],"asks":[],"checksum":3040670615,"timestamp":"2024-05-24T15:54:07.035882Z"}]}
{"channel":"book","type":"update","data":[{"symbol":"ETH/USD","bids":[],"asks":[{"price":3698.90,"qty":3.73750000}],"checksum":2620184735,"timestamp":"2024-05-24T15:54:07.048778Z"}]}
{"channel":"book","type":"update","data":[{"symbol":"ETH/USD","bids":[{"price":3698.31,"qty":0.00000000},{"price":3697.88,"qty":9.83417729}],"asks":[],"checksum":2030041020,"timestamp":"2024-05-24T15:54:07.051116Z"}]}
{"channel":"book","type":"update","data":[{"symbol":"ETH/BTC","bids":[{"price":0.05425,"qty":4.93728080}],"asks":[],"checksum":3407916373,"timestamp":"2024-05-24T15:54:07.051172Z"}]}
{"channel":"book","type":"update","data":[{"symbol":"ETH/BTC","bids":[{"price":0.05425,"qty":4.48728080}],"asks":[],"checksum":660927977,"timestamp":"2024-05-24T15:54:07.051353Z"}]}
{"channel":"book","type":"update","data":[{"symbol":"ETH/USD","bids":[],"asks":[{"price":3699.58,"qty":2.92451322}],"checksum":4142844240,"timestamp":"2024-05-24T15:54:07.052004Z"}]}
{"channel":"book","type":"update","data":[{"symbol":"ETH/USD","bids":[],"asks":[{"price":3698.90,"qty":6.92500000}],"checksum":589317971,"timestamp":"2024-05-24T15:54:07.052760Z"}]}
{"channel":"book","type":"update","data":[{"symbol":"ETH/USD","bids":[{"price":3698.89,"qty":64.33619414}],"asks":[],"checksum":4079456792,"timestamp":"2024-05-24T15:54:07.055555Z"}]}
{"channel":"book","type":"update","data":[{"symbol":"ETH/USD","bids":[{"price":3697.88,"qty":0.00000000},{"price":3697.84,"qty":4.02610258}],"asks":[],"checksum":2203351240,"timestamp":"2024-05-24T15:54:07.056414Z"}]}
{"channel":"book","type":"update","data":[{"symbol":"ETH/USD","bids":[],"asks":[{"price":3699.31,"qty":0.39579387}],"checksum":2871516037,"timestamp":"2024-05-24T15:54:07.057376Z"}]}
{"channel":"book","type":"update","data":[{"symbol":"ETH/USD","bids":[{"price":3698.89,"qty":64.07027512}],"asks":[],"checksum":909001435,"timestamp":"2024-05-24T15:54:07.060721Z"}]}
{"channel":"book","type":"update","data":[{"symbol":"ETH/BTC","bids":[],"asks":[{"price":0.05427,"qty":17.21320458}],"checksum":713635558,"timestamp":"2024-05-24T15:54:07.060837Z"}]}
{"channel":"book","type":"update","data":[{"symbol":"ETH/BTC","bids":[{"price":0.05424,"qty":3.34649505}],"asks":[],"checksum":4142287749,"timestamp":"2024-05-24T15:54:07.060862Z"}]}
{"channel":"book","type":"update","data":[{"symbol":"ETH/BTC","bids":[{"price":0.05424,"qty":0.64298798}],"asks":[],"checksum":249023781,"timestamp":"2024-05-24T15:54:07.060881Z"}]}
{"channel":"book","type":"update","data":[{"symbol":"ETH/USD","bids":[],"asks":[{"price":3699.29,"qty":4.05485407}],"checksum":1535967584,"timestamp":"2024-05-24T15:54:07.061867Z"}]}
{"channel":"book","type":"update","data":[{"symbol":"ETH/USD","bids":[],"asks":[{"price":3699.56,"qty":0.00000000},{"price":3699.71,"qty":1.53600000}],"checksum":2970865112,"timestamp":"2024-05-24T15:54:07.063846Z"}]}
{"channel":"book","type":"update","data":[{"symbol":"ETH/USD","bids":[],"asks":[{"price":3699.49,"qty":0.00000000},{"price":3699.76,"qty":4.05521582}],"checksum":3174812714,"timestamp":"2024-05-24T15:54:07.066961Z"}]}
{"channel":"book","type":"update","data":[{"symbol":"ETH/USD","bids":[],"asks":[{"price":3699.30,"qty":0.00000000},{"price":3699.77,"qty":27.02876772}],"checksum":3098611212,"timestamp":"2024-05-24T15:54:07.067010Z"}]}
{"channel":"book","type":"update","data":[{"symbol":"ETH/USD","bids":[],"asks":[{"price":3699.23,"qty":27.03269353}],"checksum":1846810894,"timestamp":"2024-05-24T15:54:07.067067Z"}]}
{"channel":"book","type":"update","data":[{"symbol":"ETH/USD","bids":[{"price":3698.89,"qty":37.03513756}],"asks":[],"checksum":1258364492,"timestamp":"2024-05-24T15:54:07.067120Z"}]}
{"channel":"book","type":"update","data":[{"symbol":"ETH/USD","bids":[{"price":3698.79,"qty":0.00000000},{"price":3697.83,"qty":17.08157162}],"asks":[],"checksum":3221493003,"timestamp":"2024-05-24T15:54:07.067186Z"}]}
{"channel":"book","type":"update","data":[{"symbol":"ETH/USD","bids":[{"price":3698.89,"qty":10.00000000}],"asks":[],"checksum":2681613425,"timestamp":"2024-05-24T15:54:07.067216Z"}]}
{"channel":"book","type":"update","data":[{"symbol":"ETH/BTC","bids":[],"asks":[{"price":0.05426,"qty":8.96598945}],"checksum":1886547368,"timestamp":"2024-05-24T15:54:07.067838Z"}]}
{"channel":"book","type":"update","data":[{"symbol":"ETH/USD","bids":[{"price":3698.56,"qty":0.00000000},{"price":3697.81,"qty":0.28806122}],"asks":[],"checksum":2701085151,"timestamp":"2024-05-24T15:54:07.068318Z"}]}
{"channel":"book","type":"update","data":[{"symbol":"ETH/USD","bids":[],"asks":[{"price":3699.58,"qty":0.81451322},{"price":3699.34,"qty":2.11000000}],"checksum":3656209632,"timestamp":"2024-05-24T15:54:07.069261Z"}]}
{"channel":"book","type":"update","data":[{"symbol":"ETH/BTC","bids":[{"price":0.05423,"qty":14.63493318}],"asks":[],"checksum":1451985779,"timestamp":"2024-05-24T15:54:07.069608Z"}]}
{"channel":"book","type":"update","data":[{"symbol":"ETH/USD","bids":[{"price":3698.69,"qty":0.00000000},{"price":3697.79,"qty":1.09400000}],"asks":[],"checksum":1972914613,"timestamp":"2024-05-24T15:54:07.071038Z"}]}
{"channel":"book","type":"update","data":[{"symbol":"ETH/BTC","bids":[],"asks":[{"price":0.05426,"qty":9.41598945}],"checksum":3490602953,"timestamp":"2024-05-24T15:54:07.071198Z"}]}
{"channel":"book","type":"update","data":[{"symbol":"ETH/BTC","bids":[],"asks":[{"price":0.05426,"qty":22.92792371}],"checksum":3441978212,"timestamp":"2024-05-24T15:54:07.071611Z"}]}
{"channel":"book","type":"update","data":[{"symbol":"ETH/BTC","bids":[{"price":0.05423,"qty":17.33841932}],"asks":[],"checksum":435442448,"timestamp":"2024-05-24T15:54:07.071633Z"}]}
{"channel":"book","type":"update","data":[{"symbol":"ETH/USD","bids":[],"asks":[{"price":3699.34,"qty":4.22000000}],"checksum":1775794314,"timestamp":"2024-05-24T15:54:07.071836Z"}]}
{"channel":"book","type":"update","data":[{"symbol":"ETH/BTC","bids":[{"price":0.05423,"qty":20.04208014}],"asks":[],"checksum":1510423611,"timestamp":"2024-05-24T15:54:07.071877Z"}]}
{"channel":"book","type":"update","data":[{"symbol":"ETH/USD","bids":[],"asks":[{"price":3698.90,"qty":7.46570128}],"checksum":3195203903,"timestamp":"2024-05-24T15:54:07.074269Z"}]}
{"channel":"book","type":"update","data":[{"symbol":"ETH/USD","bids":[],"asks":[{"price":3699.27,"qty":3.18750000}],"checksum":3026850469,"timestamp":"2024-05-24T15:54:07.074661Z"}]}
{"channel":"book","type":"update","data":[{"symbol":"ETH/USD","bids":[],"asks":[{"price":3699.23,"qty":0.00000000},{"price":3699.71,"qty":1.53600000}],"checksum":363441252,"timestamp":"2024-05-24T15:54:07.079021Z"}]}
{"channel":"book","type":"update","data":[{"symbol":"ETH/BTC","bids":[{"price":0.05422,"qty":2.06494397}],"asks":[],"checksum":3276379125,"timestamp":"2024-05-24T15:54:07.083894Z"}]}
{"channel":"book","type":"update","data":[{"symbol":"ETH/USD","bids":[],"asks":[{"price":3699.07,"qty":27.03386331}],"checksum":1694368523,"timestamp":"2024-05-24T15:54:07.085795Z"}]}
{"channel":"book","type":"update","data":[{"symbol":"ETH/USD","bids":[{"price":3698.59,"qty":27.03731890}],"asks":[],"checksum":3798841271,"timestamp":"2024-05-24T15:54:07.085852Z"}]}
{"channel":"book","type":"update","data":[{"symbol":"ETH/USD","bids":[{"price":3698.61,"qty":27.03714079}],"asks":[],"checksum":2837869432,"timestamp":"2024-05-24T15:54:07.085962Z"}]}
{"channel":"book","type":"update","data":[{"symbol":"ETH/USD","bids":[{"price":3698.47,"qty":27.03815773}],"asks":[],"checksum":715062980,"timestamp":"2024-05-24T15:54:07.086002Z"}]}
{"channel":"book","type":"update","data":[{"symbol":"ETH/USD","bids":[{"price":3698.23,"qty":27.03990466}],"asks":[],"checksum":2586561572,"timestamp":"2024-05-24T15:54:07.086038Z"}]}
{"channel":"book","type":"update","data":[{"symbol":"BTC/USD","bids":[{"price":68186.0,"qty":0.00000000},{"price":68180.8,"qty":0.00247937}],"asks":[],"checksum":4202767088,"timestamp":"2024-05-24T15:54:07.089038Z"}]}
{"channel":"book","type":"update","data":[{"symbol":"BTC/USD","bids":[{"price":68181.9,"qty":0.01353482}],"asks":[],"checksum":3338947205,"timestamp":"2024-05-24T15:54:07.089422Z"}]}
{"channel":"book","type":"update","data":[{"symbol":"ETH/USD","bids":[],"asks":[{"price":3698.90,"qty":6.92500000}],"checksum":305938839,"timestamp":"2024-05-24T15:54:07.090803Z"}]}
{"channel":"book","type":"update","data":[{"symbol":"ETH/USD","bids":[],"asks":[{"price":3698.90,"qty":3.73750000}],"checksum":3354578836,"timestamp":"2024-05-24T15:54:07.091821Z"}]}
{"channel":"book","type":"update","data":[{"symbol":"ETH/BTC","bids":[{"price":0.05417,"qty":14.47418911}],"asks":[],"checksum":3614517735,"timestamp":"2024-05-24T15:54:07.091852Z"}]}
{"channel":"book","type":"update","data":[{"symbol":"ETH/USD","bids":[],"asks":[{"price":3698.90,"qty":30.77256447}],"checksum":1454152918,"timestamp":"2024-05-24T15:54:07.093147Z"}]}
{"channel":"book","type":"update","data":[{"symbol":"ETH/USD","bids":[],"asks":[{"price":3699.06,"qty":4.05485407}],"checksum":435814578,"timestamp":"2024-05-24T15:54:07.095519Z"}]}
{"channel":"book","type":"update","data":[{"symbol":"ETH/USD","bids":[{"price":3698.67,"qty":0.00000000},{"price":3697.84,"qty":4.02610258}],"asks":[],"checksum":1065088718,"timestamp":"2024-05-24T15:54:07.095808Z"}]}
{"channel":"book","type":"update","data":[{"symbol":"ETH/USD","bids":[],"asks":[{"price":3699.29,"qty":0.00000000},{"price":3699.68,"qty":0.39579387}],"checksum":1240040516,"timestamp":"2024-05-24T15:54:07.098496Z"}]}
{"channel":"book","type":"update","data":[{"symbol":"ETH/USD","bids":[],"asks":[{"price":3698.90,"qty":33.96006447}],"checksum":1229565418,"timestamp":"2024-05-24T15:54:07.098838Z"}]}
{"channel":"book","type":"update","data":[{"symbol":"ETH/USD","bids":[],"asks":[{"price":3698.90,"qty":34.50076575}],"checksum":1793160415,"timestamp":"2024-05-24T15:54:07.099439Z"}]}
{"channel":"book","type":"update","data":[{"symbol":"ETH/USD","bids":[{"price":3698.61,"qty":0.00000000},{"price":3697.83,"qty":17.08157162}],"asks":[],"checksum":3309333514,"timestamp":"2024-05-24T15:54:07.101077Z"}]}
{"channel":"book","type":"update","data":[{"symbol":"ETH/USD","bids":[{"price":3698.59,"qty":0.00000000},{"price":3697.81,"qty":0.28806122}],"asks":[],"checksum":3816872555,"timestamp":"2024-05-24T15:54:07.101088Z"}]}
{"channel":"book","type":"update","data":[{"symbol":"ETH/USD","bids":[{"price":3698.64,"qty":1.06244254}],"asks":[],"checksum":3403415775,"timestamp":"2024-05-24T15:54:07.101149Z"}]}
{"channel":"book","type":"update","data":[{"symbol":"ETH/USD","bids":[{"price":3698.33,"qty":0.00000000},{"price":3697.81,"qty":0.28806122}],"asks":[],"checksum":2124157087,"timestamp":"2024-05-24T15:54:07.102625Z"}]}
{"channel":"book","type":"update","data":[{"symbol":"ETH/BTC","bids":[{"price":0.05423,"qty":6.52253184}],"asks":[],"checksum":1580088918,"timestamp":"2024-05-24T15:54:07.103183Z"}]}
{"channel":"book","type":"update","data":[{"symbol":"ETH/USD","bids":[],"asks":[{"price":3698.90,"qty":48.02101780}],"checksum":1148949400,"timestamp":"2024-05-24T15:54:07.104197Z"}]}
{"channel":"book","type":"update","data":[{"symbol":"ETH/USD","bids":[],"asks":[{"price":3699.07,"qty":0.00000000},{"price":3699.71,"qty":1.53600000}],"checksum":2255275466,"timestamp":"2024-05-24T15:54:07.106893Z"}]}
{"channel":"book","type":"update","data":[{"symbol":"ETH/USD","bids":[{"price":3698.47,"qty":0.00000000},{"price":3697.79,"qty":1.09400000}],"asks":[],"checksum":1018391053,"timestamp":"2024-05-24T15:54:07.109790Z"}]}
{"channel":"book","type":"update","data":[{"symbol":"BTC/USD","bids":[{"price":68188.2,"qty":0.00000000},{"price":68180.8,"qty":0.00247937}],"asks":[],"checksum":4108534834,"timestamp":"2024-05-24T15:54:07.110929Z"}]}
{"channel":"book","type":"update","data":[{"symbol":"BTC/USD","bids":[{"price":68188.9,"qty":0.00000000},{"price":68180.7,"qty":0.91220814}],"asks":[],"checksum":1873968636,"timestamp":"2024-05-24T15:54:07.111066Z"}]}
{"channel":"book","type":"update","data":[{"symbol":"BTC/USD","bids":[{"price":68184.8,"qty":0.00000000},{"price":68180.0,"qty":0.15000000}],"asks":[],"checksum":1198739599,"timestamp":"2024-05-24T15:54:07.111106Z"}]}
{"channel":"book","type":"update","data":[{"symbol":"ETH/USD","bids":[{"price":3698.23,"qty":0.00000000},{"price":3697.73,"qty":9.83417729}],"asks":[],"checksum":769574916,"timestamp":"2024-05-24T15:54:07.113258Z"}]}
