{"channel":"book","type":"update","data":[{"symbol":"ETH/USD","bids":[{"price":3697.84,"qty":0.00000000},{"price":3697.66,"qty":4.10000000}],"asks":[],"checksum":3842932199,"timestamp":"2024-05-24T15:54:07.117329Z"}]}
{"channel":"book","type":"update","data":[{"symbol":"ETH/BTC","bids":[{"price":0.05422,"qty":15.58631365}],"asks":[],"checksum":2732060094,"timestamp":"2024-05-24T15:54:07.117651Z"}]}
{"channel":"book","type":"update","data":[{"symbol":"ETH/USD","bids":[{"price":3698.89,"qty":0.00000000},{"price":3697.65,"qty":7.37288448}],"asks":[],"checksum":4042981139,"timestamp":"2024-05-24T15:54:07.120524Z"}]}
{"channel":"book","type":"update","data":[{"symbol":"ETH/USD","bids":[{"price":3698.64,"qty":0.00000000},{"price":3697.64,"qty":3.18750000}],"asks":[],"checksum":1628551509,"timestamp":"2024-05-24T15:54:07.121108Z"}]}
{"channel":"book","type":"update","data":[{"symbol":"BTC/USD","bids":[{"price":68180.8,"qty":0.00000000},{"price":68179.4,"qty":0.33750000}],"asks":[],"checksum":2794307002,"timestamp":"2024-05-24T15:54:07.123165Z"}]}
{"channel":"book","type":"update","data":[{"symbol":"ETH/USD","bids":[{"price":3697.73,"qty":0.00000000},{"price":3697.35,"qty":5.40400000}],"asks":[],"checksum":89587651,"timestamp":"2024-05-24T15:54:07.123486Z"}]}
{"channel":"book","type":"update","data":[{"symbol":"ETH/USD","bids":[{"price":3697.79,"qty":0.00000000},{"price":3697.32,"qty":6.70000000}],"asks":[],"checksum":890980796,"timestamp":"2024-05-24T15:54:07.123514Z"}]}
{"channel":"book","type":"update","data":[{"symbol":"BTC/USD","bids":[{"price":68181.0,"qty":1.46668408}],"asks":[],"checksum":2241605327,"timestamp":"2024-05-24T15:54:07.124290Z"}]}
{"channel":"book","type":"update","data":[{"symbol":"BTC/USD","bids":[{"price":68185.6,"qty":1.46658497}],"asks":[],"checksum":69296849,"timestamp":"2024-05-24T15:54:07.124316Z"}]}
{"channel":"book","type":"update","data":[{"symbol":"ETH/BTC","bids":[{"price":0.05422,"qty":15.41410680}],"asks":[],"checksum":2986496524,"timestamp":"2024-05-24T15:54:07.125544Z"}]}
{"channel":"book","type":"update","data":[{"symbol":"ETH/USD","bids":[{"price":3697.35,"qty":0.00000000},{"price":3697.19,"qty":4.02610258}],"asks":[],"checksum":1333277070,"timestamp":"2024-05-24T15:54:07.126205Z"}]}
{"channel":"book","type":"update","data":[{"symbol":"ETH/USD","bids":[{"price":3698.54,"qty":1.06256954}],"asks":[],"checksum":3518230944,"timestamp":"2024-05-24T15:54:07.126597Z"}]}
{"channel":"book","type":"update","data":[{"symbol":"ETH/BTC","bids":[],"asks":[{"price":0.05426,"qty":24.30492371}],"checksum":1158380114,"timestamp":"2024-05-24T15:54:07.126857Z"}]}
{"channel":"book","type":"update","data":[{"symbol":"ETH/USD","bids":[],"asks":[{"price":3698.90,"qty":75.05608227}],"checksum":4199345712,"timestamp":"2024-05-24T15:54:07.131371Z"}]}
{"channel":"book","type":"update","data":[{"symbol":"ETH/USD","bids":[],"asks":[{"price":3699.34,"qty":2.11000000},{"price":3699.09,"qty":2.11000000}],"checksum":1057111363,"timestamp":"2024-05-24T15:54:07.131869Z"}]}
{"channel":"book","type":"update","data":[{"symbol":"BTC/USD","bids":[],"asks":[{"price":68209.8,"qty":0.19080000}],"checksum":463290232,"timestamp":"2024-05-24T15:54:07.134730Z"}]}
{"channel":"book","type":"update","data":[{"symbol":"ETH/USD","bids":[],"asks":[{"price":3699.34,"qty":0.00000000},{"price":3699.71,"qty":1.53600000}],"checksum":3652319705,"timestamp":"2024-05-24T15:54:07.135061Z"}]}
{"channel":"book","type":"update","data":[{"symbol":"ETH/BTC","bids":[{"price":0.05421,"qty":17.02907027}],"asks":[],"checksum":3032425545,"timestamp":"2024-05-24T15:54:07.137505Z"}]}
{"channel":"book","type":"update","data":[{"symbol":"ETH/USD","bids":[],"asks":[{"price":3698.89,"qty":0.04046589}],"checksum":2209545157,"timestamp":"2024-05-24T15:54:07.138008Z"}]}
{"channel":"book","type":"update","data":[{"symbol":"ETH/USD","bids":[],"asks":[{"price":3698.90,"qty":74.51538099},{"price":3698.81,"qty":0.54071444}],"checksum":2909360307,"timestamp":"2024-05-24T15:54:07.139782Z"}]}
{"channel":"book","type":"update","data":[{"symbol":"ETH/USD","bids":[],"asks":[{"price":3698.81,"qty":14.06159292}],"checksum":1732095676,"timestamp":"2024-05-24T15:54:07.142360Z"}]}
{"channel":"book","type":"update","data":[{"symbol":"ETH/USD","bids":[],"asks":[{"price":3698.90,"qty":47.48031652}],"checksum":1769133909,"timestamp":"2024-05-24T15:54:07.143149Z"}]}
{"channel":"book","type":"update","data":[{"symbol":"ETH/BTC","bids":[],"asks":[{"price":0.05430,"qty":18.89784108}],"checksum":947519666,"timestamp":"2024-05-24T15:54:07.144224Z"}]}
{"channel":"book","type":"update","data":[{"symbol":"ETH/BTC","bids":[],"asks":[{"price":0.05429,"qty":17.38299777}],"checksum":1302401486,"timestamp":"2024-05-24T15:54:07.144319Z"}]}
{"channel":"book","type":"update","data":[{"symbol":"ETH/USD","bids":[],"asks":[{"price":3698.90,"qty":33.96006447}],"checksum":1896570092,"timestamp":"2024-05-24T15:54:07.144391Z"}]}
{"channel":"book","type":"update","data":[{"symbol":"ETH/USD","bids":[],"asks":[{"price":3698.81,"qty":17.24909292}],"checksum":2968908233,"timestamp":"2024-05-24T15:54:07.145524Z"}]}
{"channel":"book","type":"update","data":[{"symbol":"ETH/USD","bids":[],"asks":[{"price":3698.90,"qty":6.92500000}],"checksum":1128888486,"timestamp":"2024-05-24T15:54:07.149040Z"}]}
{"channel":"book","type":"update","data":[{"symbol":"ETH/USD","bids":[{"price":3697.84,"qty":4.02610258}],"asks":[],"checksum":3619959731,"timestamp":"2024-05-24T15:54:07.151478Z"}]}
{"channel":"book","type":"update","data":[{"symbol":"BTC/USD","bids":[{"price":68185.6,"qty":0.00000000},{"price":68180.0,"qty":0.15000000}],"asks":[],"checksum":3812813084,"timestamp":"2024-05-24T15:54:07.152491Z"}]}
{"channel":"book","type":"update","data":[{"symbol":"ETH/BTC","bids":[],"asks":[{"price":0.05429,"qty":17.29740257}],"checksum":2223808495,"timestamp":"2024-05-24T15:54:07.153180Z"}]}
{"channel":"book","type":"update","data":[{"symbol":"ETH/BTC","bids":[],"asks":[{"price":0.05426,"qty":24.39051891}],"checksum":556375298,"timestamp":"2024-05-24T15:54:07.153310Z"}]}
{"channel":"book","type":"update","data":[{"symbol":"ETH/USD","bids":[{"price":3698.54,"qty":0.00000000},{"price":3697.32,"qty":6.70000000}],"asks":[],"checksum":2756229486,"timestamp":"2024-05-24T15:54:07.154302Z"}]}
{"channel":"book","type":"update","data":[{"symbol":"BTC/USD","bids":[{"price":68189.0,"qty":0.01353482}],"asks":[],"checksum":1001222375,"timestamp":"2024-05-24T15:54:07.154809Z"}]}
{"channel":"book","type":"update","data":[{"symbol":"ETH/USD","bids":[{"price":3697.65,"qty":0.00000000},{"price":3697.17,"qty":0.20000000}],"asks":[],"checksum":2544097618,"timestamp":"2024-05-24T15:54:07.156168Z"}]}
{"channel":"book","type":"update","data":[{"symbol":"ETH/USD","bids":[{"price":3698.45,"qty":1.06289856}],"asks":[],"checksum":2229537864,"timestamp":"2024-05-24T15:54:07.160019Z"}]}
{"channel":"book","type":"update","data":[{"symbol":"ETH/BTC","bids":[{"price":0.05423,"qty":3.81887102}],"asks":[],"checksum":2900674366,"timestamp":"2024-05-24T15:54:07.166576Z"}]}
{"channel":"book","type":"update","data":[{"symbol":"ETH/BTC","bids":[{"price":0.05417,"qty":27.99107324}],"asks":[],"checksum":610738369,"timestamp":"2024-05-24T15:54:07.166826Z"}]}
{"channel":"book","type":"update","data":[{"symbol":"ETH/USD","bids":[{"price":3698.45,"qty":0.00000000},{"price":3697.17,"qty":0.20000000}],"asks":[],"checksum":2544097618,"timestamp":"2024-05-24T15:54:07.169728Z"}]}
{"channel":"book","type":"update","data":[{"symbol":"ETH/USD","bids":[{"price":3697.93,"qty":27.04213800}],"asks":[],"checksum":671643319,"timestamp":"2024-05-24T15:54:07.171168Z"}]}
{"channel":"book","type":"update","data":[{"symbol":"BTC/USD","bids":[{"price":68185.9,"qty":0.04828856}],"asks":[],"checksum":3250553215,"timestamp":"2024-05-24T15:54:07.172433Z"}]}
{"channel":"book","type":"update","data":[{"symbol":"ETH/USD","bids":[{"price":3698.38,"qty":1.06292295}],"asks":[],"checksum":3813014226,"timestamp":"2024-05-24T15:54:07.175459Z"}]}
{"channel":"book","type":"update","data":[{"symbol":"BTC/USD","bids":[{"price":68183.4,"qty":1.46698600}],"asks":[],"checksum":956333871,"timestamp":"2024-05-24T15:54:07.176522Z"}]}
{"channel":"book","type":"update","data":[{"symbol":"ETH/USD","bids":[{"price":3697.65,"qty":0.72912968}],"asks":[],"checksum":98155069,"timestamp":"2024-05-24T15:54:07.180081Z"}]}
{"channel":"book","type":"update","data":[{"symbol":"ETH/USD","bids":[{"price":3697.84,"qty":0.00000000},{"price":3697.64,"qty":3.18750000},{"price":3697.94,"qty":4.02610258}],"asks":[],"checksum":3937102301,"timestamp":"2024-05-24T15:54:07.180122Z"}]}
{"channel":"book","type":"update","data":[{"symbol":"BTC/USD","bids":[{"price":68185.0,"qty":1.56544822}],"asks":[],"checksum":3359766659,"timestamp":"2024-05-24T15:54:07.184365Z"}]}
{"channel":"book","type":"update","data":[{"symbol":"ETH/USD","bids":[{"price":3697.93,"qty":0.00000000},{"price":3697.64,"qty":3.18750000}],"asks":[],"checksum":3580872102,"timestamp":"2024-05-24T15:54:07.186702Z"}]}
{"channel":"book","type":"update","data":[{"symbol":"ETH/BTC","bids":[],"asks":[{"price":0.05429,"qty":17.05080454}],"checksum":1936831300,"timestamp":"2024-05-24T15:54:07.189347Z"}]}
{"channel":"book","type":"update","data":[{"symbol":"ETH/BTC","bids":[],"asks":[{"price":0.05429,"qty":16.81088406}],"checksum":381210960,"timestamp":"2024-05-24T15:54:07.189510Z"}]}
{"channel":"book","type":"update","data":[{"symbol":"ETH/BTC","bids":[],"asks":[{"price":0.05428,"qty":4.13998254}],"checksum":609005018,"timestamp":"2024-05-24T15:54:07.189702Z"}]}
{"channel":"book","type":"update","data":[{"symbol":"ETH/USD","bids":[{"price":3697.81,"qty":0.00000000},{"price":3697.32,"qty":6.70000000}],"asks":[],"checksum":3605715611,"timestamp":"2024-05-24T15:54:07.189963Z"}]}
{"channel":"book","type":"update","data":[{"symbol":"ETH/USD","bids":[{"price":3697.83,"qty":16.89819748}],"asks":[],"checksum":3250796339,"timestamp":"2024-05-24T15:54:07.190229Z"}]}
{"channel":"book","type":"update","data":[{"symbol":"ETH/BTC","bids":[],"asks":[{"price":0.05428,"qty":4.37039083}],"checksum":3111199769,"timestamp":"2024-05-24T15:54:07.190300Z"}]}
{"channel":"book","type":"update","data":[{"symbol":"ETH/USD","bids":[],"asks":[{"price":3698.81,"qty":44.28481521}],"checksum":1634777608,"timestamp":"2024-05-24T15:54:07.191629Z"}]}
{"channel":"book","type":"update","data":[{"symbol":"BTC/USD","bids":[{"price":68185.0,"qty":0.09885000}],"asks":[],"checksum":956333871,"timestamp":"2024-05-24T15:54:07.195883Z"}]}
{"channel":"book","type":"update","data":[{"symbol":"ETH/USD","bids":[{"price":3697.89,"qty":0.26202433}],"asks":[],"checksum":2163175046,"timestamp":"2024-05-24T15:54:07.198546Z"}]}
{"channel":"book","type":"update","data":[{"symbol":"ETH/USD","bids":[],"asks":[{"price":3698.89,"qty":3.48046589}],"checksum":717567514,"timestamp":"2024-05-24T15:54:07.200219Z"}]}
{"channel":"book","type":"update","data":[{"symbol":"ETH/USD","bids":[{"price":3698.80,"qty":0.00000000},{"price":3697.32,"qty":6.70000000},{"price":3698.52,"qty":0.02665859}],"asks":[],"checksum":4068357851,"timestamp":"2024-05-24T15:54:07.211182Z"}]}
{"channel":"book","type":"update","data":[{"symbol":"ETH/USD","bids":[],"asks":[{"price":3699.48,"qty":0.00000000},{"price":3699.68,"qty":0.39579387},{"price":3699.63,"qty":0.18297255}],"checksum":3253475398,"timestamp":"2024-05-24T15:54:07.211420Z"}]}
{"channel":"book","type":"update","data":[{"symbol":"ETH/USD","bids":[],"asks":[{"price":3698.89,"qty":3.44000000}],"checksum":3564039407,"timestamp":"2024-05-24T15:54:07.214170Z"}]}
{"channel":"book","type":"update","data":[{"symbol":"ETH/USD","bids":[{"price":3697.94,"qty":0.00000000},{"price":3697.32,"qty":6.70000000}],"asks":[],"checksum":3870941670,"timestamp":"2024-05-24T15:54:07.214967Z"}]}
{"channel":"book","type":"update","data":[{"symbol":"ETH/USD","bids":[],"asks":[{"price":3698.81,"qty":17.24909292}],"checksum":1460845391,"timestamp":"2024-05-24T15:54:07.217012Z"}]}
{"channel":"book","type":"update","data":[{"symbol":"ETH/USD","bids":[],"asks":[{"price":3698.80,"qty":0.04046589}],"checksum":3182033120,"timestamp":"2024-05-24T15:54:07.217160Z"}]}
{"channel":"book","type":"update","data":[{"symbol":"ETH/USD","bids":[{"price":3697.66,"qty":0.00000000},{"price":3697.17,"qty":0.20000000}],"asks":[],"checksum":4079289763,"timestamp":"2024-05-24T15:54:07.217202Z"}]}
{"channel":"book","type":"update","data":[{"symbol":"ETH/USD","bids":[],"asks":[{"price":3698.80,"qty":27.07626128}],"checksum":1423357921,"timestamp":"2024-05-24T15:54:07.220525Z"}]}
{"channel":"book","type":"update","data":[{"symbol":"ETH/USD","bids":[{"price":3697.93,"qty":27.04211310}],"asks":[],"checksum":2450454220,"timestamp":"2024-05-24T15:54:07.220540Z"}]}
{"channel":"book","type":"update","data":[{"symbol":"ETH/USD","bids":[],"asks":[{"price":3698.62,"qty":3.18750000}],"checksum":1003415032,"timestamp":"2024-05-24T15:54:07.224170Z"}]}
{"channel":"book","type":"update","data":[{"symbol":"ETH/USD","bids":[],"asks":[{"price":3698.80,"qty":0.04046589}],"checksum":2517421672,"timestamp":"2024-05-24T15:54:07.224387Z"}]}
{"channel":"book","type":"update","data":[{"symbol":"ETH/USD","bids":[],"asks":[{"price":3698.90,"qty":3.73750000}],"checksum":1577938009,"timestamp":"2024-05-24T15:54:07.224528Z"}]}
{"channel":"book","type":"update","data":[{"symbol":"ETH/USD","bids":[],"asks":[{"price":3698.80,"qty":0.00000000},{"price":3699.63,"qty":0.18297255}],"checksum":2315684597,"timestamp":"2024-05-24T15:54:07.227128Z"}]}
{"channel":"book","type":"update","data":[{"symbol":"ETH/USD","bids":[{"price":3697.70,"qty":8.44009854}],"asks":[],"checksum":3032717809,"timestamp":"2024-05-24T15:54:07.229036Z"}]}
{"channel":"book","type":"update","data":[{"symbol":"ETH/USD","bids":[],"asks":[{"price":3698.61,"qty":0.04046589}],"checksum":3480182117,"timestamp":"2024-05-24T15:54:07.229847Z"}]}
{"channel":"book","type":"update","data":[{"symbol":"ETH/USD","bids":[],"asks":[{"price":3698.89,"qty":0.00000000},{"price":3699.63,"qty":0.18297255}],"checksum":4009178534,"timestamp":"2024-05-24T15:54:07.232773Z"}]}
{"channel":"book","type":"update","data":[{"symbol":"ETH/USD","bids":[{"price":3697.93,"qty":0.00000000},{"price":3697.32,"qty":6.70000000}],"asks":[],"checksum":702115232,"timestamp":"2024-05-24T15:54:07.236189Z"}]}
{"channel":"book","type":"update","data":[{"symbol":"ETH/USD","bids":[],"asks":[{"price":3699.09,"qty":0.00000000},{"price":3699.64,"qty":3.18750000},{"price":3698.86,"qty":2.11000000}],"checksum":2157119235,"timestamp":"2024-05-24T15:54:07.236437Z"}]}
{"channel":"book","type":"update","data":[{"symbol":"ETH/USD","bids":[],"asks":[{"price":3698.86,"qty":4.22000000}],"checksum":3301719547,"timestamp":"2024-05-24T15:54:07.239427Z"}]}
{"channel":"book","type":"update","data":[{"symbol":"ETH/USD","bids":[{"price":3698.38,"qty":0.00000000},{"price":3697.17,"qty":0.20000000}],"asks":[],"checksum":3021382571,"timestamp":"2024-05-24T15:54:07.239627Z"}]}
{"channel":"book","type":"update","data":[{"symbol":"ETH/USD","bids":[{"price":3697.43,"qty":2.11000000}],"asks":[],"checksum":2997615295,"timestamp":"2024-05-24T15:54:07.239813Z"}]}
{"channel":"book","type":"update","data":[{"symbol":"ETH/USD","bids":[],"asks":[{"price":3698.53,"qty":27.03776905}],"checksum":2477914778,"timestamp":"2024-05-24T15:54:07.242209Z"}]}
{"channel":"book","type":"update","data":[{"symbol":"ETH/USD","bids":[],"asks":[{"price":3698.53,"qty":30.22526905}],"checksum":46300253,"timestamp":"2024-05-24T15:54:07.244993Z"}]}
{"channel":"book","type":"update","data":[{"symbol":"ETH/USD","bids":[],"asks":[{"price":3698.81,"qty":14.06159292}],"checksum":1932572850,"timestamp":"2024-05-24T15:54:07.245605Z"}]}
{"channel":"book","type":"update","data":[{"symbol":"ETH/USD","bids":[{"price":3698.33,"qty":1.06831304}],"asks":[],"checksum":2037964629,"timestamp":"2024-05-24T15:54:07.245763Z"}]}
{"channel":"book","type":"update","data":[{"symbol":"ETH/USD","bids":[],"asks":[{"price":3698.61,"qty":0.00000000},{"price":3699.63,"qty":0.18297255}],"checksum":2762740270,"timestamp":"2024-05-24T15:54:07.246136Z"}]}
{"channel":"book","type":"update","data":[{"symbol":"BTC/USD","bids":[{"price":68184.7,"qty":1.46660464}],"asks":[],"checksum":3739180072,"timestamp":"2024-05-24T15:54:07.246868Z"}]}
{"channel":"book","type":"update","data":[{"symbol":"ETH/USD","bids":[],"asks":[{"price":3698.81,"qty":13.52087848},{"price":3698.80,"qty":0.54071590}],"checksum":2509355869,"timestamp":"2024-05-24T15:54:07.248460Z"}]}
{"channel":"book","type":"update","data":[{"symbol":"ETH/USD","bids":[],"asks":[{"price":3699.58,"qty":0.00000000},{"price":3699.63,"qty":0.18297255}],"checksum":3996029980,"timestamp":"2024-05-24T15:54:07.248643Z"}]}
{"channel":"book","type":"update","data":[{"symbol":"ETH/USD","bids":[],"asks":[{"price":3699.05,"qty":0.81316964}],"checksum":2629499441,"timestamp":"2024-05-24T15:54:07.248992Z"}]}
{"channel":"book","type":"update","data":[{"symbol":"BTC/USD","bids":[{"price":68186.3,"qty":0.00000000},{"price":68181.0,"qty":1.46668408}],"asks":[],"checksum":2516064315,"timestamp":"2024-05-24T15:54:07.251524Z"}]}
{"channel":"book","type":"update","data":[{"symbol":"ETH/USD","bids":[],"asks":[{"price":3698.80,"qty":0.00000000},{"price":3699.63,"qty":0.18297255},{"price":3698.53,"qty":30.76602443}],"checksum":1489012502,"timestamp":"2024-05-24T15:54:07.252607Z"}]}
{"channel":"book","type":"update","data":[{"symbol":"ETH/BTC","bids":[],"asks":[{"price":0.05426,"qty":24.30492371}],"checksum":483665652,"timestamp":"2024-05-24T15:54:07.254033Z"}]}
{"channel":"book","type":"update","data":[{"symbol":"ETH/USD","bids":[{"price":3697.70,"qty":0.00000000},{"price":3697.32,"qty":6.70000000}],"asks":[],"checksum":538859320,"timestamp":"2024-05-24T15:54:07.255213Z"}]}
{"channel":"book","type":"update","data":[{"symbol":"BTC/USD","bids":[{"price":68184.7,"qty":0.00000000},{"price":68180.7,"qty":0.91220814}],"asks":[],"checksum":947511591,"timestamp":"2024-05-24T15:54:07.260779Z"}]}
{"channel":"book","type":"update","data":[{"symbol":"ETH/USD","bids":[{"price":3698.16,"qty":0.00000000},{"price":3697.17,"qty":0.20000000}],"asks":[],"checksum":1593212166,"timestamp":"2024-05-24T15:54:07.264972Z"}]}
{"channel":"book","type":"update","data":[{"symbol":"ETH/BTC","bids":[],"asks":[{"price":0.05427,"qty":17.29879978}],"checksum":1690876603,"timestamp":"2024-05-24T15:54:07.269608Z"}]}
{"channel":"book","type":"update","data":[{"symbol":"ETH/USD","bids":[{"price":3698.33,"qty":0.00000000},{"price":3697.10,"qty":4.02610258}],"asks":[],"checksum":2437174638,"timestamp":"2024-05-24T15:54:07.271439Z"}]}
{"channel":"book","type":"update","data":[{"symbol":"BTC/USD","bids":[{"price":68186.3,"qty":0.33750000}],"asks":[],"checksum":956333871,"timestamp":"2024-05-24T15:54:07.273632Z"}]}
{"channel":"book","type":"update","data":[{"symbol":"ETH/USD","bids":[{"price":3698.27,"qty":1.06833037}],"asks":[],"checksum":616103781,"timestamp":"2024-05-24T15:54:07.276471Z"}]}
{"channel":"book","type":"update","data":[{"symbol":"ETH/USD","bids":[{"price":3697.90,"qty":27.04236603}],"asks":[],"checksum":1506289830,"timestamp":"2024-05-24T15:54:07.276880Z"}]}
{"channel":"book","type":"update","data":[{"symbol":"BTC/USD","bids":[{"price":68185.0,"qty":0.00000000},{"price":68180.7,"qty":0.91220814}],"asks":[],"checksum":2074042411,"timestamp":"2024-05-24T15:54:07.290083Z"}]}
{"channel":"book","type":"update","data":[{"symbol":"ETH/USD","bids":[{"price":3697.90,"qty":0.00000000},{"price":3697.17,"qty":0.20000000}],"asks":[],"checksum":616103781,"timestamp":"2024-05-24T15:54:07.291810Z"}]}
{"channel":"book","type":"update","data":[{"symbol":"ETH/BTC","bids":[{"price":0.05423,"qty":1.11538488}],"asks":[],"checksum":2303757064,"timestamp":"2024-05-24T15:54:07.297531Z"}]}
{"channel":"book","type":"update","data":[{"symbol":"ETH/USD","bids":[{"price":3697.89,"qty":27.30442169}],"asks":[],"checksum":1228629824,"timestamp":"2024-05-24T15:54:07.297556Z"}]}
{"channel":"book","type":"update","data":[{"symbol":"ETH/USD","bids":[],"asks":[{"price":3698.53,"qty":57.80379348}],"checksum":1140060865,"timestamp":"2024-05-24T15:54:07.297578Z"}]}
{"channel":"book","type":"update","data":[{"symbol":"ETH/USD","bids":[],"asks":[{"price":3698.53,"qty":84.84156253}],"checksum":2775673748,"timestamp":"2024-05-24T15:54:07.297704Z"}]}
{"channel":"book","type":"update","data":[{"symbol":"ETH/BTC","bids":[{"price":0.05424,"qty":0.63661791},{"price":0.05423,"qty":1.12178168}],"asks":[],"checksum":1044161495,"timestamp":"2024-05-24T15:54:07.305357Z"}]}
{"channel":"book","type":"update","data":[{"symbol":"ETH/BTC","bids":[{"price":0.05424,"qty":0.18661791}],"asks":[],"checksum":2330057031,"timestamp":"2024-05-24T15:54:07.311379Z"}]}
{"channel":"book","type":"update","data":[{"symbol":"BTC/USD","bids":[],"asks":[{"price":68202.0,"qty":0.17890000}],"checksum":1428380887,"timestamp":"2024-05-24T15:54:07.311801Z"}]}
{"channel":"book","type":"update","data":[{"symbol":"BTC/USD","bids":[],"asks":[{"price":68205.0,"qty":0.00000000},{"price":68209.8,"qty":0.19080000}],"checksum":1559750967,"timestamp":"2024-05-24T15:54:07.311836Z"}]}
{"channel":"book","type":"update","data":[{"symbol":"BTC/USD","bids":[{"price":68199.0,"qty":0.00000000},{"price":68180.0,"qty":0.15000000}],"asks":[],"checksum":3766462079,"timestamp":"2024-05-24T15:54:07.311900Z"}]}
{"channel":"book","type":"update","data":[{"symbol":"BTC/USD","bids":[{"price":68186.3,"qty":0.00000000},{"price":68179.4,"qty":0.33750000}],"asks":[],"checksum":2093880264,"timestamp":"2024-05-24T15:54:07.341864Z"}]}
{"channel":"book","type":"update","data":[{"symbol":"BTC/USD","bids":[{"price":68189.0,"qty":0.00000000},{"price":68178.8,"qty":0.11607238}],"asks":[],"checksum":3302019940,"timestamp":"2024-05-24T15:54:07.352788Z"}]}
{"channel":"book","type":"update","data":[{"symbol":"BTC/USD","bids":[],"asks":[{"price":68209.7,"qty":0.91228454}],"checksum":1482164387,"timestamp":"2024-05-24T15:54:07.354597Z"}]}
{"channel":"book","type":"update","data":[{"symbol":"BTC/USD","bids":[{"price":68184.9,"qty":1.46659949}],"asks":[],"checksum":463318678,"timestamp":"2024-05-24T15:54:07.361443Z"}]}
{"channel":"book","type":"update","data":[{"symbol":"BTC/USD","bids":[{"price":68180.7,"qty":0.00000000},{"price":68178.8,"qty":0.11607238}],"asks":[],"checksum":1033696489,"timestamp":"2024-05-24T15:54:07.362672Z"}]}
{"channel":"book","type":"update","data":[{"symbol":"ETH/USD","bids":[{"price":3697.44,"qty":0.80132412}],"asks":[],"checksum":990295395,"timestamp":"2024-05-24T15:54:07.364943Z"}]}
{"channel":"book","type":"update","data":[{"symbol":"BTC/USD","bids":[],"asks":[{"price":68200.2,"qty":3.46522032}],"checksum":277625172,"timestamp":"2024-05-24T15:54:07.370830Z"}]}
{"channel":"book","type":"update","data":[{"symbol":"BTC/USD","bids":[{"price":68189.7,"qty":0.01353482}],"asks":[],"checksum":3581951371,"timestamp":"2024-05-24T15:54:07.382785Z"}]}
{"channel":"book","type":"update","data":[{"symbol":"BTC/USD","bids":[{"price":68184.9,"qty":1.54228949}],"asks":[],"checksum":3999321246,"timestamp":"2024-05-24T15:54:07.396979Z"}]}
{"channel":"book","type":"update","data":[{"symbol":"ETH/USD","bids":[{"price":3698.51,"qty":0.00000000},{"price":3697.17,"qty":0.20000000}],"asks":[],"checksum":1154545250,"timestamp":"2024-05-24T15:54:07.401519Z"}]}
{"channel":"book","type":"update","data":[{"symbol":"BTC/USD","bids":[{"price":68189.7,"qty":0.00000000},{"price":68178.8,"qty":0.11607238}],"asks":[],"checksum":1984636147,"timestamp":"2024-05-24T15:54:07.412420Z"}]}
{"channel":"book","type":"update","data":[{"symbol":"ETH/USD","bids":[{"price":3697.92,"qty":27.04221702}],"asks":[],"checksum":4018378693,"timestamp":"2024-05-24T15:54:07.432369Z"}]}
{"channel":"book","type":"update","data":[{"symbol":"ETH/USD","bids":[{"price":3697.67,"qty":27.04401878}],"asks":[],"checksum":2910344674,"timestamp":"2024-05-24T15:54:07.432566Z"}]}
{"channel":"book","type":"update","data":[{"symbol":"ETH/USD","bids":[{"price":3697.89,"qty":27.04239736}],"asks":[],"checksum":2498847514,"timestamp":"2024-05-24T15:54:07.454239Z"}]}
{"channel":"book","type":"update","data":[{"symbol":"ETH/USD","bids":[],"asks":[{"price":3698.89,"qty":1.53600000}],"checksum":3675270018,"timestamp":"2024-05-24T15:54:07.462693Z"}]}
{"channel":"book","type":"update","data":[{"symbol":"BTC/USD","bids":[],"asks":[{"price":68200.2,"qty":3.80272032}],"checksum":1497755840,"timestamp":"2024-05-24T15:54:07.464019Z"}]}
{"channel":"book","type":"update","data":[{"symbol":"ETH/USD","bids":[{"price":3697.92,"qty":0.00000000},{"price":3697.32,"qty":6.70000000}],"asks":[],"checksum":1264249389,"timestamp":"2024-05-24T15:54:07.464148Z"}]}
{"channel":"book","type":"update","data":[{"symbol":"ETH/USD","bids":[{"price":3697.59,"qty":8.44034963}],"asks":[],"checksum":286807839,"timestamp":"2024-05-24T15:54:07.475353Z"}]}
{"channel":"book","type":"update","data":[{"symbol":"BTC/USD","bids":[{"price":68184.9,"qty":0.07569000}],"asks":[],"checksum":3253346462,"timestamp":"2024-05-24T15:54:07.478968Z"}]}
{"channel":"book","type":"update","data":[{"symbol":"ETH/USD","bids":[{"price":3697.94,"qty":27.04202649}],"asks":[],"checksum":2876938281,"timestamp":"2024-05-24T15:54:07.482491Z"}]}
{"channel":"book","type":"update","data":[{"symbol":"BTC/USD","bids":[{"price":68184.7,"qty":1.46660433}],"asks":[],"checksum":2202746332,"timestamp":"2024-05-24T15:54:07.482762Z"}]}
{"channel":"book","type":"update","data":[{"symbol":"BTC/USD","bids":[],"asks":[{"price":68200.2,"qty":3.46522032}],"checksum":3806562784,"timestamp":"2024-05-24T15:54:07.485829Z"}]}
{"channel":"book","type":"update","data":[{"symbol":"ETH/BTC","bids":[],"asks":[{"price":0.05427,"qty":16.74879978}],"checksum":2959466919,"timestamp":"2024-05-24T15:54:07.487874Z"}]}
{"channel":"book","type":"update","data":[{"symbol":"ETH/BTC","bids":[],"asks":[{"price":0.05426,"qty":24.85492371}],"checksum":1614331406,"timestamp":"2024-05-24T15:54:07.488094Z"}]}
{"channel":"book","type":"update","data":[{"symbol":"ETH/USD","bids":[{"price":3697.94,"qty":0.00000000},{"price":3697.43,"qty":2.11000000}],"asks":[],"checksum":286807839,"timestamp":"2024-05-24T15:54:07.488529Z"}]}
{"channel":"book","type":"update","data":[{"symbol":"BTC/USD","bids":[{"price":68181.1,"qty":0.02195702}],"asks":[],"checksum":2266886514,"timestamp":"2024-05-24T15:54:07.494792Z"}]}
{"channel":"book","type":"update","data":[{"symbol":"BTC/USD","bids":[],"asks":[{"price":68200.2,"qty":3.12772032}],"checksum":314859051,"timestamp":"2024-05-24T15:54:07.501935Z"}]}
{"channel":"book","type":"update","data":[{"symbol":"ETH/USD","bids":[],"asks":[{"price":3698.99,"qty":0.40087922}],"checksum":1412178504,"timestamp":"2024-05-24T15:54:07.520798Z"}]}
{"channel":"book","type":"update","data":[{"symbol":"ETH/USD","bids":[{"price":3697.97,"qty":27.04183240}],"asks":[],"checksum":1170276496,"timestamp":"2024-05-24T15:54:07.552604Z"}]}
{"channel":"book","type":"update","data":[{"symbol":"ETH/USD","bids":[{"price":3697.97,"qty":0.00000000},{"price":3697.43,"qty":2.11000000}],"asks":[],"checksum":1412178504,"timestamp":"2024-05-24T15:54:07.555961Z"}]}
{"channel":"book","type":"update","data":[{"symbol":"ETH/BTC","bids":[{"price":0.05422,"qty":18.11829247}],"asks":[],"checksum":4289960309,"timestamp":"2024-05-24T15:54:07.577724Z"}]}
{"channel":"book","type":"update","data":[{"symbol":"ETH/BTC","bids":[{"price":0.05422,"qty":20.82229953}],"asks":[],"checksum":855861835,"timestamp":"2024-05-24T15:54:07.577855Z"}]}
{"channel":"book","type":"update","data":[{"symbol":"ETH/USD","bids":[{"price":3697.67,"qty":0.00000000},{"price":3697.32,"qty":6.70000000}],"asks":[],"checksum":581464754,"timestamp":"2024-05-24T15:54:07.578336Z"}]}
{"channel":"book","type":"update","data":[{"symbol":"ETH/USD","bids":[{"price":3697.89,"qty":0.00000000},{"price":3697.17,"qty":0.20000000}],"asks":[],"checksum":3503829269,"timestamp":"2024-05-24T15:54:07.578524Z"}]}
{"channel":"book","type":"update","data":[{"symbol":"BTC/USD","bids":[{"price":68184.7,"qty":0.00000000},{"price":68179.4,"qty":0.33750000}],"asks":[],"checksum":1948309178,"timestamp":"2024-05-24T15:54:07.578657Z"}]}
{"channel":"book","type":"update","data":[{"symbol":"BTC/USD","bids":[{"price":68183.4,"qty":0.00035492}],"asks":[],"checksum":1638994234,"timestamp":"2024-05-24T15:54:07.578824Z"}]}
{"channel":"book","type":"update","data":[{"symbol":"BTC/USD","bids":[{"price":68185.3,"qty":1.46658996}],"asks":[],"checksum":2820490382,"timestamp":"2024-05-24T15:54:07.587170Z"}]}
{"channel":"book","type":"update","data":[{"symbol":"ETH/BTC","bids":[{"price":0.05423,"qty":5.12178168}],"asks":[],"checksum":33057279,"timestamp":"2024-05-24T15:54:07.590704Z"}]}
{"channel":"book","type":"update","data":[{"symbol":"ETH/BTC","bids":[{"price":0.05424,"qty":0.63661791}],"asks":[],"checksum":3039105903,"timestamp":"2024-05-24T15:54:07.594839Z"}]}
{"channel":"book","type":"update","data":[{"symbol":"BTC/USD","bids":[],"asks":[{"price":68200.2,"qty":3.12989060}],"checksum":483885653,"timestamp":"2024-05-24T15:54:07.644035Z"}]}
{"channel":"book","type":"update","data":[{"symbol":"ETH/USD","bids":[{"price":3697.45,"qty":27.04562508}],"asks":[],"checksum":3156140344,"timestamp":"2024-05-24T15:54:07.645222Z"}]}
{"channel":"book","type":"update","data":[{"symbol":"ETH/USD","bids":[{"price":3698.02,"qty":27.04144646}],"asks":[],"checksum":814777920,"timestamp":"2024-05-24T15:54:07.645321Z"}]}
{"channel":"book","type":"update","data":[{"symbol":"BTC/USD","bids":[{"price":68185.3,"qty":0.00000000},{"price":68179.4,"qty":0.33750000}],"asks":[],"checksum":2697592262,"timestamp":"2024-05-24T15:54:07.645605Z"}]}
{"channel":"book","type":"update","data":[{"symbol":"BTC/USD","bids":[{"price":68185.5,"qty":1.46658730}],"asks":[],"checksum":4093407382,"timestamp":"2024-05-24T15:54:07.649626Z"}]}
{"channel":"book","type":"update","data":[{"symbol":"ETH/USD","bids":[{"price":3697.76,"qty":0.20498878}],"asks":[],"checksum":661755987,"timestamp":"2024-05-24T15:54:07.665420Z"}]}
{"channel":"book","type":"update","data":[{"symbol":"ETH/USD","bids":[{"price":3698.02,"qty":0.00000000},{"price":3697.43,"qty":2.11000000}],"asks":[],"checksum":1369162229,"timestamp":"2024-05-24T15:54:07.668884Z"}]}
{"channel":"book","type":"update","data":[{"symbol":"BTC/USD","bids":[{"price":68185.5,"qty":0.00000000},{"price":68179.4,"qty":0.33750000}],"asks":[],"checksum":2697592262,"timestamp":"2024-05-24T15:54:07.687650Z"}]}
{"channel":"book","type":"update","data":[{"symbol":"ETH/USD","bids":[{"price":3697.83,"qty":0.00000000},{"price":3697.32,"qty":6.70000000}],"asks":[],"checksum":3906254747,"timestamp":"2024-05-24T15:54:07.705530Z"}]}
{"channel":"book","type":"update","data":[{"symbol":"ETH/USD","bids":[{"price":3697.66,"qty":4.02610258}],"asks":[],"checksum":2320101203,"timestamp":"2024-05-24T15:54:07.708597Z"}]}
{"channel":"book","type":"update","data":[{"symbol":"BTC/USD","bids":[],"asks":[{"price":68200.2,"qty":3.46739060}],"checksum":765385758,"timestamp":"2024-05-24T15:54:07.721377Z"}]}
{"channel":"book","type":"update","data":[{"symbol":"BTC/USD","bids":[{"price":68185.5,"qty":1.46658592}],"asks":[],"checksum":166402124,"timestamp":"2024-05-24T15:54:07.723403Z"}]}
{"channel":"book","type":"update","data":[{"symbol":"ETH/USD","bids":[],"asks":[{"price":3698.79,"qty":27.03586848}],"checksum":3040934744,"timestamp":"2024-05-24T15:54:07.723619Z"}]}
{"channel":"book","type":"update","data":[{"symbol":"ETH/USD","bids":[{"price":3698.02,"qty":27.04144376}],"asks":[],"checksum":3129576605,"timestamp":"2024-05-24T15:54:07.723764Z"}]}
{"channel":"book","type":"update","data":[{"symbol":"BTC/USD","bids":[{"price":68185.5,"qty":0.00000000},{"price":68179.4,"qty":0.33750000}],"asks":[],"checksum":765385758,"timestamp":"2024-05-24T15:54:07.738858Z"}]}
{"channel":"book","type":"update","data":[{"symbol":"ETH/USD","bids":[{"price":3698.02,"qty":0.00000000},{"price":3697.43,"qty":2.11000000}],"asks":[],"checksum":3040934744,"timestamp":"2024-05-24T15:54:07.738955Z"}]}
{"channel":"book","type":"update","data":[{"symbol":"ETH/USD","bids":[{"price":3697.66,"qty":0.00000000},{"price":3697.32,"qty":6.70000000}],"asks":[],"checksum":3621626768,"timestamp":"2024-05-24T15:54:07.741890Z"}]}
{"channel":"book","type":"update","data":[{"symbol":"ETH/USD","bids":[{"price":3697.92,"qty":27.04217813}],"asks":[],"checksum":511283477,"timestamp":"2024-05-24T15:54:07.742479Z"}]}
{"channel":"book","type":"update","data":[{"symbol":"ETH/USD","bids":[{"price":3697.76,"qty":27.24831691}],"asks":[],"checksum":2806059256,"timestamp":"2024-05-24T15:54:07.742617Z"}]}
{"channel":"book","type":"update","data":[{"symbol":"BTC/USD","bids":[],"asks":[{"price":68200.2,"qty":3.12989060}],"checksum":2697592262,"timestamp":"2024-05-24T15:54:07.749845Z"}]}
{"channel":"book","type":"update","data":[{"symbol":"ETH/USD","bids":[{"price":3697.92,"qty":0.00000000},{"price":3697.32,"qty":6.70000000}],"asks":[],"checksum":1099387848,"timestamp":"2024-05-24T15:54:07.786124Z"}]}
{"channel":"book","type":"update","data":[{"symbol":"BTC/USD","bids":[{"price":68185.5,"qty":1.46658680}],"asks":[],"checksum":1412678492,"timestamp":"2024-05-24T15:54:07.786303Z"}]}
{"channel":"book","type":"update","data":[{"symbol":"ETH/BTC","bids":[{"price":0.05423,"qty":5.11538488},{"price":0.05424,"qty":0.64301353}],"asks":[],"checksum":680925837,"timestamp":"2024-05-24T15:54:07.787626Z"}]}
{"channel":"book","type":"update","data":[{"symbol":"ETH/USD","bids":[{"price":3698.02,"qty":27.04145999}],"asks":[],"checksum":3620570989,"timestamp":"2024-05-24T15:54:07.789626Z"}]}
{"channel":"book","type":"update","data":[{"symbol":"ETH/USD","bids":[{"price":3698.02,"qty":0.00000000},{"price":3697.32,"qty":6.70000000}],"asks":[],"checksum":1099387848,"timestamp":"2024-05-24T15:54:07.794569Z"}]}
{"channel":"book","type":"update","data":[{"symbol":"ETH/BTC","bids":[{"price":0.05417,"qty":14.47418911}],"asks":[],"checksum":2685795698,"timestamp":"2024-05-24T15:54:07.828927Z"}]}
{"channel":"book","type":"update","data":[{"symbol":"ETH/USD","bids":[{"price":3698.03,"qty":27.04141131}],"asks":[],"checksum":327970023,"timestamp":"2024-05-24T15:54:07.869549Z"}]}
{"channel":"book","type":"update","data":[{"symbol":"BTC/USD","bids":[{"price":68183.5,"qty":1.41223928}],"asks":[],"checksum":1313792011,"timestamp":"2024-05-24T15:54:07.898241Z"}]}
{"channel":"book","type":"update","data":[{"symbol":"ETH/USD","bids":[{"price":3697.90,"qty":3.34232335}],"asks":[],"checksum":928026241,"timestamp":"2024-05-24T15:54:07.898488Z"}]}
{"channel":"book","type":"update","data":[{"symbol":"ETH/USD","bids":[{"price":3697.46,"qty":4.02610258}],"asks":[],"checksum":3141316277,"timestamp":"2024-05-24T15:54:07.901914Z"}]}
{"channel":"book","type":"update","data":[{"symbol":"ETH/USD","bids":[{"price":3698.03,"qty":0.00000000},{"price":3697.44,"qty":0.80132412}],"asks":[],"checksum":345245739,"timestamp":"2024-05-24T15:54:07.959806Z"}]}
{"channel":"book","type":"update","data":[{"symbol":"BTC/USD","bids":[{"price":68185.5,"qty":0.00000000},{"price":68180.0,"qty":0.15000000}],"asks":[],"checksum":4112597605,"timestamp":"2024-05-24T15:54:07.960671Z"}]}
{"channel":"book","type":"update","data":[{"symbol":"ETH/USD","bids":[{"price":3697.46,"qty":0.00000000},{"price":3697.43,"qty":2.11000000},{"price":3697.77,"qty":4.02610258}],"asks":[],"checksum":1424345794,"timestamp":"2024-05-24T15:54:07.962992Z"}]}
{"channel":"book","type":"update","data":[{"symbol":"ETH/USD","bids":[{"price":3698.00,"qty":27.04160332}],"asks":[],"checksum":1904841865,"timestamp":"2024-05-24T15:54:07.963632Z"}]}
{"channel":"book","type":"update","data":[{"symbol":"BTC/USD","bids":[{"price":68185.0,"qty":1.46659612}],"asks":[],"checksum":585946123,"timestamp":"2024-05-24T15:54:07.964417Z"}]}
{"channel":"book","type":"update","data":[{"symbol":"BTC/USD","bids":[{"price":68183.8,"qty":1.46662388}],"asks":[],"checksum":2888436282,"timestamp":"2024-05-24T15:54:07.964619Z"}]}
{"channel":"book","type":"update","data":[{"symbol":"ETH/BTC","bids":[{"price":0.05424,"qty":0.63661791},{"price":0.05423,"qty":5.12178167}],"asks":[],"checksum":61156936,"timestamp":"2024-05-24T15:54:07.965054Z"}]}
{"channel":"book","type":"update","data":[{"symbol":"ETH/USD","bids":[{"price":3698.00,"qty":0.00000000},{"price":3697.44,"qty":0.80132412}],"asks":[],"checksum":1424345794,"timestamp":"2024-05-24T15:54:07.967635Z"}]}
{"channel":"book","type":"update","data":[{"symbol":"BTC/USD","bids":[{"price":68185.0,"qty":0.00000000},{"price":68181.0,"qty":1.46668408}],"asks":[],"checksum":473318197,"timestamp":"2024-05-24T15:54:07.968155Z"}]}
{"channel":"book","type":"update","data":[{"symbol":"BTC/USD","bids":[{"price":68183.9,"qty":0.00247922}],"asks":[],"checksum":466195083,"timestamp":"2024-05-24T15:54:07.984605Z"}]}
{"channel":"book","type":"update","data":[{"symbol":"ETH/USD","bids":[{"price":3697.90,"qty":30.38469402}],"asks":[],"checksum":2641950676,"timestamp":"2024-05-24T15:54:07.992183Z"}]}
{"channel":"book","type":"update","data":[{"symbol":"ETH/USD","bids":[{"price":3697.77,"qty":0.00000000},{"price":3697.43,"qty":2.11000000},{"price":3697.91,"qty":4.02610258}],"asks":[],"checksum":3696238359,"timestamp":"2024-05-24T15:54:07.995235Z"}]}
{"channel":"book","type":"update","data":[{"symbol":"BTC/USD","bids":[{"price":68184.9,"qty":1.54229018}],"asks":[],"checksum":3173495542,"timestamp":"2024-05-24T15:54:08.024098Z"}]}
{"channel":"book","type":"update","data":[{"symbol":"BTC/USD","bids":[{"price":68184.9,"qty":0.07569000}],"asks":[],"checksum":466195083,"timestamp":"2024-05-24T15:54:08.028184Z"}]}
{"channel":"book","type":"update","data":[{"symbol":"ETH/USD","bids":[{"price":3697.97,"qty":27.04184724}],"asks":[],"checksum":3881812988,"timestamp":"2024-05-24T15:54:08.028415Z"}]}
{"channel":"book","type":"update","data":[{"symbol":"ETH/USD","bids":[{"price":3697.90,"qty":3.34232335}],"asks":[],"checksum":2719189235,"timestamp":"2024-05-24T15:54:08.028459Z"}]}
{"channel":"book","type":"update","data":[{"symbol":"ETH/USD","bids":[{"price":3697.91,"qty":0.00000000},{"price":3697.44,"qty":0.80132412},{"price":3697.46,"qty":4.02610258}],"asks":[],"checksum":3560937351,"timestamp":"2024-05-24T15:54:08.031691Z"}]}
{"channel":"book","type":"update","data":[{"symbol":"ETH/BTC","bids":[{"price":0.05423,"qty":5.11538488},{"price":0.05424,"qty":0.64301353}],"asks":[],"checksum":2685795698,"timestamp":"2024-05-24T15:54:08.047589Z"}]}
{"channel":"book","type":"update","data":[{"symbol":"ETH/USD","bids":[{"price":3697.45,"qty":0.00000000},{"price":3697.44,"qty":0.80132412}],"asks":[],"checksum":1841165387,"timestamp":"2024-05-24T15:54:08.051419Z"}]}
{"channel":"book","type":"update","data":[{"symbol":"BTC/USD","bids":[],"asks":[{"price":68202.0,"qty":0.00000000},{"price":68209.8,"qty":0.19080000}],"checksum":1380545806,"timestamp":"2024-05-24T15:54:08.062148Z"}]}
{"channel":"book","type":"update","data":[{"symbol":"BTC/USD","bids":[],"asks":[{"price":68203.0,"qty":0.17890000}],"checksum":4147960875,"timestamp":"2024-05-24T15:54:08.062257Z"}]}
{"channel":"book","type":"update","data":[{"symbol":"ETH/USD","bids":[{"price":3697.46,"qty":0.00000000},{"price":3697.43,"qty":2.11000000}],"asks":[],"checksum":294205897,"timestamp":"2024-05-24T15:54:08.065320Z"}]}
{"channel":"book","type":"update","data":[{"symbol":"BTC/USD","bids":[],"asks":[{"price":68203.0,"qty":0.00000000},{"price":68209.8,"qty":0.19080000}],"checksum":1380545806,"timestamp":"2024-05-24T15:54:08.067717Z"}]}
{"channel":"book","type":"update","data":[{"symbol":"BTC/USD","bids":[{"price":68181.1,"qty":0.00000000},{"price":68181.0,"qty":1.46668408}],"asks":[],"checksum":442187987,"timestamp":"2024-05-24T15:54:08.079963Z"}]}
{"channel":"book","type":"update","data":[{"symbol":"ETH/USD","bids":[{"price":3698.05,"qty":27.04123382}],"asks":[],"checksum":3240886590,"timestamp":"2024-05-24T15:54:08.080966Z"}]}
{"channel":"book","type":"update","data":[{"symbol":"ETH/BTC","bids":[{"price":0.05420,"qty":0.69843484},{"price":0.05418,"qty":17.66488571}],"asks":[],"checksum":3680503571,"timestamp":"2024-05-24T15:54:08.081549Z"}]}
{"channel":"book","type":"update","data":[{"symbol":"ETH/USD","bids":[],"asks":[{"price":3698.61,"qty":4.05584082}],"checksum":3582096816,"timestamp":"2024-05-24T15:54:08.084284Z"}]}
{"channel":"book","type":"update","data":[{"symbol":"ETH/USD","bids":[{"price":3698.05,"qty":0.00000000},{"price":3697.43,"qty":2.11000000}],"asks":[],"checksum":3198286037,"timestamp":"2024-05-24T15:54:08.084891Z"}]}
{"channel":"book","type":"update","data":[{"symbol":"ETH/BTC","bids":[],"asks":[{"price":0.05430,"qty":1.45900000}],"checksum":1150595243,"timestamp":"2024-05-24T15:54:08.104443Z"}]}
{"channel":"book","type":"update","data":[{"symbol":"ETH/BTC","bids":[],"asks":[{"price":0.05430,"qty":26.90242687}],"checksum":1776724506,"timestamp":"2024-05-24T15:54:08.110872Z"}]}
{"channel":"book","type":"update","data":[{"symbol":"ETH/USD","bids":[{"price":3697.90,"qty":0.00000000},{"price":3697.32,"qty":6.70000000}],"asks":[],"checksum":1114199623,"timestamp":"2024-05-24T15:54:08.117584Z"}]}
{"channel":"book","type":"update","data":[{"symbol":"ETH/BTC","bids":[{"price":0.05418,"qty":16.61927322},{"price":0.05419,"qty":4.61295023}],"asks":[],"checksum":1190502602,"timestamp":"2024-05-24T15:54:08.139297Z"}]}
{"channel":"book","type":"update","data":[{"symbol":"ETH/USD","bids":[{"price":3697.59,"qty":35.48497361}],"asks":[],"checksum":2390995402,"timestamp":"2024-05-24T15:54:08.153036Z"}]}
{"channel":"book","type":"update","data":[{"symbol":"ETH/USD","bids":[{"price":3698.04,"qty":27.04127979}],"asks":[],"checksum":1200621422,"timestamp":"2024-05-24T15:54:08.153119Z"}]}
{"channel":"book","type":"update","data":[{"symbol":"BTC/USD","bids":[{"price":68185.4,"qty":1.46658933}],"asks":[],"checksum":3127975658,"timestamp":"2024-05-24T15:54:08.154684Z"}]}
{"channel":"book","type":"update","data":[{"symbol":"BTC/USD","bids":[{"price":68185.4,"qty":0.00000000},{"price":68181.0,"qty":1.46668408}],"asks":[],"checksum":442187987,"timestamp":"2024-05-24T15:54:08.161988Z"}]}
{"channel":"book","type":"update","data":[{"symbol":"ETH/USD","bids":[{"price":3698.04,"qty":0.00000000},{"price":3697.32,"qty":6.70000000}],"asks":[],"checksum":2390995402,"timestamp":"2024-05-24T15:54:08.168013Z"}]}
{"channel":"book","type":"update","data":[{"symbol":"BTC/USD","bids":[],"asks":[{"price":68200.2,"qty":3.46739060}],"checksum":2464042260,"timestamp":"2024-05-24T15:54:08.189563Z"}]}
{"channel":"book","type":"update","data":[{"symbol":"ETH/USD","bids":[{"price":3697.97,"qty":0.00000000},{"price":3697.17,"qty":0.20000000}],"asks":[],"checksum":3216336281,"timestamp":"2024-05-24T15:54:08.198851Z"}]}
{"channel":"book","type":"update","data":[{"symbol":"ETH/USD","bids":[{"price":3697.77,"qty":4.02610258}],"asks":[],"checksum":2516849323,"timestamp":"2024-05-24T15:54:08.203770Z"}]}
{"channel":"book","type":"update","data":[{"symbol":"BTC/USD","bids":[{"price":68182.6,"qty":1.46664939}],"asks":[],"checksum":4177357961,"timestamp":"2024-05-24T15:54:08.206013Z"}]}
{"channel":"book","type":"update","data":[{"symbol":"BTC/USD","bids":[{"price":68183.8,"qty":0.00000000},{"price":68181.0,"qty":1.46668408}],"asks":[],"checksum":2011541439,"timestamp":"2024-05-24T15:54:08.220182Z"}]}
{"channel":"book","type":"update","data":[{"symbol":"BTC/USD","bids":[{"price":68184.3,"qty":1.46661279}],"asks":[],"checksum":1119097880,"timestamp":"2024-05-24T15:54:08.225033Z"}]}
{"channel":"book","type":"update","data":[{"symbol":"BTC/USD","bids":[{"price":68183.9,"qty":0.00000000},{"price":68181.0,"qty":1.46668408},{"price":68183.6,"qty":0.00247923}],"asks":[],"checksum":2452367246,"timestamp":"2024-05-24T15:54:08.226978Z"}]}
{"channel":"book","type":"update","data":[{"symbol":"ETH/USD","bids":[{"price":3698.52,"qty":0.00000000},{"price":3697.17,"qty":0.20000000},{"price":3698.28,"qty":0.02666033}],"asks":[],"checksum":1472866210,"timestamp":"2024-05-24T15:54:08.259163Z"}]}
{"channel":"book","type":"update","data":[{"symbol":"BTC/USD","bids":[{"price":68184.3,"qty":0.00000000},{"price":68181.0,"qty":1.46668408}],"asks":[],"checksum":2594115738,"timestamp":"2024-05-24T15:54:08.262309Z"}]}
{"channel":"book","type":"update","data":[{"symbol":"ETH/USD","bids":[],"asks":[{"price":3698.52,"qty":0.04046589}],"checksum":1838479118,"timestamp":"2024-05-24T15:54:08.262844Z"}]}
{"channel":"book","type":"update","data":[{"symbol":"ETH/USD","bids":[],"asks":[{"price":3698.35,"qty":3.18750000}],"checksum":3904125619,"timestamp":"2024-05-24T15:54:08.262967Z"}]}
{"channel":"book","type":"update","data":[{"symbol":"ETH/USD","bids":[],"asks":[{"price":3698.62,"qty":0.00000000},{"price":3698.99,"qty":0.40087922}],"checksum":2236424784,"timestamp":"2024-05-24T15:54:08.263035Z"}]}
{"channel":"book","type":"update","data":[{"symbol":"ETH/USD","bids":[],"asks":[{"price":3698.53,"qty":57.80379348}],"checksum":1340522691,"timestamp":"2024-05-24T15:54:08.263585Z"}]}
{"channel":"book","type":"update","data":[{"symbol":"ETH/USD","bids":[],"asks":[{"price":3698.53,"qty":30.76602443}],"checksum":2299494664,"timestamp":"2024-05-24T15:54:08.263635Z"}]}
{"channel":"book","type":"update","data":[{"symbol":"ETH/USD","bids":[],"asks":[{"price":3698.53,"qty":30.22526905},{"price":3698.52,"qty":0.58122273}],"checksum":2711153279,"timestamp":"2024-05-24T15:54:08.263761Z"}]}
{"channel":"book","type":"update","data":[{"symbol":"ETH/USD","bids":[{"price":3698.34,"qty":0.26595425}],"asks":[],"checksum":1308243312,"timestamp":"2024-05-24T15:54:08.264703Z"}]}
{"channel":"book","type":"update","data":[{"symbol":"ETH/USD","bids":[],"asks":[{"price":3698.52,"qty":0.54075684}],"checksum":1506799459,"timestamp":"2024-05-24T15:54:08.266632Z"}]}
{"channel":"book","type":"update","data":[{"symbol":"ETH/USD","bids":[{"price":3697.97,"qty":1.62232097}],"asks":[],"checksum":306530591,"timestamp":"2024-05-24T15:54:08.267809Z"}]}
{"channel":"book","type":"update","data":[{"symbol":"ETH/USD","bids":[],"asks":[{"price":3698.57,"qty":0.39584631}],"checksum":4015484555,"timestamp":"2024-05-24T15:54:08.268040Z"}]}
{"channel":"book","type":"update","data":[{"symbol":"ETH/USD","bids":[],"asks":[{"price":3698.53,"qty":3.18750000}],"checksum":4187805591,"timestamp":"2024-05-24T15:54:08.269530Z"}]}
{"channel":"book","type":"update","data":[{"symbol":"ETH/USD","bids":[],"asks":[{"price":3698.35,"qty":30.22658499}],"checksum":371269156,"timestamp":"2024-05-24T15:54:08.273901Z"}]}
{"channel":"book","type":"update","data":[{"symbol":"ETH/USD","bids":[{"price":3697.96,"qty":27.04189682}],"asks":[],"checksum":3506315947,"timestamp":"2024-05-24T15:54:08.273924Z"}]}
{"channel":"book","type":"update","data":[{"symbol":"ETH/USD","bids":[],"asks":[{"price":3698.51,"qty":27.03791526}],"checksum":923114497,"timestamp":"2024-05-24T15:54:08.273937Z"}]}
{"channel":"book","type":"update","data":[{"symbol":"ETH/USD","bids":[],"asks":[{"price":3698.35,"qty":57.26566998}],"checksum":1597670066,"timestamp":"2024-05-24T15:54:08.274115Z"}]}
{"channel":"book","type":"update","data":[{"symbol":"BTC/USD","bids":[{"price":68182.6,"qty":0.00000000},{"price":68180.0,"qty":0.15000000}],"asks":[],"checksum":2440435673,"timestamp":"2024-05-24T15:54:08.298874Z"}]}
{"channel":"book","type":"update","data":[{"symbol":"BTC/USD","bids":[{"price":68183.6,"qty":0.00000000},{"price":68179.4,"qty":0.33750000}],"asks":[],"checksum":2142494115,"timestamp":"2024-05-24T15:54:08.302828Z"}]}
{"channel":"book","type":"update","data":[{"symbol":"BTC/USD","bids":[{"price":68184.7,"qty":1.46660362}],"asks":[],"checksum":4044834978,"timestamp":"2024-05-24T15:54:08.303351Z"}]}
{"channel":"book","type":"update","data":[{"symbol":"BTC/USD","bids":[],"asks":[{"price":68200.2,"qty":3.12989060}],"checksum":186514707,"timestamp":"2024-05-24T15:54:08.312040Z"}]}
{"channel":"book","type":"update","data":[{"symbol":"ETH/BTC","bids":[{"price":0.05423,"qty":1.11538488}],"asks":[],"checksum":1704654822,"timestamp":"2024-05-24T15:54:08.312890Z"}]}
{"channel":"book","type":"update","data":[{"symbol":"ETH/BTC","bids":[{"price":0.05424,"qty":0.63661791},{"price":0.05423,"qty":1.12178362}],"asks":[],"checksum":2797204219,"timestamp":"2024-05-24T15:54:08.316879Z"}]}
{"channel":"book","type":"update","data":[{"symbol":"BTC/USD","bids":[{"price":68184.7,"qty":0.00000000},{"price":68179.4,"qty":0.33750000}],"asks":[],"checksum":2050691005,"timestamp":"2024-05-24T15:54:08.342294Z"}]}
{"channel":"book","type":"update","data":[{"symbol":"ETH/USD","bids":[{"price":3697.96,"qty":0.00000000},{"price":3697.44,"qty":0.80132412}],"asks":[],"checksum":4183080069,"timestamp":"2024-05-24T15:54:08.343467Z"}]}
{"channel":"book","type":"update","data":[{"symbol":"ETH/USD","bids":[{"price":3698.00,"qty":27.04163449}],"asks":[],"checksum":3960447052,"timestamp":"2024-05-24T15:54:08.347558Z"}]}
{"channel":"book","type":"update","data":[{"symbol":"BTC/USD","bids":[{"price":68186.3,"qty":0.33750000}],"asks":[],"checksum":439289751,"timestamp":"2024-05-24T15:54:08.398987Z"}]}
{"channel":"book","type":"update","data":[{"symbol":"ETH/USD","bids":[{"price":3698.00,"qty":0.00000000},{"price":3697.44,"qty":0.80132412}],"asks":[],"checksum":4183080069,"timestamp":"2024-05-24T15:54:08.411517Z"}]}
{"channel":"book","type":"update","data":[{"symbol":"BTC/USD","bids":[{"price":68184.7,"qty":1.46660274}],"asks":[],"checksum":299743391,"timestamp":"2024-05-24T15:54:08.412489Z"}]}
{"channel":"book","type":"update","data":[{"symbol":"ETH/USD","bids":[{"price":3697.89,"qty":27.04244459}],"asks":[],"checksum":2750449333,"timestamp":"2024-05-24T15:54:08.415424Z"}]}
{"channel":"book","type":"update","data":[{"symbol":"ETH/USD","bids":[{"price":3697.95,"qty":27.04195361}],"asks":[],"checksum":4151078287,"timestamp":"2024-05-24T15:54:08.415613Z"}]}
{"channel":"book","type":"update","data":[{"symbol":"ETH/USD","bids":[],"asks":[{"price":3698.75,"qty":0.40085380}],"checksum":1922221359,"timestamp":"2024-05-24T15:54:08.498986Z"}]}
{"channel":"book","type":"update","data":[{"symbol":"ETH/USD","bids":[{"price":3697.95,"qty":0.00000000},{"price":3697.59,"qty":35.48497361}],"asks":[],"checksum":638463509,"timestamp":"2024-05-24T15:54:08.524762Z"}]}
{"channel":"book","type":"update","data":[{"symbol":"ETH/USD","bids":[{"price":3697.96,"qty":27.04193468}],"asks":[],"checksum":1200238069,"timestamp":"2024-05-24T15:54:08.529274Z"}]}
{"channel":"book","type":"update","data":[{"symbol":"ETH/USD","bids":[{"price":3697.89,"qty":0.00000000},{"price":3697.59,"qty":35.48497361}],"asks":[],"checksum":4167138960,"timestamp":"2024-05-24T15:54:08.585054Z"}]}
{"channel":"book","type":"update","data":[{"symbol":"ETH/USD","bids":[{"price":3697.99,"qty":27.04169128}],"asks":[],"checksum":3210431003,"timestamp":"2024-05-24T15:54:08.589059Z"}]}
{"channel":"book","type":"update","data":[{"symbol":"ETH/USD","bids":[],"asks":[{"price":3698.75,"qty":4.45669462}],"checksum":4207373161,"timestamp":"2024-05-24T15:54:08.593269Z"}]}
{"channel":"book","type":"update","data":[{"symbol":"BTC/USD","bids":[{"price":68200.1,"qty":11.96515600}],"asks":[],"checksum":1251941773,"timestamp":"2024-05-24T15:54:08.607573Z"}]}
{"channel":"book","type":"update","data":[{"symbol":"ETH/USD","bids":[{"price":3697.99,"qty":0.00000000},{"price":3697.59,"qty":35.48497361}],"asks":[],"checksum":3187498978,"timestamp":"2024-05-24T15:54:08.616808Z"}]}
{"channel":"book","type":"update","data":[{"symbol":"ETH/USD","bids":[{"price":3697.88,"qty":27.04246623}],"asks":[],"checksum":2883651690,"timestamp":"2024-05-24T15:54:08.637232Z"}]}
{"channel":"book","type":"update","data":[{"symbol":"ETH/USD","bids":[{"price":3697.96,"qty":0.00000000},{"price":3697.59,"qty":35.48497361}],"asks":[],"checksum":491313731,"timestamp":"2024-05-24T15:54:08.639933Z"}]}
{"channel":"book","type":"update","data":[{"symbol":"BTC/USD","bids":[{"price":68184.7,"qty":0.00000000},{"price":68180.0,"qty":0.15000000}],"asks":[],"checksum":2250508328,"timestamp":"2024-05-24T15:54:08.644480Z"}]}
{"channel":"book","type":"update","data":[{"symbol":"ETH/USD","bids":[{"price":3697.88,"qty":0.00000000},{"price":3697.44,"qty":0.80132412}],"asks":[],"checksum":285219117,"timestamp":"2024-05-24T15:54:08.646619Z"}]}
{"channel":"book","type":"update","data":[{"symbol":"BTC/USD","bids":[{"price":68185.1,"qty":1.46659508}],"asks":[],"checksum":4060152383,"timestamp":"2024-05-24T15:54:08.648632Z"}]}
{"channel":"book","type":"update","data":[{"symbol":"ETH/USD","bids":[],"asks":[{"price":3698.35,"qty":30.22658499}],"checksum":70377444,"timestamp":"2024-05-24T15:54:08.651074Z"}]}
{"channel":"book","type":"update","data":[{"symbol":"ETH/USD","bids":[],"asks":[{"price":3698.35,"qty":3.18750000}],"checksum":1454800923,"timestamp":"2024-05-24T15:54:08.651130Z"}]}
{"channel":"book","type":"update","data":[{"symbol":"ETH/USD","bids":[],"asks":[{"price":3698.35,"qty":0.00000000},{"price":3698.89,"qty":1.53600000}],"checksum":605217912,"timestamp":"2024-05-24T15:54:08.654601Z"}]}
{"channel":"book","type":"update","data":[{"symbol":"ETH/USD","bids":[{"price":3698.07,"qty":27.04109488}],"asks":[],"checksum":399980471,"timestamp":"2024-05-24T15:54:08.655257Z"}]}
{"channel":"book","type":"update","data":[{"symbol":"ETH/USD","bids":[],"asks":[{"price":3698.60,"qty":27.03727782}],"checksum":3866520469,"timestamp":"2024-05-24T15:54:08.655288Z"}]}
{"channel":"book","type":"update","data":[{"symbol":"ETH/USD","bids":[],"asks":[{"price":3698.38,"qty":27.03891391}],"checksum":698688494,"timestamp":"2024-05-24T15:54:08.655452Z"}]}
{"channel":"book","type":"update","data":[{"symbol":"ETH/USD","bids":[],"asks":[{"price":3698.50,"qty":0.04046589}],"checksum":3043251829,"timestamp":"2024-05-24T15:54:08.658457Z"}]}
{"channel":"book","type":"update","data":[{"symbol":"ETH/USD","bids":[],"asks":[{"price":3698.46,"qty":3.18750000}],"checksum":3539660800,"timestamp":"2024-05-24T15:54:08.658482Z"}]}
{"channel":"book","type":"update","data":[{"symbol":"ETH/USD","bids":[],"asks":[{"price":3698.35,"qty":3.18750000}],"checksum":1235110665,"timestamp":"2024-05-24T15:54:08.659216Z"}]}
{"channel":"book","type":"update","data":[{"symbol":"ETH/USD","bids":[],"asks":[{"price":3698.52,"qty":0.00000000},{"price":3698.75,"qty":4.45669462},{"price":3698.50,"qty":0.58122565}],"checksum":4095292931,"timestamp":"2024-05-24T15:54:08.659285Z"}]}
{"channel":"book","type":"update","data":[{"symbol":"ETH/USD","bids":[],"asks":[{"price":3698.53,"qty":0.00000000},{"price":3698.79,"qty":27.03586848}],"checksum":3016927121,"timestamp":"2024-05-24T15:54:08.659307Z"}]}
{"channel":"book","type":"update","data":[{"symbol":"ETH/USD","bids":[{"price":3697.76,"qty":0.20498878}],"asks":[],"checksum":2511388730,"timestamp":"2024-05-24T15:54:08.660500Z"}]}
{"channel":"book","type":"update","data":[{"symbol":"ETH/USD","bids":[{"price":3698.07,"qty":0.00000000},{"price":3697.44,"qty":0.80132412}],"asks":[],"checksum":1302599902,"timestamp":"2024-05-24T15:54:08.660544Z"}]}
{"channel":"book","type":"update","data":[{"symbol":"ETH/USD","bids":[],"asks":[{"price":3698.38,"qty":0.00000000},{"price":3698.81,"qty":13.52087848}],"checksum":1906778341,"timestamp":"2024-05-24T15:54:08.660596Z"}]}
{"channel":"book","type":"update","data":[{"symbol":"ETH/USD","bids":[],"asks":[{"price":3698.50,"qty":0.54075976}],"checksum":3442959503,"timestamp":"2024-05-24T15:54:08.661819Z"}]}
{"channel":"book","type":"update","data":[{"symbol":"ETH/USD","bids":[],"asks":[{"price":3698.50,"qty":0.00000000},{"price":3698.86,"qty":4.22000000}],"checksum":109848136,"timestamp":"2024-05-24T15:54:08.662753Z"}]}
{"channel":"book","type":"update","data":[{"symbol":"ETH/USD","bids":[],"asks":[{"price":3698.46,"qty":0.00000000},{"price":3698.89,"qty":1.53600000}],"checksum":1400493255,"timestamp":"2024-05-24T15:54:08.664608Z"}]}
{"channel":"book","type":"update","data":[{"symbol":"ETH/USD","bids":[{"price":3697.86,"qty":27.04266629}],"asks":[],"checksum":188826188,"timestamp":"2024-05-24T15:54:08.664638Z"}]}
{"channel":"book","type":"update","data":[{"symbol":"ETH/USD","bids":[],"asks":[{"price":3698.86,"qty":2.11000000}],"checksum":2110370415,"timestamp":"2024-05-24T15:54:08.684249Z"}]}
{"channel":"book","type":"update","data":[{"symbol":"ETH/USD","bids":[],"asks":[{"price":3698.86,"qty":0.00000000},{"price":3698.90,"qty":0.55000000}],"checksum":2833066253,"timestamp":"2024-05-24T15:54:08.687659Z"}]}
{"channel":"book","type":"update","data":[{"symbol":"ETH/USD","bids":[],"asks":[{"price":3698.35,"qty":0.00000000},{"price":3698.94,"qty":1.62232097}],"checksum":2270501337,"timestamp":"2024-05-24T15:54:08.698867Z"}]}
{"channel":"book","type":"update","data":[{"symbol":"ETH/USD","bids":[],"asks":[{"price":3698.44,"qty":3.18750000}],"checksum":2806530012,"timestamp":"2024-05-24T15:54:08.702080Z"}]}
{"channel":"book","type":"update","data":[{"symbol":"ETH/USD","bids":[],"asks":[{"price":3698.50,"qty":0.04046589}],"checksum":2459542860,"timestamp":"2024-05-24T15:54:08.702554Z"}]}
{"channel":"book","type":"update","data":[{"symbol":"ETH/USD","bids":[],"asks":[{"price":3698.51,"qty":0.00000000},{"price":3698.90,"qty":0.55000000}],"checksum":2234140380,"timestamp":"2024-05-24T15:54:08.703327Z"}]}
{"channel":"book","type":"update","data":[{"symbol":"ETH/USD","bids":[],"asks":[{"price":3698.50,"qty":0.00000000},{"price":3698.94,"qty":1.62232097}],"checksum":565703949,"timestamp":"2024-05-24T15:54:08.705835Z"}]}
{"channel":"book","type":"update","data":[{"symbol":"BTC/USD","bids":[{"price":68181.3,"qty":0.02195560}],"asks":[],"checksum":2233021310,"timestamp":"2024-05-24T15:54:08.706036Z"}]}
{"channel":"book","type":"update","data":[{"symbol":"ETH/USD","bids":[],"asks":[{"price":3698.50,"qty":27.03798837}],"checksum":2397203336,"timestamp":"2024-05-24T15:54:08.707261Z"}]}
{"channel":"book","type":"update","data":[{"symbol":"ETH/USD","bids":[],"asks":[{"price":3698.40,"qty":27.03874625}],"checksum":29020164,"timestamp":"2024-05-24T15:54:08.707283Z"}]}
{"channel":"book","type":"update","data":[{"symbol":"ETH/USD","bids":[{"price":3698.08,"qty":27.04102998}],"asks":[],"checksum":1967046790,"timestamp":"2024-05-24T15:54:08.707326Z"}]}
{"channel":"book","type":"update","data":[{"symbol":"BTC/USD","bids":[{"price":68185.1,"qty":0.00000000},{"price":68181.0,"qty":1.46668408}],"asks":[],"checksum":1160657155,"timestamp":"2024-05-24T15:54:08.716693Z"}]}
{"channel":"book","type":"update","data":[{"symbol":"BTC/USD","bids":[{"price":68185.3,"qty":1.46658980}],"asks":[],"checksum":816724063,"timestamp":"2024-05-24T15:54:08.722356Z"}]}
{"channel":"book","type":"update","data":[{"symbol":"ETH/BTC","bids":[{"price":0.05422,"qty":18.11811386}],"asks":[],"checksum":3192961793,"timestamp":"2024-05-24T15:54:08.723004Z"}]}
{"channel":"book","type":"update","data":[{"symbol":"ETH/BTC","bids":[{"price":0.05423,"qty":3.82576375}],"asks":[],"checksum":3513424654,"timestamp":"2024-05-24T15:54:08.728257Z"}]}
{"channel":"book","type":"update","data":[{"symbol":"ETH/USD","bids":[],"asks":[{"price":3698.40,"qty":0.00000000},{"price":3698.90,"qty":0.55000000}],"checksum":4201020170,"timestamp":"2024-05-24T15:54:08.731354Z"}]}
{"channel":"book","type":"update","data":[{"symbol":"ETH/USD","bids":[{"price":3697.86,"qty":0.00000000},{"price":3697.59,"qty":35.48497361}],"asks":[],"checksum":2436404895,"timestamp":"2024-05-24T15:54:08.731536Z"}]}
{"channel":"book","type":"update","data":[{"symbol":"ETH/USD","bids":[{"price":3698.08,"qty":0.00000000},{"price":3697.44,"qty":0.80132412}],"asks":[],"checksum":1186739453,"timestamp":"2024-05-24T15:54:08.731547Z"}]}
{"channel":"book","type":"update","data":[{"symbol":"ETH/USD","bids":[],"asks":[{"price":3698.44,"qty":0.00000000},{"price":3698.94,"qty":1.62232097}],"checksum":4116957438,"timestamp":"2024-05-24T15:54:08.757641Z"}]}
{"channel":"book","type":"update","data":[{"symbol":"ETH/USD","bids":[],"asks":[{"price":3698.49,"qty":0.04046589}],"checksum":3994365205,"timestamp":"2024-05-24T15:54:08.761027Z"}]}
{"channel":"book","type":"update","data":[{"symbol":"ETH/USD","bids":[],"asks":[{"price":3698.49,"qty":3.22796589}],"checksum":3120916792,"timestamp":"2024-05-24T15:54:08.761221Z"}]}
{"channel":"book","type":"update","data":[{"symbol":"ETH/USD","bids":[{"price":3697.59,"qty":8.44034963}],"asks":[],"checksum":770852653,"timestamp":"2024-05-24T15:54:08.768974Z"}]}
{"channel":"book","type":"update","data":[{"symbol":"ETH/USD","bids":[],"asks":[{"price":3698.50,"qty":0.00000000},{"price":3698.94,"qty":1.62232097}],"checksum":3696777187,"timestamp":"2024-05-24T15:54:08.768984Z"}]}
{"channel":"book","type":"update","data":[{"symbol":"ETH/USD","bids":[],"asks":[{"price":3698.53,"qty":27.03780430}],"checksum":2021319766,"timestamp":"2024-05-24T15:54:08.773168Z"}]}
{"channel":"book","type":"update","data":[{"symbol":"ETH/USD","bids":[{"price":3698.20,"qty":27.04012587}],"asks":[],"checksum":1443861289,"timestamp":"2024-05-24T15:54:08.773220Z"}]}
{"channel":"book","type":"update","data":[{"symbol":"ETH/USD","bids":[{"price":3697.73,"qty":27.04354835}],"asks":[],"checksum":3148215736,"timestamp":"2024-05-24T15:54:08.773239Z"}]}
{"channel":"book","type":"update","data":[{"symbol":"ETH/USD","bids":[],"asks":[{"price":3698.49,"qty":0.04046589}],"checksum":3929964238,"timestamp":"2024-05-24T15:54:08.776350Z"}]}
{"channel":"book","type":"update","data":[{"symbol":"ETH/USD","bids":[{"price":3698.20,"qty":0.00000000},{"price":3697.59,"qty":8.44034963}],"asks":[],"checksum":722305142,"timestamp":"2024-05-24T15:54:08.778550Z"}]}
{"channel":"book","type":"update","data":[{"symbol":"ETH/USD","bids":[{"price":3697.69,"qty":2.11000000}],"asks":[],"checksum":246652047,"timestamp":"2024-05-24T15:54:08.791983Z"}]}
{"channel":"book","type":"update","data":[{"symbol":"ETH/USD","bids":[{"price":3697.69,"qty":4.22000000}],"asks":[],"checksum":2883770591,"timestamp":"2024-05-24T15:54:08.794816Z"}]}
{"channel":"book","type":"update","data":[{"symbol":"ETH/BTC","bids":[{"price":0.05422,"qty":15.41410680}],"asks":[],"checksum":1103406854,"timestamp":"2024-05-24T15:54:08.815326Z"}]}
{"channel":"book","type":"update","data":[{"symbol":"BTC/USD","bids":[{"price":68185.3,"qty":0.00000000},{"price":68181.0,"qty":1.46668408}],"asks":[],"checksum":1160657155,"timestamp":"2024-05-24T15:54:08.815382Z"}]}
{"channel":"book","type":"update","data":[{"symbol":"ETH/USD","bids":[],"asks":[{"price":3698.53,"qty":0.00000000},{"price":3698.94,"qty":1.62232097}],"checksum":1906560042,"timestamp":"2024-05-24T15:54:08.816855Z"}]}
{"channel":"book","type":"update","data":[{"symbol":"ETH/USD","bids":[],"asks":[{"price":3698.49,"qty":0.00000000},{"price":3698.98,"qty":27.03452313}],"checksum":1401615906,"timestamp":"2024-05-24T15:54:08.820529Z"}]}
{"channel":"book","type":"update","data":[{"symbol":"BTC/USD","bids":[{"price":68185.6,"qty":1.46658364}],"asks":[],"checksum":176472267,"timestamp":"2024-05-24T15:54:08.820588Z"}]}
{"channel":"book","type":"update","data":[{"symbol":"ETH/USD","bids":[],"asks":[{"price":3698.56,"qty":0.04046589}],"checksum":2696971662,"timestamp":"2024-05-24T15:54:08.823174Z"}]}
{"channel":"book","type":"update","data":[{"symbol":"ETH/USD","bids":[{"price":3698.27,"qty":28.10793180}],"asks":[],"checksum":2529551063,"timestamp":"2024-05-24T15:54:08.823345Z"}]}
{"channel":"book","type":"update","data":[{"symbol":"ETH/USD","bids":[],"asks":[{"price":3698.56,"qty":27.07807988}],"checksum":874426543,"timestamp":"2024-05-24T15:54:08.823408Z"}]}
